Workbook

Sheet Petunjuk
A1: UTS Statistical Analysis II - Basis analisis & catatan data (NPM 120510253003)
A3: Bagian | B3: Keterangan
A4: Bahasa | B4: Label sheet memakai bahasa Indonesia; isi analisis dan laporan PDF dalam bahasa Inggris sesuai instruksi soal.
A5: Negara | B5: NPM berakhiran 3 -> Viet Nam (negara ke-4). Pembanding: Philippines, India.
A6: Indikator | B6: Q1: CPI inflation (FP.CPI.TOTL.ZG) 1996-2025; Q2-Q3: ILOSTAT 2024 (pengangguran dan pekerja per sektor); Q4: GDP growth (NY.GDP.MKTP.KD.ZG) 2000-2024; Q5: GDP growth ~ investasi (NE.GDI.TOTL.ZS) + inflasi; Q6: ekspor barang & jasa (NE.EXP.GNFS.CD); Q7: data survei publik Zenodo.
A7: Tanggal ekstraksi | B7: 12 Oktober 2026 (World Bank WDI, update database 2026-10-08).
A8: Presisi data | B8: Seluruh data diunduh lewat API resmi dengan presisi penuh dan disimpan apa adanya di sheet Raw_*. Tidak ada angka yang diketik manual / dibulatkan 1 desimal.
A9: Q2/Q3 | B9: Memakai hitungan ILOSTAT (status kerja dan sektor), bukan komposisi penduduk dari WDI. Angka ILO adalah estimasi survei berbobot (ribuan orang), sehingga p-value chi-square tidak dapat dibaca sebagai bukti inferensial biasa (lihat catatan di tiap sheet).
A10: Q7 | B10: Memakai dataset survei publik asli (Zenodo 10.5281/zenodo.22057938, n=248) - bukan protokol saja; tidak ada data simulasi.
A11: Rumus hidup | B11: Sheet Q1_calc, Q2_calc, Q3_calc, Q4 ANOVA dan Q7_SCR_alpha berisi rumus Excel yang dapat dicek ulang.
A12: AI disclosure | B12: AI digunakan untuk menulis skrip, menjalankan analisis, dan menyusun draft. Verifikasi akhir (unduh ulang data, cek sampel nilai, baca sumber berita primer) tetap harus dilakukan mahasiswa; lihat lampiran laporan PDF.

Sheet GDP Growth
A1: GDP growth (annual %) - World Bank WDI API, presisi penuh (diunduh 2026-10-12)
A2: Year | B2: Viet Nam (VNM) | C2: Philippines (PHL) | D2: India (IND) | E2: Indicator | F2: Source API call
A3: 2000 | B3: 6.7873164 | C3: 4.382505 | D3: 3.8409912 | E3: NY.GDP.MKTP.KD.ZG | F3: https://api.worldbank.org/v2/country/VNM;PHL;IND/indicator/NY.GDP.MKTP.KD.ZG?format=json&per_page=20000&date=1960:2025
A4: 2001 | B4: 6.1928933 | C4: 3.0492313 | D4: 4.8239663 | E4: NY.GDP.MKTP.KD.ZG | F4: https://api.worldbank.org/v2/country/VNM;PHL;IND/indicator/NY.GDP.MKTP.KD.ZG?format=json&per_page=20000&date=1960:2025
A5: 2002 | B5: 6.320821 | C5: 3.716255 | D5: 3.8039753 | E5: NY.GDP.MKTP.KD.ZG | F5: https://api.worldbank.org/v2/country/VNM;PHL;IND/indicator/NY.GDP.MKTP.KD.ZG?format=json&per_page=20000&date=1960:2025
A6: 2003 | B6: 6.8990635 | C6: 5.0869111 | D6: 7.8603815 | E6: NY.GDP.MKTP.KD.ZG | F6: https://api.worldbank.org/v2/country/VNM;PHL;IND/indicator/NY.GDP.MKTP.KD.ZG?format=json&per_page=20000&date=1960:2025
A7: 2004 | B7: 7.5364106 | C7: 6.5692285 | D7: 7.9229366 | E7: NY.GDP.MKTP.KD.ZG | F7: https://api.worldbank.org/v2/country/VNM;PHL;IND/indicator/NY.GDP.MKTP.KD.ZG?format=json&per_page=20000&date=1960:2025
A8: 2005 | B8: 7.5472477 | C8: 4.9425051 | D8: 7.9234306 | E8: NY.GDP.MKTP.KD.ZG | F8: https://api.worldbank.org/v2/country/VNM;PHL;IND/indicator/NY.GDP.MKTP.KD.ZG?format=json&per_page=20000&date=1960:2025
A9: 2006 | B9: 6.9779548 | C9: 5.3164168 | D9: 8.0607326 | E9: NY.GDP.MKTP.KD.ZG | F9: https://api.worldbank.org/v2/country/VNM;PHL;IND/indicator/NY.GDP.MKTP.KD.ZG?format=json&per_page=20000&date=1960:2025
A10: 2007 | B10: 7.1295045 | C10: 6.5192916 | D10: 7.6608151 | E10: NY.GDP.MKTP.KD.ZG | F10: https://api.worldbank.org/v2/country/VNM;PHL;IND/indicator/NY.GDP.MKTP.KD.ZG?format=json&per_page=20000&date=1960:2025
A11: 2008 | B11: 5.6617712 | C11: 4.3444873 | D11: 3.0866981 | E11: NY.GDP.MKTP.KD.ZG | F11: https://api.worldbank.org/v2/country/VNM;PHL;IND/indicator/NY.GDP.MKTP.KD.ZG?format=json&per_page=20000&date=1960:2025
A12: 2009 | B12: 5.3978975 | C12: 1.4483231 | D12: 7.8618888 | E12: NY.GDP.MKTP.KD.ZG | F12: https://api.worldbank.org/v2/country/VNM;PHL;IND/indicator/NY.GDP.MKTP.KD.ZG?format=json&per_page=20000&date=1960:2025
A13: 2010 | B13: 6.4232448 | C13: 7.3345 | D13: 8.4975847 | E13: NY.GDP.MKTP.KD.ZG | F13: https://api.worldbank.org/v2/country/VNM;PHL;IND/indicator/NY.GDP.MKTP.KD.ZG?format=json&per_page=20000&date=1960:2025
A14: 2011 | B14: 6.4131689 | C14: 3.8582328 | D14: 5.2413162 | E14: NY.GDP.MKTP.KD.ZG | F14: https://api.worldbank.org/v2/country/VNM;PHL;IND/indicator/NY.GDP.MKTP.KD.ZG?format=json&per_page=20000&date=1960:2025
... A27: 2024 | B27: 7.039552 | C27: 5.7147453 | D27: 7.0992789 | E27: NY.GDP.MKTP.KD.ZG | F27: https://api.worldbank.org/v2/country/VNM;PHL;IND/indicator/NY.GDP.MKTP.KD.ZG?format=json&per_page=20000&date=1960:2025

Sheet Q1 Normalitas
A1: Q1 - Lilliefors normality test: Viet Nam CPI inflation 1996-2025 (n = 30)
A2: Ringkasan | B2: Hasil
A3: N observasi | B3: =Q1_calc!K4
A4: Rata-rata (%) | B4: =Q1_calc!K2
A5: Simpangan baku sampel | B5: =Q1_calc!K3
A6: Statistik D Lilliefors | B6: =Q1_calc!K5
A7: Nilai kritis 5% (n=30) | B7: =Q1_calc!K6
A8: p-value (statsmodels, tabel Lilliefors) | B8: 0.0016886936
A9: Keputusan | B9: =Q1_calc!K7
A11: Cek tambahan | B11: Shapiro-Wilk W = 0.795, p = 0.00005; Jarque-Bera p < 0.001; Lilliefors pada log(1+inflasi): D = 0.208, p = 0.0022; autokorelasi lag-1 = 0.44.
A12: Interpretasi | B12: H0 normalitas ditolak. Penyebab: ekor kanan berat (lonjakan 2008 = 23.1%, 2011 = 18.7%). Karena inflasi berautokorelasi positif, observasi tidak independen sehingga p-value hanya indikatif. Implikasi: gunakan kuantil/bootstrap, bukan mean +/- 1.96 s; waspadai risiko ekor inflasi. Data terurut, F empiris dan F teoretis lengkap ada di sheet Q1_calc.

Sheet Q2 Proporsi
A1: Q2 - Chi-square 2x2: pengangguran vs bekerja, Viet Nam vs Philippines, 2024 (ILOSTAT, usia 15+)
A2: Negara | B2: Menganggur (orang) | C2: Bekerja (orang) | D2: Total | E2: Tingkat pengangguran
A3: Viet Nam | B3: 858467 | C3: 55280158 | D3: =B3+C3 | E3: =B3/D3
A4: Philippines | B4: 1147686 | C4: 47524318 | D4: =B4+C4 | E4: =B4/D4
A6: Chi-square Pearson | B6: 95384.786
A7: df | B7: 1
A8: p-value | B8: < 0.001 (underflow ke 0)
A9: Cramer's V | B9: 0.030167331
A10: Chi-square Yates | B10: 95384.345
A12: Sensitivitas (n efektif ASUMSI, bukan data) | B12: n efektif per negara | C12: chi-square | D12: p-value
B13: 2000 | C13: 3.6043498 | D13: 0.057628598
B14: 10000 | C14: 18.021749 | D14: 2.1839553e-05
B15: 50000 | C15: 90.108746 | D15: 2.25423e-21
B16: 200000 | C16: 360.43498 | D16: 2.2639533e-80
A18: Catatan | B18: Hitungan ILO adalah estimasi survei berbobot (ribuan orang x 1000), bukan jumlah responden; N = 105 juta membuat p-value selalu ~0. Arah selisih (VN lebih rendah ~0.83 poin persen) stabil, tetapi signifikansi bergantung pada n efektif yang tidak diketahui; uji yang tepat adalah Rao-Scott pada data mikro. Perhitungan dengan rumus hidup: sheet Q2_calc.

Sheet Q3 Struktur Sektor
A1: Q3 - Chi-square independensi 2x3: negara x sektor pekerjaan, 2024 (ILOSTAT)
A2: Negara | B2: Pertanian | C2: Industri | D2: Jasa | E2: Total
A3: Viet Nam | B3: 13637057 | C3: 17131226 | D3: 20666543 | E3: =SUM(B3:D3)
A4: Philippines | B4: 9858510 | C4: 8649772 | D4: 29016036 | E4: =SUM(B4:D4)
A6: Chi-square Pearson | B6: 4653826.7
A7: df | B7: 2
A8: p-value | B8: < 0.001
A9: Cramer's V | B9: 0.21685885
A10: Min. expected count | B10: 11283554
A11: Robustness 2x4 (+ tidak terklasifikasi VN = 3,845,332) | B11: chi-square = 8107444, df = 3, V = 0.281
A13: Catatan | B13: Pekerja VN 'tidak terklasifikasi' (6.96%) dikeluarkan dari uji utama. Tidak ada sel kecil (E min > 11 juta). p-value ~0 karena data berbobot nasional; ukuran efek V = 0.22 yang informatif. Keputusan: sourcing manufaktur di Viet Nam (industri 33.3% vs 18.2%), staffing layanan/BPO di Philippines (jasa 61.1%). Rumus hidup: sheet Q3_calc.

Sheet Q4 ANOVA
A1: Q4 - One-way ANOVA GDP growth 2000-2024 (rumus hidup dari sheet GDP Growth)
A2: Negara | B2: N | C2: Rata-rata (%) | D2: SD sampel | E2: SS dalam kelompok
A3: Viet Nam | B3: =COUNT('GDP Growth'!B3:B27) | C3: =AVERAGE('GDP Growth'!B3:B27) | D3: =STDEV('GDP Growth'!B3:B27) | E3: =DEVSQ('GDP Growth'!B3:B27)
A4: Philippines | B4: =COUNT('GDP Growth'!C3:C27) | C4: =AVERAGE('GDP Growth'!C3:C27) | D4: =STDEV('GDP Growth'!C3:C27) | E4: =DEVSQ('GDP Growth'!C3:C27)
A5: India | B5: =COUNT('GDP Growth'!D3:D27) | C5: =AVERAGE('GDP Growth'!D3:D27) | D5: =STDEV('GDP Growth'!D3:D27) | E5: =DEVSQ('GDP Growth'!D3:D27)
A7: Rata-rata keseluruhan | B7: =AVERAGE('GDP Growth'!B3:D27)
A8: SS antar kelompok | B8: =B3*(C3-B7)^2+B4*(C4-B7)^2+B5*(C5-B7)^2
A9: SS dalam kelompok | B9: =SUM(E3:E5)
A10: F ANOVA | B10: =(B8/2)/(B9/72)
A11: p-value ANOVA | B11: =FDIST(B10,2,72)
A12: eta kuadrat | B12: =B8/(B8+B9)
A14: Uji lain (dari skrip Python, hasil sama dalam laporan) | B14: Statistik | C14: p-value
A15: Welch ANOVA | B15: 1.7099844 | C15: 0.19363035
A16: Kruskal-Wallis (UTAMA: normalitas ditolak) | B16: 8.1733053 | C16: 0.01679536
A17: Friedman (tahun sebagai blok) | B17: 10.32 | C17: 0.0057416997
A18: Levene (median) | B18: 1.1158577 | C18: 0.33323299
A19: Bartlett | B19: 18.221733 | C19: 0.00011045898
A20: Post-hoc Dunn-Holm: PHL-IND | B20: -2.809675 | C20: 0.014877464
A21: Post-hoc Dunn-Holm: VNM-PHL | B21: 1.8623019 | C21: 0.12512109
A22: Post-hoc Dunn-Holm: VNM-IND | B22: -0.9473731 | C22: 0.34344869
A24: Kesimpulan | B24: Normalitas ditolak di ketiga kelompok; ANOVA/Welch tidak signifikan (p = 0.162/0.194), tetapi Kruskal-Wallis signifikan (p = 0.017) dan Friedman p = 0.006: distribusi pertumbuhan berbeda, terutama Philippines vs India. Tanpa 2020-2021, ANOVA signifikan (p = 0.020): hasil sensitif terhadap COVID. Antar-tahun dan antar-negara tidak independen (guncangan global sama).

Sheet Q5 Regresi
A1: Q5 - Regresi GDP growth Viet Nam ~ investasi + inflasi (1996-2025, n = 30); data: sheet Q5_data
A2: Istilah | B2: Koefisien | C2: Std. error | D2: t | E2: p-value
A3: Intersep | B3: 7.2120197 | C3: 3.3344374 | D3: 2.1628895 | E3: 0.03957042
A4: Investasi (% PDB) X1 | B4: -0.021762122 | C4: 0.10643703 | D4: -0.20446006 | E4: 0.83952744
A5: Inflasi (%) X2 | B5: -0.0060830447 | C5: 0.060724601 | D5: -0.1001743 | E5: 0.92094608
A7: R2 | B7: 0.0029935482
A8: Adjusted R2 | B8: -0.070858782
A9: F model (df 2, 27) | B9: 0.040534242
A10: p F model | B10: 0.9603346
A11: VIF X1 / X2 | B11: 1.19 / 1.19
A12: Breusch-Pagan p | B12: 0.5137117
A13: Durbin-Watson | B13: 1.5291413
A14: Breusch-Godfrey(1) p | B14: 0.37621609
A15: Shapiro-Wilk residual p | B15: 0.067698563
A17: Model kuadratik | B17: R2 | C17: Adj. R2 | D17: AIC | E17: p suku kuadrat (F nested)
A18: Linear | B18: 0.0029935482 | C18: -0.070858782 | D18: 112.46828 | E18: -
A19: + Inflasi^2 | B19: 0.018590483 | C19: -0.094649076 | D19: 113.99526 | E19: 0.52597749
A20: + Investasi^2 | B20: 0.019854436 | C20: -0.093239283 | D20: 113.9566 | E20: 0.50953235
A22: Interpretasi | B22: Tidak ada prediktor signifikan, F-test tidak menolak H0, R2 ~ 0.003; asumsi terpenuhi sehingga masalahnya adalah ketiadaan sinyal, bukan pelanggaran asumsi. Suku kuadrat tidak signifikan. Asosiasi bukan kausalitas. Rekomendasi: jangan menentukan waktu investasi/harga dari prediktor makro ini; investasi bertahap + klausul indeksasi harga.

Sheet Q6 Forecast
A1: Q6 - Ekspor barang & jasa Viet Nam (US$ miliar, NE.EXP.GNFS.CD), 1986-2025; holdout 2021-2025
A2: Tahun | B2: Ekspor (US$ bn) | C2: t | D2: MA(3) rata-rata 3 tahun sebelumnya
A3: 1986 | B3: 1.7441528 | C3: 1
A4: 1987 | B4: 2.2000101 | C4: 2
A5: 1988 | B5: 1.0030452 | C5: 3
A6: 1989 | B6: 1.5009128 | C6: 4 | D6: =AVERAGE(B3:B5)
A7: 1990 | B7: 2.3323257 | C7: 5 | D7: =AVERAGE(B4:B6)
A8: 1991 | B8: 2.971977 | C8: 6 | D8: =AVERAGE(B5:B7)
A9: 1992 | B9: 3.4283445 | C9: 7 | D9: =AVERAGE(B6:B8)
A10: 1993 | B10: 3.7859367 | C10: 8 | D10: =AVERAGE(B7:B9)
A11: 1994 | B11: 5.5395256 | C11: 9 | D11: =AVERAGE(B8:B10)
A12: 1995 | B12: 6.8041276 | C12: 10 | D12: =AVERAGE(B9:B11)
A13: 1996 | B13: 10.077135 | C13: 11 | D13: =AVERAGE(B10:B12)
A14: 1997 | B14: 11.570361 | C14: 12 | D14: =AVERAGE(B11:B13)
A15: 1998 | B15: 12.203045 | C15: 13 | D15: =AVERAGE(B12:B14)
A16: 1999 | B16: 14.332148 | C16: 14 | D16: =AVERAGE(B13:B15)
A17: 2000 | B17: 16.808689 | C17: 15 | D17: =AVERAGE(B14:B16)
... A42: 2025 | B42: 505.66123 | C42: 40 | D42: =AVERAGE(B39:B41)
A44: Evaluasi holdout 2021-2025 (latih 1986-2020)
A45: Model | B45: MAE (US$ bn) | C45: MAPE (%) | D45: RMSE
A46: linear_trend | B46: 182.86975 | C46: 44.143531 | D46: 188.54106
A47: MA3_flat | B47: 128.64504 | C47: 30.304145 | D47: 140.23617
A48: MA3_rolling_1step | B48: 69.566854 | C48: 16.828041 | D48: 73.578304
A49: loglinear_trend | B49: 295.67439 | C49: 70.407656 | D49: 316.69753
A50: naive_last | B50: 115.83845 | C50: 27.112683 | D50: 128.58919
A51: linear_trend_last10y | B51: 46.866122 | C51: 10.854921 | D51: 55.296768
A52: damped_Holt | B52: 60.408744 | C52: 14.077933 | D52: 68.911746
A54: Forecast (US$ bn) | B54: 2026 | C54: 2027 | D54: Interval 95%
A55: Tren linear seluruh data (TIDAK VALID: di bawah aktual 2025) | B55: 334.04949 | C55: 344.80096 | D55: 192-476
A56: MA(3) | B56: 437.13778 | C56: 437.13778 | D56: -
A57: Tren linear 10 tahun terakhir (basis rekomendasi) | B57: 502.13806 | C57: 533.41443 | D57: 447-557; 476-591
A58: Damped Holt | B58: 518.09983 | C58: 558.2975 | D58: -
A60: Catatan | B60: Data tahunan tidak dapat mengidentifikasi musiman dalam tahun. MA(3) mengungguli tren linear pada holdout (MAPE 30.3% vs 44.1%), namun keduanya bias ke bawah; tren 10 tahun terakhir terbaik (MAPE 10.9%) tetapi dipilih dari 5 titik holdout. Respons: rencanakan ekspor ~US$ 500-560 bn 2026-27, kapasitas bertahap, pemicu tinjau ulang di bawah ~US$ 447 bn.

Sheet Q7 Survei
A1: Q7 - Validitas & reliabilitas: enam item rancangan + analisis pada data publik asli
A2: Item | B2: Pernyataan (Likert 1-5)
A3: SR1 | B3: My firm could keep production running if energy prices stayed sharply higher for the next six months.
A4: SR2 | B4: We have qualified alternative suppliers for our most critical inputs.
A5: SR3 | B5: We could pass at least part of higher energy or transport costs to customers without losing major accounts.
A6: SR4 | B6: Our logistics network can be rerouted quickly if a key supplier or shipping route is disrupted.
A7: SR5 | B7: Our inventory buffers of critical inputs would cover at least one month of supply disruption.
A8: SR6 | B8: Management regularly monitors energy-price and supplier-risk indicators and acts on them.
A10: Data | B10: Zenodo 10.5281/zenodo.22057938 (CC-BY 4.0), file DATAUPDATE.csv, SCR1-SCR6, n = 248, Likert 1-5. Teks item asli tidak tersedia di deposit; Dataset A (Zenodo 20439760, OR1-OR5) sebagai pembanding - alpha negatif, tidak dipakai.
A11: Cronbach alpha | B11: =Q7_SCR_alpha!B253
A12: Odd-even r (Pearson) | B12: =Q7_SCR_alpha!B254
A13: Spearman-Brown | B13: =Q7_SCR_alpha!B255
A14: Corrected item-total r (SCR1..SCR6) | B14: 0.787, 0.812, 0.812, 0.806, 0.829, 0.840
A15: CI 95% alpha (bootstrap) | B15: 0.923 - 0.950
A16: Interpretasi | B16: Konsistensi internal sangat tinggi (alpha 0.94; semua item-total r >= 0.79). Mean inter-item r = 0.72 mengindikasikan redundansi. Reliabilitas bukan validitas; responden Indonesia, bukan Viet Nam; item tidak identik dengan rancangan.

Sheet Q8 Memo
A1: Q8 - Executive decision memo (365 kata)
A2: To: Board of Directors | Re: Viet Nam operations | 12 October 2026 Decision: REDESIGN. Proceed with a phased expansion in Viet Nam, released in tranches against energy-cost and demand triggers, rather than one full commitment. Claim 1 (IMF, Reuters 7 Oct 2026: energy prices, record public debt and AI-investment risks threaten global growth). This is a forward-looking warning in the news, not a Viet Nam finding, and our data cannot test an energy shock directly because no energy-price series was analysed. Historically, Viet Nam's GDP growth averaged 6.3% in 2000-2024 with the lowest volatility of the three countries (SD 1.35 pp vs Philippines 3.36, India 3.03), yet it fell to 2.9% in 2020 and 2.6% in 2021. In our regression, inflation and investment explained almost none of annual growth (R² = 0.003, p = 0.96), so we found no statistical evidence that domestic price pressure alone drives growth; this is association, not causation, from 30 points. Exports equal 98% of GDP (2025), so a global slowdown is the more plausible channel, which we did not model. Claim 2 (IEA Global EV Outlook 2026, as reported: Viet Nam's EV share of new-car sales reached about 40% in 2025, with far higher shares projected for 2035). We cannot test sales shares with our data, and the 2035 figure is a projection, not an observation. As a loose proxy only, electricity use per capita grew 7.1% a year in 2014-2024, consistent with, but not proof of, rising power demand. Risk indicators. (1) Inflation tail risk: Viet Nam's CPI inflation failed the Lilliefors normality test (D = 0.211 > 0.161) because of a 23.1% spike in 2008; it exceeded 4% in 14 of 30 years, although volatility since 2015 is low (SD 0.9 pp; 3.3% in 2025). (2) Export uncertainty: 2026 exports are forecast at US$ 502-518 bn with a 95% interval of roughly 447-557 bn. Contingency. Stage capital in two tranches; release the second only if 2026 exports stay above US$ 447 bn and inflation below 5%; use energy-indexed supplier and customer contracts and hold 4-6 weeks of critical inputs. Limitations. Annual data cannot capture within-year shocks; ILO labour figures are weighted survey estimates; and the news claims were assessed from published summaries, not the full Reuters and IEA texts.

Sheet Sumber
A1: Statistical Analysis II - UTS 2026/2027 - Workbook
A2: Student ID (NPM) | B2: 120510253003 (last digit 3 -> 4th country)
A3: Assigned country | B3: Viet Nam (VNM); comparators Philippines (PHL), India (IND)
A4: Extraction date | B4: 2026-10-12
A6: Source | B6: Exact URL / API call | C6: Indicator code | D6: Unit | E6: Period used
A7: World Bank WDI (via API) | B7: https://api.worldbank.org/v2/country/VNM;PHL;IND/indicator/FP.CPI.TOTL.ZG?format=json&per_page=20000&date=1960:2025 | C7: FP.CPI.TOTL.ZG | D7: % y/y | E7: 1996-2025 (VNM)
A8: World Bank WDI | B8: same pattern, indicator NY.GDP.MKTP.KD.ZG | C8: NY.GDP.MKTP.KD.ZG | D8: % y/y | E8: 2000-2024 (Q4), 1996-2025 (Q5)
A9: World Bank WDI | B9: same pattern, indicator NE.GDI.TOTL.ZS | C9: NE.GDI.TOTL.ZS | D9: % of GDP | E9: 1996-2025
A10: World Bank WDI | B10: same pattern, indicator NE.EXP.GNFS.CD | C10: NE.EXP.GNFS.CD | D10: current US$ (shown in US$ bn) | E10: 1986-2025
A11: World Bank WDI | B11: same pattern, indicators NE.EXP.GNFS.ZS, EG.USE.ELEC.KH.PC (context, Q8) | C11: NE.EXP.GNFS.ZS; EG.USE.ELEC.KH.PC | D11: % GDP; kWh/capita | E11: to 2025 / 2024
A12: ILOSTAT SDMX | B12: https://sdmx.ilo.org/rest/data/ILO,DF_UNE_TUNE_SEX_AGE_NB/VNM+PHL+IND....?format=csv&startPeriod=2015 | C12: UNE_TUNE_NB (age 15+) | D12: thousand persons (UNIT_MULT=3) | E12: 2024
A13: Zenodo (Q7) | B13: https://zenodo.org/records/22057938 (CC-BY 4.0, file DATAUPDATE.csv) and https://zenodo.org/records/20439760 | C13: SCR1-SCR6; OR1-OR5 | D13: Likert | E13: 2025-26
A14: ILOSTAT SDMX | B14: https://sdmx.ilo.org/rest/data/ILO,DF_EMP_TEMP_SEX_ECO_NB/VNM+PHL+IND....?format=csv&startPeriod=2015 | C14: EMP_TEMP_NB by ECO_SECTOR_* | D14: thousand persons | E14: 2024
A16: Sheets: Raw_* = downloaded data as received; Q1..Q6 = transformations/tests (Q1-Q3 contain live Excel formulas); Q7 = protocol (no data collected); Results = all statistics from analysis.py.
A17: ILO figures are weighted labour-force-survey estimates (thousands), NOT raw respondent counts - see report Q2/Q3 caveat.

Sheet Raw_WB_FP_CPI_TOTL_ZG
A1: iso3 | B1: year | C1: FP.CPI.TOTL.ZG
A2: IND | B2: 1960 | C2: 1.7798778
A3: IND | B3: 1961 | C3: 1.6952129
A4: IND | B4: 1962 | C4: 3.632215
A5: IND | B5: 1963 | C5: 2.9461614
A6: IND | B6: 1964 | C6: 13.355261
A7: IND | B7: 1965 | C7: 9.4747586
A8: IND | B8: 1966 | C8: 10.801848
A9: IND | B9: 1967 | C9: 13.062202
A10: IND | B10: 1968 | C10: 3.2374124
A11: IND | B11: 1969 | C11: -0.58413661
A12: IND | B12: 1970 | C12: 5.0922616
A13: IND | B13: 1971 | C13: 3.0799387
... A133: PHL | B133: 2025 | C133: 1.6587365
A134: VNM | B134: 1960
A135: VNM | B135: 1961
A136: VNM | B136: 1962
A137: VNM | B137: 1963
A138: VNM | B138: 1964
A139: VNM | B139: 1965
A140: VNM | B140: 1966
A141: VNM | B141: 1967
A142: VNM | B142: 1968
A143: VNM | B143: 1969
A144: VNM | B144: 1970
A145: VNM | B145: 1971
... A169: VNM | B169: 1995
A170: VNM | B170: 1996 | C170: 5.675
A171: VNM | B171: 1997 | C171: 3.2095261
A172: VNM | B172: 1998 | C172: 7.266198
A173: VNM | B173: 1999 | C173: 4.1171024
A174: VNM | B174: 2000 | C174: -1.7103373
A175: VNM | B175: 2001 | C175: -0.43154451
A176: VNM | B176: 2002 | C176: 3.8308284
A177: VNM | B177: 2003 | C177: 3.2346482
A178: VNM | B178: 2004 | C178: 7.7549475
A179: VNM | B179: 2005 | C179: 8.2845724
A180: VNM | B180: 2006 | C180: 7.4180172
A181: VNM | B181: 2007 | C181: 8.3444489
... A199: VNM | B199: 2025 | C199: 3.3099931

Sheet Raw_WB_NY_GDP_MKTP_KD_ZG
A1: iso3 | B1: year | C1: NY.GDP.MKTP.KD.ZG
A2: IND | B2: 1960
A3: IND | B3: 1961 | C3: 3.7227425
A4: IND | B4: 1962 | C4: 2.9311277
A5: IND | B5: 1963 | C5: 5.9943533
A6: IND | B6: 1964 | C6: 7.4529501
A7: IND | B7: 1965 | C7: -2.6357701
A8: IND | B8: 1966 | C8: -0.05532877
A9: IND | B9: 1967 | C9: 7.825963
A10: IND | B10: 1968 | C10: 3.3879292
A11: IND | B11: 1969 | C11: 6.5397003
A12: IND | B12: 1970 | C12: 5.1572297
A13: IND | B13: 1971 | C13: 1.6429304
A14: IND | B14: 1972 | C14: -0.55330131
... A67: IND | B67: 2025 | C67: 7.5666618
A68: PHL | B68: 1960
A69: PHL | B69: 1961 | C69: 5.695471
A70: PHL | B70: 1962 | C70: 4.8462942
A71: PHL | B71: 1963 | C71: 7.0162652
A72: PHL | B72: 1964 | C72: 3.4024944
A73: PHL | B73: 1965 | C73: 5.3450893
A74: PHL | B74: 1966 | C74: 4.4411585
A75: PHL | B75: 1967 | C75: 5.2226876
A76: PHL | B76: 1968 | C76: 5.0381594
A77: PHL | B77: 1969 | C77: 4.6894734
A78: PHL | B78: 1970 | C78: 3.6924875
A79: PHL | B79: 1971 | C79: 5.3890084
A80: PHL | B80: 1972 | C80: 5.4303875
... A133: PHL | B133: 2025 | C133: 4.4024016
A134: VNM | B134: 1960
A135: VNM | B135: 1961
A136: VNM | B136: 1962
A137: VNM | B137: 1963
A138: VNM | B138: 1964
A139: VNM | B139: 1965
A140: VNM | B140: 1966
A141: VNM | B141: 1967
A142: VNM | B142: 1968
A143: VNM | B143: 1969
A144: VNM | B144: 1970
...

Sheet Raw_WB_NE_GDI_TOTL_ZS
A1: iso3 | B1: year | C1: NE.GDI.TOTL.ZS
A2: IND | B2: 1960 | C2: 17.931335
A3: IND | B3: 1961 | C3: 19.262146
A4: IND | B4: 1962 | C4: 18.107571
A5: IND | B5: 1963 | C5: 18.995457
A6: IND | B6: 1964 | C6: 19.529828
A7: IND | B7: 1965 | C7: 20.057223
A8: IND | B8: 1966 | C8: 18.358014
A9: IND | B9: 1967 | C9: 18.197544
A10: IND | B10: 1968 | C10: 17.74225
A11: IND | B11: 1969 | C11: 17.640095
A12: IND | B12: 1970 | C12: 18.211439
A13: IND | B13: 1971 | C13: 19.203616
... A67: IND | B67: 2025 | C67: 34.603005
A68: PHL | B68: 1960
A69: PHL | B69: 1961
A70: PHL | B70: 1962
A71: PHL | B71: 1963
A72: PHL | B72: 1964
A73: PHL | B73: 1965
A74: PHL | B74: 1966
A75: PHL | B75: 1967
A76: PHL | B76: 1968
A77: PHL | B77: 1969
A78: PHL | B78: 1970
A79: PHL | B79: 1971
... A88: PHL | B88: 1980
A89: PHL | B89: 1981 | C89: 26.401113
A90: PHL | B90: 1982 | C90: 26.686179
A91: PHL | B91: 1983 | C91: 28.232635
A92: PHL | B92: 1984 | C92: 19.831063
A93: PHL | B93: 1985 | C93: 14.165844
A94: PHL | B94: 1986 | C94: 15.052369
A95: PHL | B95: 1987 | C95: 17.16003
A96: PHL | B96: 1988 | C96: 18.300494
A97: PHL | B97: 1989 | C97: 21.009589
A98: PHL | B98: 1990 | C98: 23.331711
A99: PHL | B99: 1991 | C99: 19.717093
A100: PHL | B100: 1992 | C100: 20.748331
... A133: PHL | B133: 2025 | C133: 22.140947
...

Sheet Raw_WB_NE_EXP_GNFS_CD
A1: iso3 | B1: year | C1: NE.EXP.GNFS.CD
A2: IND | B2: 1960 | C2: 1.6527017e+09
A3: IND | B3: 1961 | C3: 1.6884017e+09
A4: IND | B4: 1962 | C4: 1.7577018e+09
A5: IND | B5: 1963 | C5: 2.0727021e+09
A6: IND | B6: 1964 | C6: 2.1042021e+09
A7: IND | B7: 1965 | C7: 1.969802e+09
A8: IND | B8: 1966 | C8: 1.8882256e+09
A9: IND | B9: 1967 | C9: 2.0226667e+09
A10: IND | B10: 1968 | C10: 2144000000
A11: IND | B11: 1969 | C11: 2.1706667e+09
A12: IND | B12: 1970 | C12: 2.3613333e+09
A13: IND | B13: 1971 | C13: 2.4699142e+09
... A67: IND | B67: 2025 | C67: 8.8074085e+11
A68: PHL | B68: 1960
A69: PHL | B69: 1961
A70: PHL | B70: 1962
A71: PHL | B71: 1963
A72: PHL | B72: 1964
A73: PHL | B73: 1965
A74: PHL | B74: 1966
A75: PHL | B75: 1967
A76: PHL | B76: 1968
A77: PHL | B77: 1969
A78: PHL | B78: 1970
A79: PHL | B79: 1971
... A88: PHL | B88: 1980
A89: PHL | B89: 1981 | C89: 6.5433586e+09
A90: PHL | B90: 1982 | C90: 5.8544436e+09
A91: PHL | B91: 1983 | C91: 5.5545916e+09
A92: PHL | B92: 1984 | C92: 6.0535758e+09
A93: PHL | B93: 1985 | C93: 5.9511873e+09
A94: PHL | B94: 1986 | C94: 6.3101068e+09
A95: PHL | B95: 1987 | C95: 7.0071212e+09
A96: PHL | B96: 1988 | C96: 8.6301512e+09
A97: PHL | B97: 1989 | C97: 9.5765654e+09
A98: PHL | B98: 1990 | C98: 9.7951797e+09
A99: PHL | B99: 1991 | C99: 1.0856619e+10
A100: PHL | B100: 1992 | C100: 1.2555557e+10
... A133: PHL | B133: 2025 | C133: 1.29323e+11
...

Sheet Raw_WB_NE_EXP_GNFS_ZS
A1: iso3 | B1: year | C1: NE.EXP.GNFS.ZS
A2: IND | B2: 1960 | C2: 4.4631565
A3: IND | B3: 1961 | C3: 4.3035862
A4: IND | B4: 1962 | C4: 4.1689753
A5: IND | B5: 1963 | C5: 4.2805034
A6: IND | B6: 1964 | C6: 3.7255512
A7: IND | B7: 1965 | C7: 3.3074728
A8: IND | B8: 1966 | C8: 4.1425507
A9: IND | B9: 1967 | C9: 4.034445
A10: IND | B10: 1968 | C10: 4.038771
A11: IND | B11: 1969 | C11: 3.7138428
A12: IND | B12: 1970 | C12: 3.7828251
A13: IND | B13: 1971 | C13: 3.6672052
... A67: IND | B67: 2025 | C67: 22.263041
A68: PHL | B68: 1960
A69: PHL | B69: 1961
A70: PHL | B70: 1962
A71: PHL | B71: 1963
A72: PHL | B72: 1964
A73: PHL | B73: 1965
A74: PHL | B74: 1966
A75: PHL | B75: 1967
A76: PHL | B76: 1968
A77: PHL | B77: 1969
A78: PHL | B78: 1970
A79: PHL | B79: 1971
... A88: PHL | B88: 1980
A89: PHL | B89: 1981 | C89: 16.156685
A90: PHL | B90: 1982 | C90: 13.871113
A91: PHL | B91: 1983 | C91: 14.710573
A92: PHL | B92: 1984 | C92: 16.942469
A93: PHL | B93: 1985 | C93: 17.022123
A94: PHL | B94: 1986 | C94: 18.566123
A95: PHL | B95: 1987 | C95: 18.541533
A96: PHL | B96: 1988 | C96: 19.999364
A97: PHL | B97: 1989 | C97: 19.73989
A98: PHL | B98: 1990 | C98: 19.393213
A99: PHL | B99: 1991 | C99: 20.965141
A100: PHL | B100: 1992 | C100: 20.779665
... A133: PHL | B133: 2025 | C133: 26.550336
...

Sheet Raw_WB_EG_USE_ELEC_KH_PC
A1: iso3 | B1: year | C1: EG.USE.ELEC.KH.PC
A2: IND | B2: 1960
A3: IND | B3: 1961
A4: IND | B4: 1962
A5: IND | B5: 1963
A6: IND | B6: 1964
A7: IND | B7: 1965
A8: IND | B8: 1966
A9: IND | B9: 1967
A10: IND | B10: 1968
A11: IND | B11: 1969
A12: IND | B12: 1970
A13: IND | B13: 1971
... A31: IND | B31: 1989
A32: IND | B32: 1990 | C32: 270.90465
A33: IND | B33: 1991 | C33: 289.26125
A34: IND | B34: 1992 | C34: 301.71866
A35: IND | B35: 1993 | C35: 317.59913
A36: IND | B36: 1994 | C36: 337.32918
A37: IND | B37: 1995 | C37: 354.35346
A38: IND | B38: 1996 | C38: 354.44589
A39: IND | B39: 1997 | C39: 369.39699
A40: IND | B40: 1998 | C40: 379.59974
A41: IND | B41: 1999 | C41: 383.12956
A42: IND | B42: 2000 | C42: 384.98936
A43: IND | B43: 2001 | C43: 384.81821
... A66: IND | B66: 2024 | C66: 1222.8315
A67: IND | B67: 2025
A68: PHL | B68: 1960
A69: PHL | B69: 1961
A70: PHL | B70: 1962
A71: PHL | B71: 1963
A72: PHL | B72: 1964
A73: PHL | B73: 1965
A74: PHL | B74: 1966
A75: PHL | B75: 1967
A76: PHL | B76: 1968
A77: PHL | B77: 1969
A78: PHL | B78: 1970
... A97: PHL | B97: 1989
...

Sheet Raw_ILO_Unemployed
A1: REF_AREA | B1: SEX | C1: AGE | D1: TIME_PERIOD | E1: OBS_VALUE | F1: UNIT_MULT | G1: SOURCE
A2: IND | B2: SEX_T | C2: AGE_YTHADULT_YGE15 | D2: 2024 | E2: 21023.748 | F2: 3 | G2: LFS - Periodic Labour Force Survey
A3: IND | B3: SEX_M | C3: AGE_YTHADULT_YGE15 | D3: 2024 | E3: 14628.922 | F3: 3 | G3: LFS - Periodic Labour Force Survey
A4: IND | B4: SEX_F | C4: AGE_YTHADULT_YGE15 | D4: 2024 | E4: 6394.826 | F4: 3 | G4: LFS - Periodic Labour Force Survey
A5: PHL | B5: SEX_T | C5: AGE_YTHADULT_YGE15 | D5: 2024 | E5: 1147.686 | F5: 3 | G5: LFS - Labour Force Survey
A6: PHL | B6: SEX_M | C6: AGE_YTHADULT_YGE15 | D6: 2024 | E6: 626.598 | F6: 3 | G6: LFS - Labour Force Survey
A7: PHL | B7: SEX_F | C7: AGE_YTHADULT_YGE15 | D7: 2024 | E7: 521.088 | F7: 3 | G7: LFS - Labour Force Survey
A8: VNM | B8: SEX_T | C8: AGE_YTHADULT_YGE15 | D8: 2024 | E8: 858.467 | F8: 3 | G8: LFS - Labour Force Survey
A9: VNM | B9: SEX_M | C9: AGE_YTHADULT_YGE15 | D9: 2024 | E9: 475.379 | F9: 3 | G9: LFS - Labour Force Survey
A10: VNM | B10: SEX_F | C10: AGE_YTHADULT_YGE15 | D10: 2024 | E10: 383.088 | F10: 3 | G10: LFS - Labour Force Survey

Sheet Raw_ILO_EmpSector
A1: REF_AREA | B1: SEX | C1: ECO | D1: TIME_PERIOD | E1: OBS_VALUE | F1: UNIT_MULT | G1: SOURCE
A2: IND | B2: SEX_T | C2: ECO_SECTOR_TOTAL | D2: 2024 | E2: 482793.23 | F2: 3 | G2: LFS - Periodic Labour Force Survey
A3: IND | B3: SEX_T | C3: ECO_SECTOR_AGR | D3: 2024 | E3: 204485.98 | F3: 3 | G3: LFS - Periodic Labour Force Survey
A4: IND | B4: SEX_T | C4: ECO_SECTOR_NAG | D4: 2024 | E4: 278307.26 | F4: 3 | G4: LFS - Periodic Labour Force Survey
A5: IND | B5: SEX_T | C5: ECO_SECTOR_IND | D5: 2024 | E5: 122489.1 | F5: 3 | G5: LFS - Periodic Labour Force Survey
A6: IND | B6: SEX_T | C6: ECO_SECTOR_SER | D6: 2024 | E6: 155818.16 | F6: 3 | G6: LFS - Periodic Labour Force Survey
A7: PHL | B7: SEX_T | C7: ECO_SECTOR_TOTAL | D7: 2024 | E7: 47524.318 | F7: 3 | G7: LFS - Labour Force Survey
A8: PHL | B8: SEX_T | C8: ECO_SECTOR_AGR | D8: 2024 | E8: 9858.51 | F8: 3 | G8: LFS - Labour Force Survey
A9: PHL | B9: SEX_T | C9: ECO_SECTOR_NAG | D9: 2024 | E9: 37665.808 | F9: 3 | G9: LFS - Labour Force Survey
A10: PHL | B10: SEX_T | C10: ECO_SECTOR_IND | D10: 2024 | E10: 8649.772 | F10: 3 | G10: LFS - Labour Force Survey
A11: PHL | B11: SEX_T | C11: ECO_SECTOR_SER | D11: 2024 | E11: 29016.036 | F11: 3 | G11: LFS - Labour Force Survey
A12: VNM | B12: SEX_T | C12: ECO_SECTOR_TOTAL | D12: 2024 | E12: 55280.158 | F12: 3 | G12: LFS - Labour Force Survey
A13: VNM | B13: SEX_T | C13: ECO_SECTOR_AGR | D13: 2024 | E13: 13637.057 | F13: 3 | G13: LFS - Labour Force Survey
... A17: VNM | B17: SEX_T | C17: ECO_SECTOR_X | D17: 2024 | E17: 3845.332 | F17: 3 | G17: LFS - Labour Force Survey

Sheet Q1_calc
A1: rank i | B1: ordered x (VNM CPI %) | C1: year | D1: z=(x-mean)/s | E1: F_theoretical | F1: F_emp upper i/n | G1: D+ = i/n - F | H1: D- = F-(i-1)/n
A2: 1 | B2: -1.7103373 | C2: 2000 | D2: =(B2-$K$2)/$K$3 | E2: =NORMSDIST(D2) | F2: =A2/$K$4 | G2: =F2-E2 | H2: =E2-(A2-1)/$K$4 | J2: mean | K2: =AVERAGE(B2:B31)
A3: 2 | B3: -0.43154451 | C3: 2001 | D3: =(B3-$K$2)/$K$3 | E3: =NORMSDIST(D3) | F3: =A3/$K$4 | G3: =F3-E3 | H3: =E3-(A3-1)/$K$4 | J3: sd (n-1) | K3: =STDEV(B2:B31)
A4: 3 | B4: 0.63120091 | C4: 2015 | D4: =(B4-$K$2)/$K$3 | E4: =NORMSDIST(D4) | F4: =A4/$K$4 | G4: =F4-E4 | H4: =E4-(A4-1)/$K$4 | J4: n | K4: =COUNT(B2:B31)
A5: 4 | B5: 1.8347155 | C5: 2021 | D5: =(B5-$K$2)/$K$3 | E5: =NORMSDIST(D5) | F5: =A5/$K$4 | G5: =F5-E5 | H5: =E5-(A5-1)/$K$4 | J5: D = max(D+,D-) | K5: =MAX(G2:H31)
A6: 5 | B6: 2.6682482 | C6: 2016 | D6: =(B6-$K$2)/$K$3 | E6: =NORMSDIST(D6) | F6: =A6/$K$4 | G6: =F6-E6 | H6: =E6-(A6-1)/$K$4 | J6: Lilliefors crit 5% (n=30) | K6: 0.161
A7: 6 | B7: 2.7958237 | C7: 2019 | D7: =(B7-$K$2)/$K$3 | E7: =NORMSDIST(D7) | F7: =A7/$K$4 | G7: =F7-E7 | H7: =E7-(A7-1)/$K$4 | J7: Reject H0? | K7: =IF(K5>K6,"REJECT normality","do not reject")
A8: 7 | B8: 3.1565075 | C8: 2022 | D8: =(B8-$K$2)/$K$3 | E8: =NORMSDIST(D8) | F8: =A8/$K$4 | G8: =F8-E8 | H8: =E8-(A8-1)/$K$4
A9: 8 | B9: 3.2095261 | C9: 1997 | D9: =(B9-$K$2)/$K$3 | E9: =NORMSDIST(D9) | F9: =A9/$K$4 | G9: =F9-E9 | H9: =E9-(A9-1)/$K$4 | J9: Python p (statsmodels, table) | K9: 0.0016886936
A10: 9 | B10: 3.2209344 | C10: 2020 | D10: =(B10-$K$2)/$K$3 | E10: =NORMSDIST(D10) | F10: =A10/$K$4 | G10: =F10-E10 | H10: =E10-(A10-1)/$K$4
A11: 10 | B11: 3.2346482 | C11: 2003 | D11: =(B11-$K$2)/$K$3 | E11: =NORMSDIST(D11) | F11: =A11/$K$4 | G11: =F11-E11 | H11: =E11-(A11-1)/$K$4
A12: 11 | B12: 3.2528928 | C12: 2023 | D12: =(B12-$K$2)/$K$3 | E12: =NORMSDIST(D12) | F12: =A12/$K$4 | G12: =F12-E12 | H12: =E12-(A12-1)/$K$4
A13: 12 | B13: 3.3099931 | C13: 2025 | D13: =(B13-$K$2)/$K$3 | E13: =NORMSDIST(D13) | F13: =A13/$K$4 | G13: =F13-E13 | H13: =E13-(A13-1)/$K$4
A14: 13 | B14: 3.5202569 | C14: 2017 | D14: =(B14-$K$2)/$K$3 | E14: =NORMSDIST(D14) | F14: =A14/$K$4 | G14: =F14-E14 | H14: =E14-(A14-1)/$K$4
A15: 14 | B15: 3.5396281 | C15: 2018 | D15: =(B15-$K$2)/$K$3 | E15: =NORMSDIST(D15) | F15: =A15/$K$4 | G15: =F15-E15 | H15: =E15-(A15-1)/$K$4
A16: 15 | B16: 3.6210927 | C16: 2024 | D16: =(B16-$K$2)/$K$3 | E16: =NORMSDIST(D16) | F16: =A16/$K$4 | G16: =F16-E16 | H16: =E16-(A16-1)/$K$4
A17: 16 | B17: 3.8308284 | C17: 2002 | D17: =(B17-$K$2)/$K$3 | E17: =NORMSDIST(D17) | F17: =A17/$K$4 | G17: =F17-E17 | H17: =E17-(A17-1)/$K$4
A18: 17 | B18: 4.0845545 | C18: 2014 | D18: =(B18-$K$2)/$K$3 | E18: =NORMSDIST(D18) | F18: =A18/$K$4 | G18: =F18-E18 | H18: =E18-(A18-1)/$K$4
A19: 18 | B19: 4.1171024 | C19: 1999 | D19: =(B19-$K$2)/$K$3 | E19: =NORMSDIST(D19) | F19: =A19/$K$4 | G19: =F19-E19 | H19: =E19-(A19-1)/$K$4
A20: 19 | B20: 5.675 | C20: 1996 | D20: =(B20-$K$2)/$K$3 | E20: =NORMSDIST(D20) | F20: =A20/$K$4 | G20: =F20-E20 | H20: =E20-(A20-1)/$K$4
A21: 20 | B21: 6.5926748 | C21: 2013 | D21: =(B21-$K$2)/$K$3 | E21: =NORMSDIST(D21) | F21: =A21/$K$4 | G21: =F21-E21 | H21: =E21-(A21-1)/$K$4
... A31: 30 | B31: 23.115448 | C31: 2008 | D31: =(B31-$K$2)/$K$3 | E31: =NORMSDIST(D31) | F31: =A31/$K$4 | G31: =F31-E31 | H31: =E31-(A31-1)/$K$4

Sheet Q2_calc
A1: OBSERVED (persons = thousands x 1000) | B1: Unemployed | C1: Employed | D1: Row total
A2: Viet Nam | B2: 858467 | C2: 55280158 | D2: =SUM(B2:C2)
A3: Philippines | B3: 1147686 | C3: 47524318 | D3: =SUM(B3:C3)
A4: Col total | B4: =SUM(B2:B3) | C4: =SUM(C2:C3) | D4: =SUM(D2:D3)
A6: EXPECTED = row total x col total / N | B6: Unemployed | C6: Employed
A7: Viet Nam | B7: =$D2*B$4/$D$4 | C7: =$D2*C$4/$D$4
A8: Philippines | B8: =$D3*B$4/$D$4 | C8: =$D3*C$4/$D$4
A10: (O-E)^2/E | B10: Unemployed | C10: Employed
A11: Viet Nam | B11: =(B2-B7)^2/B7 | C11: =(C2-C7)^2/C7
A12: Philippines | B12: =(B3-B8)^2/B8 | C12: =(C3-C8)^2/C8
A14: Chi-square | B14: =SUM(B11:C12)
A15: df | B15: 1
A16: p-value | B16: =CHIDIST(B14,B15)
A17: Cramer's V | B17: =SQRT(B14/(B4*0+D4*1))
A19: ILO weighted survey estimates, 2024, age 15+. Naive chi-square on these counts overstates significance (see report). Sensitivity with illustrative n_eff in Results sheet.

Sheet Q3_calc
A1: OBSERVED (persons = thousands x 1000) | B1: Agriculture | C1: Industry | D1: Services | E1: Row total
A2: Viet Nam | B2: 13637057 | C2: 17131226 | D2: 20666543 | E2: =SUM(B2:D2)
A3: Philippines | B3: 9858510 | C3: 8649772 | D3: 29016036 | E3: =SUM(B3:D3)
A4: Col total | B4: =SUM(B2:B3) | C4: =SUM(C2:C3) | D4: =SUM(D2:D3) | E4: =SUM(E2:E3)
A6: EXPECTED = row total x col total / N | B6: Agriculture | C6: Industry | D6: Services
A7: Viet Nam | B7: =$E2*B$4/$E$4 | C7: =$E2*C$4/$E$4 | D7: =$E2*D$4/$E$4
A8: Philippines | B8: =$E3*B$4/$E$4 | C8: =$E3*C$4/$E$4 | D8: =$E3*D$4/$E$4
A10: (O-E)^2/E | B10: Agriculture | C10: Industry | D10: Services
A11: Viet Nam | B11: =(B2-B7)^2/B7 | C11: =(C2-C7)^2/C7 | D11: =(D2-D7)^2/D7
A12: Philippines | B12: =(B3-B8)^2/B8 | C12: =(C3-C8)^2/C8 | D12: =(D3-D8)^2/D8
A14: Chi-square | B14: =SUM(B11:D12)
A15: df | B15: 2
A16: p-value | B16: =CHIDIST(B14,B15)
A17: Cramer's V | B17: =SQRT(B14/(B4*0+E4*1))
A19: Viet Nam: 3,845,332 workers 'not classified' (ECO_SECTOR_X) excluded; 2x4 robustness in Results sheet.

Sheet Q4_panel
A1: index | B1: year | C1: VNM | D1: PHL | E1: IND
A2: 0 | B2: 2000 | C2: 6.7873164 | D2: 4.382505 | E2: 3.8409912
A3: 1 | B3: 2001 | C3: 6.1928933 | D3: 3.0492313 | E3: 4.8239663
A4: 2 | B4: 2002 | C4: 6.320821 | D4: 3.716255 | E4: 3.8039753
A5: 3 | B5: 2003 | C5: 6.8990635 | D5: 5.0869111 | E5: 7.8603815
A6: 4 | B6: 2004 | C6: 7.5364106 | D6: 6.5692285 | E6: 7.9229366
A7: 5 | B7: 2005 | C7: 7.5472477 | D7: 4.9425051 | E7: 7.9234306
A8: 6 | B8: 2006 | C8: 6.9779548 | D8: 5.3164168 | E8: 8.0607326
A9: 7 | B9: 2007 | C9: 7.1295045 | D9: 6.5192916 | E9: 7.6608151
A10: 8 | B10: 2008 | C10: 5.6617712 | D10: 4.3444873 | E10: 3.0866981
A11: 9 | B11: 2009 | C11: 5.3978975 | D11: 1.4483231 | E11: 7.8618888
A12: 10 | B12: 2010 | C12: 6.4232448 | D12: 7.3345 | E12: 8.4975847
A13: 11 | B13: 2011 | C13: 6.4131689 | D13: 3.8582328 | E13: 5.2413162
... A26: 24 | B26: 2024 | C26: 7.039552 | D26: 5.7147453 | E26: 7.0992789

Sheet Q5_data
A1: index | B1: year | C1: GDP_growth | D1: Investment_pctGDP | E1: Inflation
A2: 0 | B2: 1996 | C2: 9.3400175 | D2: 28.102898 | E2: 5.675
A3: 1 | B3: 1997 | C3: 8.1520841 | D3: 28.299583 | E3: 3.2095261
A4: 2 | B4: 1998 | C4: 5.7644555 | D4: 29.049879 | E4: 7.266198
A5: 3 | B5: 1999 | C5: 4.7735869 | D5: 27.629756 | E5: 4.1171024
A6: 4 | B6: 2000 | C6: 6.7873164 | D6: 29.609914 | E6: -1.7103373
A7: 5 | B7: 2001 | C7: 6.1928933 | D7: 31.172773 | E7: -0.43154451
A8: 6 | B8: 2002 | C8: 6.320821 | D8: 33.220534 | E8: 3.8308284
A9: 7 | B9: 2003 | C9: 6.8990635 | D9: 35.444858 | E9: 3.2346482
A10: 8 | B10: 2004 | C10: 7.5364106 | D10: 35.465332 | E10: 7.7549475
A11: 9 | B11: 2005 | C11: 7.5472477 | D11: 33.757403 | E11: 8.2845724
A12: 10 | B12: 2006 | C12: 6.9779548 | D12: 34.536651 | E12: 7.4180172
A13: 11 | B13: 2007 | C13: 7.1295045 | D13: 39.566271 | E13: 8.3444489
... A31: 29 | B31: 2025 | C31: 8.01883 | D31: 30.795135 | E31: 3.3099931

Sheet Q6_series
A1: index | B1: year | C1: Exports_USD_bn
A2: 0 | B2: 1986 | C2: 1.7441528
A3: 1 | B3: 1987 | C3: 2.2000101
A4: 2 | B4: 1988 | C4: 1.0030452
A5: 3 | B5: 1989 | C5: 1.5009128
A6: 4 | B6: 1990 | C6: 2.3323257
A7: 5 | B7: 1991 | C7: 2.971977
A8: 6 | B8: 1992 | C8: 3.4283445
A9: 7 | B9: 1993 | C9: 3.7859367
A10: 8 | B10: 1994 | C10: 5.5395256
A11: 9 | B11: 1995 | C11: 6.8041276
A12: 10 | B12: 1996 | C12: 10.077135
A13: 11 | B13: 1997 | C13: 11.570361
... A41: 39 | B41: 2025 | C41: 505.66123

Sheet Q6_holdout
A1: index | B1: year | C1: actual | D1: linear_trend | E1: MA3_flat | F1: MA3_rolling_1step | G1: loglinear_trend | H1: naive_last | I1: linear_trend_last10y | J1: damped_Holt
A2: 0 | B2: 2021 | C2: 343.93731 | D2: 210.05854 | E2: 279.6733 | F2: 279.6733 | G2: 489.9505 | H2: 292.4799 | I2: 317.57277 | J2: 311.08
A3: 1 | B3: 2022 | C3: 386.24107 | D3: 217.75356 | E3: 279.6733 | F3: 307.05154 | G3: 579.18532 | H3: 292.4799 | I3: 339.5125 | J3: 329.58711
A4: 2 | B4: 2023 | C4: 376.26802 | D4: 225.44859 | E4: 279.6733 | F4: 340.88609 | G4: 684.6725 | H4: 292.4799 | I4: 361.45222 | J4: 348.00167
A5: 3 | B5: 2024 | C5: 429.4841 | D5: 233.14362 | E5: 279.6733 | F5: 368.81547 | G5: 809.37209 | H5: 292.4799 | I5: 383.39195 | J5: 366.32417
A6: 4 | B6: 2025 | C6: 505.66123 | D6: 240.83865 | E6: 279.6733 | F6: 397.33106 | G6: 956.78325 | H6: 292.4799 | I6: 405.33167 | J6: 384.55505

Sheet Q7_SCR_alpha
A1: resp | B1: SCR1 | C1: SCR2 | D1: SCR3 | E1: SCR4 | F1: SCR5 | G1: SCR6 | H1: Total | I1: odd (1,3,5) | J1: even (2,4,6) | K1: Total-SCR1 | L1: Total-SCR2 | M1: Total-SCR3 | N1: Total-SCR4 | O1: Total-SCR5 | P1: Total-SCR6
A2: 1 | B2: 4 | C2: 4 | D2: 4 | E2: 4 | F2: 4 | G2: 4 | H2: =SUM(B2:G2) | I2: =B2+D2+F2 | J2: =C2+E2+G2 | K2: =H2-B2 | L2: =H2-C2 | M2: =H2-D2 | N2: =H2-E2 | O2: =H2-F2 | P2: =H2-G2
A3: 2 | B3: 5 | C3: 5 | D3: 5 | E3: 5 | F3: 5 | G3: 5 | H3: =SUM(B3:G3) | I3: =B3+D3+F3 | J3: =C3+E3+G3 | K3: =H3-B3 | L3: =H3-C3 | M3: =H3-D3 | N3: =H3-E3 | O3: =H3-F3 | P3: =H3-G3
A4: 3 | B4: 1 | C4: 1 | D4: 2 | E4: 5 | F4: 4 | G4: 5 | H4: =SUM(B4:G4) | I4: =B4+D4+F4 | J4: =C4+E4+G4 | K4: =H4-B4 | L4: =H4-C4 | M4: =H4-D4 | N4: =H4-E4 | O4: =H4-F4 | P4: =H4-G4
A5: 4 | B5: 2 | C5: 1 | D5: 1 | E5: 5 | F5: 5 | G5: 4 | H5: =SUM(B5:G5) | I5: =B5+D5+F5 | J5: =C5+E5+G5 | K5: =H5-B5 | L5: =H5-C5 | M5: =H5-D5 | N5: =H5-E5 | O5: =H5-F5 | P5: =H5-G5
A6: 5 | B6: 1 | C6: 3 | D6: 1 | E6: 5 | F6: 5 | G6: 4 | H6: =SUM(B6:G6) | I6: =B6+D6+F6 | J6: =C6+E6+G6 | K6: =H6-B6 | L6: =H6-C6 | M6: =H6-D6 | N6: =H6-E6 | O6: =H6-F6 | P6: =H6-G6
A7: 6 | B7: 2 | C7: 2 | D7: 1 | E7: 4 | F7: 5 | G7: 4 | H7: =SUM(B7:G7) | I7: =B7+D7+F7 | J7: =C7+E7+G7 | K7: =H7-B7 | L7: =H7-C7 | M7: =H7-D7 | N7: =H7-E7 | O7: =H7-F7 | P7: =H7-G7
A8: 7 | B8: 2 | C8: 1 | D8: 1 | E8: 5 | F8: 5 | G8: 4 | H8: =SUM(B8:G8) | I8: =B8+D8+F8 | J8: =C8+E8+G8 | K8: =H8-B8 | L8: =H8-C8 | M8: =H8-D8 | N8: =H8-E8 | O8: =H8-F8 | P8: =H8-G8
A9: 8 | B9: 1 | C9: 3 | D9: 1 | E9: 5 | F9: 5 | G9: 4 | H9: =SUM(B9:G9) | I9: =B9+D9+F9 | J9: =C9+E9+G9 | K9: =H9-B9 | L9: =H9-C9 | M9: =H9-D9 | N9: =H9-E9 | O9: =H9-F9 | P9: =H9-G9
A10: 9 | B10: 1 | C10: 1 | D10: 2 | E10: 4 | F10: 5 | G10: 4 | H10: =SUM(B10:G10) | I10: =B10+D10+F10 | J10: =C10+E10+G10 | K10: =H10-B10 | L10: =H10-C10 | M10: =H10-D10 | N10: =H10-E10 | O10: =H10-F10 | P10: =H10-G10
A11: 10 | B11: 1 | C11: 3 | D11: 1 | E11: 4 | F11: 5 | G11: 5 | H11: =SUM(B11:G11) | I11: =B11+D11+F11 | J11: =C11+E11+G11 | K11: =H11-B11 | L11: =H11-C11 | M11: =H11-D11 | N11: =H11-E11 | O11: =H11-F11 | P11: =H11-G11
A12: 11 | B12: 2 | C12: 1 | D12: 3 | E12: 4 | F12: 4 | G12: 5 | H12: =SUM(B12:G12) | I12: =B12+D12+F12 | J12: =C12+E12+G12 | K12: =H12-B12 | L12: =H12-C12 | M12: =H12-D12 | N12: =H12-E12 | O12: =H12-F12 | P12: =H12-G12
A13: 12 | B13: 2 | C13: 1 | D13: 2 | E13: 4 | F13: 3 | G13: 4 | H13: =SUM(B13:G13) | I13: =B13+D13+F13 | J13: =C13+E13+G13 | K13: =H13-B13 | L13: =H13-C13 | M13: =H13-D13 | N13: =H13-E13 | O13: =H13-F13 | P13: =H13-G13
... A249: 248 | B249: 2 | C249: 2 | D249: 1 | E249: 2 | F249: 2 | G249: 2 | H249: =SUM(B249:G249) | I249: =B249+D249+F249 | J249: =C249+E249+G249 | K249: =H249-B249 | L249: =H249-C249 | M249: =H249-D249 | N249: =H249-E249 | O249: =H249-F249 | P249: =H249-G249
A251: Variance (n-1) | B251: =VAR(B2:B249) | C251: =VAR(C2:C249) | D251: =VAR(D2:D249) | E251: =VAR(E2:E249) | F251: =VAR(F2:F249) | G251: =VAR(G2:G249) | H251: =VAR(H2:H249)
A252: Corrected item-total r | B252: =CORREL(B2:B249,K2:K249) | C252: =CORREL(C2:C249,L2:L249) | D252: =CORREL(D2:D249,M2:M249) | E252: =CORREL(E2:E249,N2:N249) | F252: =CORREL(F2:F249,O2:O249) | G252: =CORREL(G2:G249,P2:P249)
A253: Cronbach alpha | B253: =6/5*(1-SUM(B251:G251)/H251)
A254: Odd-even r | B254: =CORREL(I2:I249,J2:J249)
A255: Spearman-Brown | B255: =2*B254/(1+B254)
A257: Source: Zenodo 10.5281/zenodo.22057938, DATAUPDATE.csv, columns SCR1-SCR6 (real respondent data, n=248). No simulated data.

Sheet Raw_Zenodo_B_all18
A1: SCRMC1 | B1: SCRMC2 | C1: SCRMC3 | D1: SCRMC4 | E1: SCA1 | F1: SCA2 | G1: SCA3 | H1: SCA4 | I1: SCR1 | J1: SCR2 | K1: SCR3 | L1: SCR4 | M1: SCR5 | N1: SCR6 | O1: BP1 | P1: BP2 | Q1: BP3 | R1: BP4
A2: 5 | B2: 4 | C2: 5 | D2: 4 | E2: 4 | F2: 4 | G2: 4 | H2: 4 | I2: 4 | J2: 4 | K2: 4 | L2: 4 | M2: 4 | N2: 4 | O2: 4 | P2: 4 | Q2: 4 | R2: 4
A3: 5 | B3: 5 | C3: 5 | D3: 5 | E3: 5 | F3: 5 | G3: 5 | H3: 5 | I3: 5 | J3: 5 | K3: 5 | L3: 5 | M3: 5 | N3: 5 | O3: 5 | P3: 5 | Q3: 5 | R3: 5
A4: 5 | B4: 4 | C4: 5 | D4: 5 | E4: 5 | F4: 5 | G4: 5 | H4: 5 | I4: 1 | J4: 1 | K4: 2 | L4: 5 | M4: 4 | N4: 5 | O4: 4 | P4: 5 | Q4: 5 | R4: 5
A5: 5 | B5: 4 | C5: 5 | D5: 4 | E5: 3 | F5: 4 | G5: 5 | H5: 5 | I5: 2 | J5: 1 | K5: 1 | L5: 5 | M5: 5 | N5: 4 | O5: 4 | P5: 3 | Q5: 4 | R5: 5
A6: 5 | B6: 4 | C6: 4 | D6: 5 | E6: 3 | F6: 4 | G6: 4 | H6: 5 | I6: 1 | J6: 3 | K6: 1 | L6: 5 | M6: 5 | N6: 4 | O6: 4 | P6: 3 | Q6: 5 | R6: 4
A7: 5 | B7: 4 | C7: 3 | D7: 4 | E7: 5 | F7: 5 | G7: 4 | H7: 5 | I7: 2 | J7: 2 | K7: 1 | L7: 4 | M7: 5 | N7: 4 | O7: 4 | P7: 3 | Q7: 4 | R7: 5
A8: 5 | B8: 4 | C8: 3 | D8: 4 | E8: 5 | F8: 4 | G8: 3 | H8: 4 | I8: 2 | J8: 1 | K8: 1 | L8: 5 | M8: 5 | N8: 4 | O8: 4 | P8: 4 | Q8: 4 | R8: 5
A9: 5 | B9: 4 | C9: 3 | D9: 4 | E9: 5 | F9: 5 | G9: 4 | H9: 4 | I9: 1 | J9: 3 | K9: 1 | L9: 5 | M9: 5 | N9: 4 | O9: 4 | P9: 3 | Q9: 5 | R9: 5
A10: 5 | B10: 4 | C10: 4 | D10: 5 | E10: 4 | F10: 5 | G10: 4 | H10: 3 | I10: 1 | J10: 1 | K10: 2 | L10: 4 | M10: 5 | N10: 4 | O10: 4 | P10: 3 | Q10: 4 | R10: 5
A11: 5 | B11: 4 | C11: 4 | D11: 5 | E11: 5 | F11: 4 | G11: 3 | H11: 4 | I11: 1 | J11: 3 | K11: 1 | L11: 4 | M11: 5 | N11: 5 | O11: 4 | P11: 3 | Q11: 4 | R11: 5
A12: 5 | B12: 3 | C12: 5 | D12: 5 | E12: 4 | F12: 4 | G12: 5 | H12: 4 | I12: 2 | J12: 1 | K12: 3 | L12: 4 | M12: 4 | N12: 5 | O12: 4 | P12: 3 | Q12: 4 | R12: 5
A13: 5 | B13: 4 | C13: 3 | D13: 4 | E13: 5 | F13: 5 | G13: 4 | H13: 4 | I13: 2 | J13: 1 | K13: 2 | L13: 4 | M13: 3 | N13: 4 | O13: 5 | P13: 5 | Q13: 4 | R13: 5
... A249: 1 | B249: 1 | C249: 2 | D249: 2 | E249: 2 | F249: 5 | G249: 2 | H249: 2 | I249: 2 | J249: 2 | K249: 1 | L249: 2 | M249: 2 | N249: 2 | O249: 1 | P249: 1 | Q249: 2 | R249: 2

Sheet Q7_OR_items_dsA
A1: Unnamed: 0 | B1: OR1 | C1: OR2 | D1: OR3 | E1: OR4 | F1: OR5
A2: 0 | B2: 6 | C2: 5 | D2: 6 | E2: 6 | F2: 6
A3: 1 | B3: 6 | C3: 7 | D3: 6 | E3: 7 | F3: 7
A4: 2 | B4: 6 | C4: 7 | D4: 6 | E4: 7 | F4: 6
A5: 3 | B5: 7 | C5: 5 | D5: 7 | E5: 6 | F5: 6
A6: 4 | B6: 6 | C6: 7 | D6: 6 | E6: 6 | F6: 7
A7: 5 | B7: 7 | C7: 5 | D7: 7 | E7: 6 | F7: 6
A8: 6 | B8: 7 | C8: 5 | D8: 7 | E8: 6 | F8: 6
A9: 7 | B9: 7 | C9: 6 | D9: 6 | E9: 7 | F9: 6
A10: 8 | B10: 6 | C10: 7 | D10: 6 | E10: 7 | F10: 6
A11: 9 | B11: 6 | C11: 7 | D11: 6 | E11: 5 | F11: 7
A12: 10 | B12: 7 | C12: 6 | D12: 7 | E12: 6 | F12: 6
A13: 11 | B13: 6 | C13: 7 | D13: 6 | E13: 6 | F13: 7
... A248: 246 | B248: 7 | C248: 7 | D248: 5 | E248: 7 | F248: 6

Sheet Q7_protocol
A1: Six designed items and protocol: see report Section 7. Reliability computed on public Zenodo data (dataset B primary, dataset A comparison). q7_reliability.py reproduces the statistics from any CSV with columns item1..item6.

Sheet Results
A1: key | B1: value
A2: Q1.n | B2: 30
A3: Q1.years | B3: [1996, 2025]
A4: Q1.mean | B4: 5.5344754
A5: Q1.sd | B5: 5.0157312
A6: Q1.skew | B6: 2.0364567
A7: Q1.kurt_excess | B7: 5.4449116
A8: Q1.D | B8: 0.21125272
A9: Q1.D_statsmodels | B9: 0.21125272
A10: Q1.p_lilliefors | B10: 0.0016886936
A11: Q1.crit05 | B11: 0.161
A12: Q1.reject | B12: TRUE
A13: Q1.shapiro_W | B13: 0.79453781
A14: Q1.shapiro_p | B14: 5.2215419e-05
A15: Q1.jb | B15: 42.724221
A16: Q1.jb_p | B16: 5.2790187e-10
A17: Q1.lag1_autocorr | B17: 0.43775257
A18: Q1.log_D | B18: 0.20780422
A19: Q1.log_p | B19: 0.0021765506
A20: Q1.min | B20: -1.7103373
A21: Q1.max | B21: 23.115448
A22: Q1.argmax_year | B22: 2008
A23: Q1.median | B23: 3.7259606
A24: Q2.chi2 | B24: 95384.786
... A26: Q2.dof | B26: 1
A27: Q2.expected | B27: [[1074534.8256580448, 55064090.174341954], [931618.1743419553, 47740385.825658046]]
A28: Q2.observed | B28: [[858467.0, 55280158.0], [1147686.0, 47524318.0]]
A29: Q2.cramers_v | B29: 0.030167331
A30: Q2.min_expected | B30: 931618.17
A31: Q2.std_resid | B31: [[-208.4394189167086, 29.1176195774973], [223.85722993327747, -31.271386644357104]]
A32: Q2.chi2_yates | B32: 95384.345
A33: Q2.p_yates | B33: 0
A34: Q2.rows | B34: ["Viet Nam", "Philippines"]
A35: Q2.cols | B35: ["Unemployed", "Employed"]
A36: Q2.N | B36: 104810629
A37: Q2.rates.VNM | B37: 0.015291914
A38: Q2.rates.PHL | B38: 0.023580003
A39: Q2.rates.IND | B39: 0.041728939
A40: Q2.diff | B40: -0.0082880894
A41: Q2.ci_naive | B41: [-0.00834145308510303, -0.00823472581234294]
...
