Workbook

Sheet README
A1: Soal 7 - Item analysis and reliability of the TB scale (TB1-TB6)
A2: Data source (verified from the uploaded files only)
A3: File 1: Electric_Cars_Purchase_Intention-Data_in_Brief.csv (MD5 09e51b6cd9256e2b3c7d0faef39daf9d), 510 data rows x 41 columns.
A4: File 2: Electric_Cars_Purchase_Intention-Maheswaran_and_Veena.sav (MD5 5bbeb8c35e913cba2aa6b264b5a7a33b), SPSS 23, created 21 May 2021; item values identical to File 1.
A5: Dataset landing page named by the user: https://data.mendeley.com/datasets/tz7krp8rvz/2 (could not be opened from the analysis environment; licence, version and citation NOT verified).
A6: Item wording below comes from the SPSS variable labels. The SPSS file has NO value labels for the Likert items: the meaning of codes 1-5 is NOT documented in the files.
A7: Construct name for 'TB' is NOT documented in the files.
A8: Sheets
A9: Raw_Data: the CSV exactly as uploaded (blank cells kept blank). Do not edit.
A10: Data_Check: range, missing-value and duplicate checks computed from Raw_Data.
A11: TB_Primary: TB1-TB6 linked from Raw_Data (n = 510) with total, rest scores and odd/even half scores.
A12: TB_Sensitivity: same, excluding Raw_Data row 142 (data row 141), the second of two rows identical on all 41 variables (n = 509).
... A20: Criteria (assumed; official Soal 7 criteria not available): corrected item-total r >= 0.30; alpha / Spearman-Brown >= 0.70 acceptable, 0.60-0.69 questionable, < 0.60 poor.

Sheet Item_Analysis
A1: Item analysis: corrected item-total correlation (CITC) = Pearson r between an item and the sum of the other five TB items
A2: CITC criterion (assumed; edit if the lecturer specifies another) | F2: 0.3
A3: Alpha for significance tests | F3: 0.05
A5: PRIMARY ANALYSIS (n = 510, as published)
A6: n | B6: =COUNT(TB_Primary!$H$2:$H$511) -> 510
A7: r critical (two-tailed) | B7: =TINV($F$3,B6-2)/SQRT(TINV($F$3,B6-2)^2+B6-2) -> 0.08683774
A9: Item | B9: Wording | C9: Mean | D9: SD | E9: Variance | F9: r item-total (uncorrected) | G9: CITC | H9: t | I9: p (two-tailed) | J9: Alpha if item deleted | K9: Meets CITC >= criterion? | L9: Statistically significant?
A10: TB1 | B10: I think e-cars are sleek | C10: =AVERAGE(TB_Primary!$B$2:$B$511) -> 3.754902 | D10: =STDEV(TB_Primary!$B$2:$B$511) -> 0.97348214 | E10: =VAR(TB_Primary!$B$2:$B$511) -> 0.94766748 | F10: =CORREL(TB_Primary!$B$2:$B$511,TB_Primary!$H$2:$H$511) -> 0.59179793 | G10: =CORREL(TB_Primary!$B$2:$B$511,TB_Primary!$I$2:$I$511) -> 0.29248686 | H10: =G10*SQRT(($B$6-2)/(1-G10^2)) -> 6.8937875 | I10: =TDIST(ABS(H10),$B$6-2,2) -> 1.6174168e-11 | J10: =(5/4)*(1-(SUM($E$10:$E$15)-E10)/VAR(TB_Primary!$I$2:$I$511)) -> 0.33454198 | K10: =IF(G10>=$F$2,"Yes","No") -> No | L10: =IF(I10<$F$3,"Yes","No") -> Yes
A11: TB2 | B11: I think e-cars are durable | C11: =AVERAGE(TB_Primary!$C$2:$C$511) -> 3.0686275 | D11: =STDEV(TB_Primary!$C$2:$C$511) -> 1.0132696 | E11: =VAR(TB_Primary!$C$2:$C$511) -> 1.0267152 | F11: =CORREL(TB_Primary!$C$2:$C$511,TB_Primary!$H$2:$H$511) -> 0.50896507 | G11: =CORREL(TB_Primary!$C$2:$C$511,TB_Primary!$J$2:$J$511) -> 0.17123658 | H11: =G11*SQRT(($B$6-2)/(1-G11^2)) -> 3.9173357 | I11: =TDIST(ABS(H11),$B$6-2,2) -> 0.00010177598 | J11: =(5/4)*(1-(SUM($E$10:$E$15)-E11)/VAR(TB_Primary!$J$2:$J$511)) -> 0.41411447 | K11: =IF(G11>=$F$2,"Yes","No") -> No | L11: =IF(I11<$F$3,"Yes","No") -> Yes
A12: TB3 | B12: I think e-cars are available in different size, colours and designs | C12: =AVERAGE(TB_Primary!$D$2:$D$511) -> 4.0509804 | D12: =STDEV(TB_Primary!$D$2:$D$511) -> 0.87384446 | E12: =VAR(TB_Primary!$D$2:$D$511) -> 0.76360414 | F12: =CORREL(TB_Primary!$D$2:$D$511,TB_Primary!$H$2:$H$511) -> 0.4614002 | G12: =CORREL(TB_Primary!$D$2:$D$511,TB_Primary!$K$2:$K$511) -> 0.16831647 | H12: =G12*SQRT(($B$6-2)/(1-G12^2)) -> 3.848568 | I12: =TDIST(ABS(H12),$B$6-2,2) -> 0.00013395332 | J12: =(5/4)*(1-(SUM($E$10:$E$15)-E12)/VAR(TB_Primary!$K$2:$K$511)) -> 0.41125979 | K12: =IF(G12>=$F$2,"Yes","No") -> No | L12: =IF(I12<$F$3,"Yes","No") -> Yes
A13: TB4 | B13: I think e-cars are aesthetically appealing | C13: =AVERAGE(TB_Primary!$E$2:$E$511) -> 3.3392157 | D13: =STDEV(TB_Primary!$E$2:$E$511) -> 0.80068204 | E13: =VAR(TB_Primary!$E$2:$E$511) -> 0.64109172 | F13: =CORREL(TB_Primary!$E$2:$E$511,TB_Primary!$H$2:$H$511) -> 0.5640402 | G13: =CORREL(TB_Primary!$E$2:$E$511,TB_Primary!$L$2:$L$511) -> 0.32120709 | H13: =G13*SQRT(($B$6-2)/(1-G13^2)) -> 7.6447428 | I13: =TDIST(ABS(H13),$B$6-2,2) -> 1.0538504e-13 | J13: =(5/4)*(1-(SUM($E$10:$E$15)-E13)/VAR(TB_Primary!$L$2:$L$511)) -> 0.33103521 | K13: =IF(G13>=$F$2,"Yes","No") -> Yes | L13: =IF(I13<$F$3,"Yes","No") -> Yes
A14: TB5 | B14: I think e-cars are technologically superior | C14: =AVERAGE(TB_Primary!$F$2:$F$511) -> 2.9058824 | D14: =STDEV(TB_Primary!$F$2:$F$511) -> 0.93762476 | E14: =VAR(TB_Primary!$F$2:$F$511) -> 0.87914018 | F14: =CORREL(TB_Primary!$F$2:$F$511,TB_Primary!$H$2:$H$511) -> 0.41168415 | G14: =CORREL(TB_Primary!$F$2:$F$511,TB_Primary!$M$2:$M$511) -> 0.086530634 | H14: =G14*SQRT(($B$6-2)/(1-G14^2)) -> 1.9576442 | I14: =TDIST(ABS(H14),$B$6-2,2) -> 0.050818847 | J14: =(5/4)*(1-(SUM($E$10:$E$15)-E14)/VAR(TB_Primary!$M$2:$M$511)) -> 0.45975266 | K14: =IF(G14>=$F$2,"Yes","No") -> No | L14: =IF(I14<$F$3,"Yes","No") -> No
A15: TB6 | B15: I think e-cars give comfortable ride | C15: =AVERAGE(TB_Primary!$G$2:$G$511) -> 3.0470588 | D15: =STDEV(TB_Primary!$G$2:$G$511) -> 0.90931718 | E15: =VAR(TB_Primary!$G$2:$G$511) -> 0.82685774 | F15: =CORREL(TB_Primary!$G$2:$G$511,TB_Primary!$H$2:$H$511) -> 0.53560575 | G15: =CORREL(TB_Primary!$G$2:$G$511,TB_Primary!$N$2:$N$511) -> 0.2446946 | H15: =G15*SQRT(($B$6-2)/(1-G15^2)) -> 5.6880518 | I15: =TDIST(ABS(H15),$B$6-2,2) -> 2.1716328e-08 | J15: =(5/4)*(1-(SUM($E$10:$E$15)-E15)/VAR(TB_Primary!$N$2:$N$511)) -> 0.36740945 | K15: =IF(G15>=$F$2,"Yes","No") -> No | L15: =IF(I15<$F$3,"Yes","No") -> Yes
A16: Items meeting CITC criterion | C16: =COUNTIF(K10:K15,"Yes")&" of 6" -> 1 of 6
A18: Inter-item Pearson correlations
B19: TB1 | C19: TB2 | D19: TB3 | E19: TB4 | F19: TB5 | G19: TB6
A20: TB1 | B20: =CORREL(TB_Primary!$B$2:$B$511,TB_Primary!$B$2:$B$511) -> 1 | C20: =CORREL(TB_Primary!$B$2:$B$511,TB_Primary!$C$2:$C$511) -> 0.04895346 | D20: =CORREL(TB_Primary!$B$2:$B$511,TB_Primary!$D$2:$D$511) -> 0.18100229 | E20: =CORREL(TB_Primary!$B$2:$B$511,TB_Primary!$E$2:$E$511) -> 0.30851943 | F20: =CORREL(TB_Primary!$B$2:$B$511,TB_Primary!$F$2:$F$511) -> 0.099517347 | G20: =CORREL(TB_Primary!$B$2:$B$511,TB_Primary!$G$2:$G$511) -> 0.1617563
A21: TB2 | B21: =CORREL(TB_Primary!$C$2:$C$511,TB_Primary!$B$2:$B$511) -> 0.04895346 | C21: =CORREL(TB_Primary!$C$2:$C$511,TB_Primary!$C$2:$C$511) -> 1 | D21: =CORREL(TB_Primary!$C$2:$C$511,TB_Primary!$D$2:$D$511) -> 0.11363865 | E21: =CORREL(TB_Primary!$C$2:$C$511,TB_Primary!$E$2:$E$511) -> 0.068112609 | F21: =CORREL(TB_Primary!$C$2:$C$511,TB_Primary!$F$2:$F$511) -> 0.079188155 | G21: =CORREL(TB_Primary!$C$2:$C$511,TB_Primary!$G$2:$G$511) -> 0.16067268
A22: TB3 | B22: =CORREL(TB_Primary!$D$2:$D$511,TB_Primary!$B$2:$B$511) -> 0.18100229 | C22: =CORREL(TB_Primary!$D$2:$D$511,TB_Primary!$C$2:$C$511) -> 0.11363865 | D22: =CORREL(TB_Primary!$D$2:$D$511,TB_Primary!$D$2:$D$511) -> 1 | E22: =CORREL(TB_Primary!$D$2:$D$511,TB_Primary!$E$2:$E$511) -> 0.27568476 | F22: =CORREL(TB_Primary!$D$2:$D$511,TB_Primary!$F$2:$F$511) -> -0.14519587 | G22: =CORREL(TB_Primary!$D$2:$D$511,TB_Primary!$G$2:$G$511) -> 0.056314354
A23: TB4 | B23: =CORREL(TB_Primary!$E$2:$E$511,TB_Primary!$B$2:$B$511) -> 0.30851943 | C23: =CORREL(TB_Primary!$E$2:$E$511,TB_Primary!$C$2:$C$511) -> 0.068112609 | D23: =CORREL(TB_Primary!$E$2:$E$511,TB_Primary!$D$2:$D$511) -> 0.27568476 | E23: =CORREL(TB_Primary!$E$2:$E$511,TB_Primary!$E$2:$E$511) -> 1 | F23: =CORREL(TB_Primary!$E$2:$E$511,TB_Primary!$F$2:$F$511) -> 0.063545359 | G23: =CORREL(TB_Primary!$E$2:$E$511,TB_Primary!$G$2:$G$511) -> 0.13184077
A24: TB5 | B24: =CORREL(TB_Primary!$F$2:$F$511,TB_Primary!$B$2:$B$511) -> 0.099517347 | C24: =CORREL(TB_Primary!$F$2:$F$511,TB_Primary!$C$2:$C$511) -> 0.079188155 | D24: =CORREL(TB_Primary!$F$2:$F$511,TB_Primary!$D$2:$D$511) -> -0.14519587 | E24: =CORREL(TB_Primary!$F$2:$F$511,TB_Primary!$E$2:$E$511) -> 0.063545359 | F24: =CORREL(TB_Primary!$F$2:$F$511,TB_Primary!$F$2:$F$511) -> 1 | G24: =CORREL(TB_Primary!$F$2:$F$511,TB_Primary!$G$2:$G$511) -> 0.13424542
A25: TB6 | B25: =CORREL(TB_Primary!$G$2:$G$511,TB_Primary!$B$2:$B$511) -> 0.1617563 | C25: =CORREL(TB_Primary!$G$2:$G$511,TB_Primary!$C$2:$C$511) -> 0.16067268 | D25: =CORREL(TB_Primary!$G$2:$G$511,TB_Primary!$D$2:$D$511) -> 0.056314354 | E25: =CORREL(TB_Primary!$G$2:$G$511,TB_Primary!$E$2:$E$511) -> 0.13184077 | F25: =CORREL(TB_Primary!$G$2:$G$511,TB_Primary!$F$2:$F$511) -> 0.13424542 | G25: =CORREL(TB_Primary!$G$2:$G$511,TB_Primary!$G$2:$G$511) -> 1
A27: Mean inter-item r (15 pairs) | C27: =(SUM(B20:G25)-6)/30 -> 0.11585305
A28: Smallest inter-item r | C28: =MIN(B20:G25) -> -0.14519587
A31: SENSITIVITY ANALYSIS (n = 509, second identical row removed)
A32: n | B32: =COUNT(TB_Sensitivity!$H$2:$H$510) -> 509
A33: r critical (two-tailed) | B33: =TINV($F$3,B32-2)/SQRT(TINV($F$3,B32-2)^2+B32-2) -> 0.086923097
A35: Item | B35: Wording | C35: Mean | D35: SD | E35: Variance | F35: r item-total (uncorrected) | G35: CITC | H35: t | I35: p (two-tailed) | J35: Alpha if item deleted | K35: Meets CITC >= criterion? | L35: Statistically significant?
A36: TB1 | B36: I think e-cars are sleek | C36: =AVERAGE(TB_Sensitivity!$B$2:$B$510) -> 3.7544204 | D36: =STDEV(TB_Sensitivity!$B$2:$B$510) -> 0.97437902 | E36: =VAR(TB_Sensitivity!$B$2:$B$510) -> 0.94941448 | F36: =CORREL(TB_Sensitivity!$B$2:$B$510,TB_Sensitivity!$H$2:$H$510) -> 0.59192536 | G36: =CORREL(TB_Sensitivity!$B$2:$B$510,TB_Sensitivity!$I$2:$I$510) -> 0.29230673 | H36: =G36*SQRT(($B$32-2)/(1-G36^2)) -> 6.8823612 | I36: =TDIST(ABS(H36),$B$32-2,2) -> 1.7441759e-11 | J36: =(5/4)*(1-(SUM($E$36:$E$41)-E36)/VAR(TB_Sensitivity!$I$2:$I$510)) -> 0.33497166 | K36: =IF(G36>=$F$2,"Yes","No") -> No | L36: =IF(I36<$F$3,"Yes","No") -> Yes
A37: TB2 | B37: I think e-cars are durable | C37: =AVERAGE(TB_Sensitivity!$C$2:$C$510) -> 3.064833 | D37: =STDEV(TB_Sensitivity!$C$2:$C$510) -> 1.0106329 | E37: =VAR(TB_Sensitivity!$C$2:$C$510) -> 1.021379 | F37: =CORREL(TB_Sensitivity!$C$2:$C$510,TB_Sensitivity!$H$2:$H$510) -> 0.50751568 | G37: =CORREL(TB_Sensitivity!$C$2:$C$510,TB_Sensitivity!$J$2:$J$510) -> 0.17049602 | H37: =G37*SQRT(($B$32-2)/(1-G37^2)) -> 3.8960455 | I37: =TDIST(ABS(H37),$B$32-2,2) -> 0.00011088633 | J37: =(5/4)*(1-(SUM($E$36:$E$41)-E37)/VAR(TB_Sensitivity!$J$2:$J$510)) -> 0.41479424 | K37: =IF(G37>=$F$2,"Yes","No") -> No | L37: =IF(I37<$F$3,"Yes","No") -> Yes
A38: TB3 | B38: I think e-cars are available in different size, colours and designs | C38: =AVERAGE(TB_Sensitivity!$D$2:$D$510) -> 4.0491159 | D38: =STDEV(TB_Sensitivity!$D$2:$D$510) -> 0.87368811 | E38: =VAR(TB_Sensitivity!$D$2:$D$510) -> 0.76333091 | F38: =CORREL(TB_Sensitivity!$D$2:$D$510,TB_Sensitivity!$H$2:$H$510) -> 0.46024369 | G38: =CORREL(TB_Sensitivity!$D$2:$D$510,TB_Sensitivity!$K$2:$K$510) -> 0.16701366 | H38: =G38*SQRT(($B$32-2)/(1-G38^2)) -> 3.8141614 | I38: =TDIST(ABS(H38),$B$32-2,2) -> 0.0001534892 | J38: =(5/4)*(1-(SUM($E$36:$E$41)-E38)/VAR(TB_Sensitivity!$K$2:$K$510)) -> 0.41227996 | K38: =IF(G38>=$F$2,"Yes","No") -> No | L38: =IF(I38<$F$3,"Yes","No") -> Yes
A39: TB4 | B39: I think e-cars are aesthetically appealing | C39: =AVERAGE(TB_Sensitivity!$E$2:$E$510) -> 3.3379175 | D39: =STDEV(TB_Sensitivity!$E$2:$E$510) -> 0.80093227 | E39: =VAR(TB_Sensitivity!$E$2:$E$510) -> 0.6414925 | F39: =CORREL(TB_Sensitivity!$E$2:$E$510,TB_Sensitivity!$H$2:$H$510) -> 0.5633453 | G39: =CORREL(TB_Sensitivity!$E$2:$E$510,TB_Sensitivity!$L$2:$L$510) -> 0.32023234 | H39: =G39*SQRT(($B$32-2)/(1-G39^2)) -> 7.6113857 | I39: =TDIST(ABS(H39),$B$32-2,2) -> 1.33303e-13 | J39: =(5/4)*(1-(SUM($E$36:$E$41)-E39)/VAR(TB_Sensitivity!$L$2:$L$510)) -> 0.33186842 | K39: =IF(G39>=$F$2,"Yes","No") -> Yes | L39: =IF(I39<$F$3,"Yes","No") -> Yes
A40: TB5 | B40: I think e-cars are technologically superior | C40: =AVERAGE(TB_Sensitivity!$F$2:$F$510) -> 2.9076621 | D40: =STDEV(TB_Sensitivity!$F$2:$F$510) -> 0.93768449 | E40: =VAR(TB_Sensitivity!$F$2:$F$510) -> 0.8792522 | F40: =CORREL(TB_Sensitivity!$F$2:$F$510,TB_Sensitivity!$H$2:$H$510) -> 0.41438776 | G40: =CORREL(TB_Sensitivity!$F$2:$F$510,TB_Sensitivity!$M$2:$M$510) -> 0.08955532 | H40: =G40*SQRT(($B$32-2)/(1-G40^2)) -> 2.024622 | I40: =TDIST(ABS(H40),$B$32-2,2) -> 0.043429866 | J40: =(5/4)*(1-(SUM($E$36:$E$41)-E40)/VAR(TB_Sensitivity!$M$2:$M$510)) -> 0.45837499 | K40: =IF(G40>=$F$2,"Yes","No") -> No | L40: =IF(I40<$F$3,"Yes","No") -> Yes
A41: TB6 | B41: I think e-cars give comfortable ride | C41: =AVERAGE(TB_Sensitivity!$G$2:$G$510) -> 3.0471513 | D41: =STDEV(TB_Sensitivity!$G$2:$G$510) -> 0.91020934 | E41: =VAR(TB_Sensitivity!$G$2:$G$510) -> 0.82848104 | F41: =CORREL(TB_Sensitivity!$G$2:$G$510,TB_Sensitivity!$H$2:$H$510) -> 0.53624271 | G41: =CORREL(TB_Sensitivity!$G$2:$G$510,TB_Sensitivity!$N$2:$N$510) -> 0.24514689 | H41: =G41*SQRT(($B$32-2)/(1-G41^2)) -> 5.693625 | I41: =TDIST(ABS(H41),$B$32-2,2) -> 2.1081136e-08 | J41: =(5/4)*(1-(SUM($E$36:$E$41)-E41)/VAR(TB_Sensitivity!$N$2:$N$510)) -> 0.36744632 | K41: =IF(G41>=$F$2,"Yes","No") -> No | L41: =IF(I41<$F$3,"Yes","No") -> Yes
A42: Items meeting CITC criterion | C42: =COUNTIF(K36:K41,"Yes")&" of 6" -> 1 of 6
A44: Inter-item Pearson correlations
B45: TB1 | C45: TB2 | D45: TB3 | E45: TB4 | F45: TB5 | G45: TB6
A46: TB1 | B46: =CORREL(TB_Sensitivity!$B$2:$B$510,TB_Sensitivity!$B$2:$B$510) -> 1 | C46: =CORREL(TB_Sensitivity!$B$2:$B$510,TB_Sensitivity!$C$2:$C$510) -> 0.048184382 | D46: =CORREL(TB_Sensitivity!$B$2:$B$510,TB_Sensitivity!$D$2:$D$510) -> 0.18068517 | E46: =CORREL(TB_Sensitivity!$B$2:$B$510,TB_Sensitivity!$E$2:$E$510) -> 0.3083364 | F46: =CORREL(TB_Sensitivity!$B$2:$B$510,TB_Sensitivity!$F$2:$F$510) -> 0.10009443 | G46: =CORREL(TB_Sensitivity!$B$2:$B$510,TB_Sensitivity!$G$2:$G$510) -> 0.16179248
A47: TB2 | B47: =CORREL(TB_Sensitivity!$C$2:$C$510,TB_Sensitivity!$B$2:$B$510) -> 0.048184382 | C47: =CORREL(TB_Sensitivity!$C$2:$C$510,TB_Sensitivity!$C$2:$C$510) -> 1 | D47: =CORREL(TB_Sensitivity!$C$2:$C$510,TB_Sensitivity!$D$2:$D$510) -> 0.11008553 | E47: =CORREL(TB_Sensitivity!$C$2:$C$510,TB_Sensitivity!$E$2:$E$510) -> 0.065293609 | F47: =CORREL(TB_Sensitivity!$C$2:$C$510,TB_Sensitivity!$F$2:$F$510) -> 0.083187434 | G47: =CORREL(TB_Sensitivity!$C$2:$C$510,TB_Sensitivity!$G$2:$G$510) -> 0.16144563
A48: TB3 | B48: =CORREL(TB_Sensitivity!$D$2:$D$510,TB_Sensitivity!$B$2:$B$510) -> 0.18068517 | C48: =CORREL(TB_Sensitivity!$D$2:$D$510,TB_Sensitivity!$C$2:$C$510) -> 0.11008553 | D48: =CORREL(TB_Sensitivity!$D$2:$D$510,TB_Sensitivity!$D$2:$D$510) -> 1 | E48: =CORREL(TB_Sensitivity!$D$2:$D$510,TB_Sensitivity!$E$2:$E$510) -> 0.27442301 | F48: =CORREL(TB_Sensitivity!$D$2:$D$510,TB_Sensitivity!$F$2:$F$510) -> -0.14342868 | G48: =CORREL(TB_Sensitivity!$D$2:$D$510,TB_Sensitivity!$G$2:$G$510) -> 0.056490757
...

Sheet Reliability
A1: Reliability of the 6-item TB scale
A2: CI level | C2: 0.95
A3: Acceptable threshold (assumed) | C3: 0.7
A4: Questionable threshold (assumed) | C4: 0.6
A6: Statistic | B6: Primary (n = 510) | C6: Sensitivity (n = 509) | D6: Formula / note
A7: n | B7: =COUNT(TB_Primary!$H$2:$H$511) -> 510 | C7: =COUNT(TB_Sensitivity!$H$2:$H$510) -> 509 | D7: COUNT of total scores
A8: k (items) | B8: 6 | C8: 6 | D8: TB1-TB6
A9: Sum of item variances | B9: =SUM(Item_Analysis!$E$10:$E$15) -> 5.0850765 | C9: =SUM(Item_Analysis!$E$36:$E$41) -> 5.0833501 | D9: SUM of VAR of each item (Item_Analysis col E)
A10: Variance of total score | B10: =VAR(TB_Primary!$H$2:$H$511) -> 7.9505566 | C10: =VAR(TB_Sensitivity!$H$2:$H$510) -> 7.9503736 | D10: VAR of Total
A11: Cronbach's alpha | B11: =(B8/(B8-1))*(1-B9/B10) -> 0.43249503 | C11: =(C8/(C8-1))*(1-C9/C10) -> 0.43273793 | D11: k/(k-1) * (1 - sum item var / total var)
A12: Alpha 95% CI lower (Feldt) | B12: =1-(1-B11)*FINV((1-$C$2)/2,B7-1,(B7-1)*(B8-1)) -> 0.35264832 | C12: =1-(1-C11)*FINV((1-$C$2)/2,C7-1,(C7-1)*(C8-1)) -> 0.3528434 | D12: 1-(1-alpha)*FINV(0.025, n-1, (n-1)(k-1))
A13: Alpha 95% CI upper (Feldt) | B13: =1-(1-B11)*FINV(1-(1-$C$2)/2,B7-1,(B7-1)*(B8-1)) -> 0.50553239 | C13: =1-(1-C11)*FINV(1-(1-$C$2)/2,C7-1,(C7-1)*(C8-1)) -> 0.50581263 | D13: 1-(1-alpha)*FINV(0.975, n-1, (n-1)(k-1))
A14: Alpha decision | B14: =IF(B11>=$C$3,"Acceptable",IF(B11>=$C$4,"Questionable","Poor")) -> Poor | C14: =IF(C11>=$C$3,"Acceptable",IF(C11>=$C$4,"Questionable","Poor")) -> Poor | D14: >= 0.70 acceptable; 0.60-0.69 questionable; < 0.60 poor
A15: r between odd and even half scores | B15: =CORREL(TB_Primary!$O$2:$O$511,TB_Primary!$P$2:$P$511) -> 0.33983097 | C15: =CORREL(TB_Sensitivity!$O$2:$O$510,TB_Sensitivity!$P$2:$P$510) -> 0.34005531 | D15: Odd = TB1+TB3+TB5, Even = TB2+TB4+TB6
A16: Spearman-Brown corrected split-half | B16: =2*B15/(1+B15) -> 0.50727439 | C16: =2*C15/(1+C15) -> 0.50752429 | D16: 2r / (1 + r)
A17: Split-half decision | B17: =IF(B16>=$C$3,"Acceptable",IF(B16>=$C$4,"Questionable","Poor")) -> Poor | C17: =IF(C16>=$C$3,"Acceptable",IF(C16>=$C$4,"Questionable","Poor")) -> Poor | D17: same thresholds
A18: Variance of odd half | B18: =VAR(TB_Primary!$O$2:$O$511) -> 2.842101 | C18: =VAR(TB_Sensitivity!$O$2:$O$510) -> 2.8475318
A19: Variance of even half | B19: =VAR(TB_Primary!$P$2:$P$511) -> 3.093247 | C19: =VAR(TB_Sensitivity!$P$2:$P$510) -> 3.08656
A20: Guttman split-half (lambda-4, same split; supplementary) | B20: =2*(1-(B18+B19)/B10) -> 0.50693522 | C20: =2*(1-(C18+C19)/C10) -> 0.50721685 | D20: 2*(1-(var odd + var even)/var total)

Sheet Cross_Check
A1: Cross-check: Excel formulas vs independent Python computation (pandas 2.x / scipy). Python values are pasted as fixed numbers.
A3: Analysis | B3: Statistic | C3: Excel (formula) | D3: Python (fixed value) | E3: Absolute difference
A4: Primary n=510 | B4: TB1 citc | C4: =Item_Analysis!G10 -> 0.29248686 | D4: 0.29248686 | E4: =ABS(C4-D4) -> 0
A5: Primary n=510 | B5: TB1 alpha_if_deleted | C5: =Item_Analysis!J10 -> 0.33454198 | D5: 0.33454198 | E5: =ABS(C5-D5) -> 1.2767565e-15
A6: Primary n=510 | B6: TB1 mean | C6: =Item_Analysis!C10 -> 3.754902 | D6: 3.754902 | E6: =ABS(C6-D6) -> 0
A7: Primary n=510 | B7: TB1 sd | C7: =Item_Analysis!D10 -> 0.97348214 | D7: 0.97348214 | E7: =ABS(C7-D7) -> 0
A8: Primary n=510 | B8: TB2 citc | C8: =Item_Analysis!G11 -> 0.17123658 | D8: 0.17123658 | E8: =ABS(C8-D8) -> 0
A9: Primary n=510 | B9: TB2 alpha_if_deleted | C9: =Item_Analysis!J11 -> 0.41411447 | D9: 0.41411447 | E9: =ABS(C9-D9) -> 2.6645353e-15
A10: Primary n=510 | B10: TB2 mean | C10: =Item_Analysis!C11 -> 3.0686275 | D10: 3.0686275 | E10: =ABS(C10-D10) -> 0
A11: Primary n=510 | B11: TB2 sd | C11: =Item_Analysis!D11 -> 1.0132696 | D11: 1.0132696 | E11: =ABS(C11-D11) -> 0
A12: Primary n=510 | B12: TB3 citc | C12: =Item_Analysis!G12 -> 0.16831647 | D12: 0.16831647 | E12: =ABS(C12-D12) -> 0
A13: Primary n=510 | B13: TB3 alpha_if_deleted | C13: =Item_Analysis!J12 -> 0.41125979 | D13: 0.41125979 | E13: =ABS(C13-D13) -> 2.4980018e-15
A14: Primary n=510 | B14: TB3 mean | C14: =Item_Analysis!C12 -> 4.0509804 | D14: 4.0509804 | E14: =ABS(C14-D14) -> 0
A15: Primary n=510 | B15: TB3 sd | C15: =Item_Analysis!D12 -> 0.87384446 | D15: 0.87384446 | E15: =ABS(C15-D15) -> 0
A16: Primary n=510 | B16: TB4 citc | C16: =Item_Analysis!G13 -> 0.32120709 | D16: 0.32120709 | E16: =ABS(C16-D16) -> 0
A17: Primary n=510 | B17: TB4 alpha_if_deleted | C17: =Item_Analysis!J13 -> 0.33103521 | D17: 0.33103521 | E17: =ABS(C17-D17) -> 1.9428903e-15
A18: Primary n=510 | B18: TB4 mean | C18: =Item_Analysis!C13 -> 3.3392157 | D18: 3.3392157 | E18: =ABS(C18-D18) -> 0
A19: Primary n=510 | B19: TB4 sd | C19: =Item_Analysis!D13 -> 0.80068204 | D19: 0.80068204 | E19: =ABS(C19-D19) -> 3.663736e-15
A20: Primary n=510 | B20: TB5 citc | C20: =Item_Analysis!G14 -> 0.086530634 | D20: 0.086530634 | E20: =ABS(C20-D20) -> 0
A21: Primary n=510 | B21: TB5 alpha_if_deleted | C21: =Item_Analysis!J14 -> 0.45975266 | D21: 0.45975266 | E21: =ABS(C21-D21) -> 6.4948047e-15
A22: Primary n=510 | B22: TB5 mean | C22: =Item_Analysis!C14 -> 2.9058824 | D22: 2.9058824 | E22: =ABS(C22-D22) -> 0
A23: Primary n=510 | B23: TB5 sd | C23: =Item_Analysis!D14 -> 0.93762476 | D23: 0.93762476 | E23: =ABS(C23-D23) -> 0
A24: Primary n=510 | B24: TB6 citc | C24: =Item_Analysis!G15 -> 0.2446946 | D24: 0.2446946 | E24: =ABS(C24-D24) -> 0
A25: Primary n=510 | B25: TB6 alpha_if_deleted | C25: =Item_Analysis!J15 -> 0.36740945 | D25: 0.36740945 | E25: =ABS(C25-D25) -> 3.7192471e-15
A26: Primary n=510 | B26: TB6 mean | C26: =Item_Analysis!C15 -> 3.0470588 | D26: 3.0470588 | E26: =ABS(C26-D26) -> 0
A27: Primary n=510 | B27: TB6 sd | C27: =Item_Analysis!D15 -> 0.90931718 | D27: 0.90931718 | E27: =ABS(C27-D27) -> 0
A28: Primary n=510 | B28: alpha | C28: =Reliability!B11 -> 0.43249503 | D28: 0.43249503 | E28: =ABS(C28-D28) -> 4.6074256e-15
A29: Primary n=510 | B29: spearman_brown | C29: =Reliability!B16 -> 0.50727439 | D29: 0.50727439 | E29: =ABS(C29-D29) -> 0
A30: Primary n=510 | B30: r_half | C30: =Reliability!B15 -> 0.33983097 | D30: 0.33983097 | E30: =ABS(C30-D30) -> 0
A31: Primary n=510 | B31: guttman | C31: =Reliability!B20 -> 0.50693522 | D31: 0.50693522 | E31: =ABS(C31-D31) -> 5.9952043e-15
A32: Primary n=510 | B32: alpha CI lower | C32: =Reliability!B12 -> 0.35264832 | D32: 0.35264832 | E32: =ABS(C32-D32) -> 4.9404925e-15
A33: Primary n=510 | B33: alpha CI upper | C33: =Reliability!B13 -> 0.50553239 | D33: 0.50553239 | E33: =ABS(C33-D33) -> 4.6629367e-15
A34: Sensitivity n=509 | B34: TB1 citc | C34: =Item_Analysis!G36 -> 0.29230673 | D34: 0.29230673 | E34: =ABS(C34-D34) -> 0
A35: Sensitivity n=509 | B35: TB1 alpha_if_deleted | C35: =Item_Analysis!J36 -> 0.33497166 | D35: 0.33497166 | E35: =ABS(C35-D35) -> 2.2759572e-15
A36: Sensitivity n=509 | B36: TB1 mean | C36: =Item_Analysis!C36 -> 3.7544204 | D36: 3.7544204 | E36: =ABS(C36-D36) -> 0
A37: Sensitivity n=509 | B37: TB1 sd | C37: =Item_Analysis!D36 -> 0.97437902 | D37: 0.97437902 | E37: =ABS(C37-D37) -> 0
A38: Sensitivity n=509 | B38: TB2 citc | C38: =Item_Analysis!G37 -> 0.17049602 | D38: 0.17049602 | E38: =ABS(C38-D38) -> 0
A39: Sensitivity n=509 | B39: TB2 alpha_if_deleted | C39: =Item_Analysis!J37 -> 0.41479424 | D39: 0.41479424 | E39: =ABS(C39-D39) -> 7.5495166e-15
A40: Sensitivity n=509 | B40: TB2 mean | C40: =Item_Analysis!C37 -> 3.064833 | D40: 3.064833 | E40: =ABS(C40-D40) -> 0
A41: Sensitivity n=509 | B41: TB2 sd | C41: =Item_Analysis!D37 -> 1.0106329 | D41: 1.0106329 | E41: =ABS(C41-D41) -> 0
...

Sheet Data_Check
A1: Data checks (computed from Raw_Data)
A3: Variable | B3: Item wording | C3: N non-blank | D3: Blank | E3: Min | F3: Max | G3: Outside 1-5 | H3: n=1 | I3: n=2 | J3: n=3 | K3: n=4 | L3: n=5 | M3: Mean | N3: SD | O3: Raw_Data row | P3: Row key (Raw_Data row) | Q3: Count of identical rows
A4: TB1 | B4: I think e-cars are sleek | C4: =COUNT(Raw_Data!$AJ$2:$AJ$511) -> 510 | D4: =COUNTBLANK(Raw_Data!$AJ$2:$AJ$511) -> 0 | E4: =MIN(Raw_Data!$AJ$2:$AJ$511) -> 1 | F4: =MAX(Raw_Data!$AJ$2:$AJ$511) -> 5 | G4: =COUNT(Raw_Data!$AJ$2:$AJ$511)-COUNTIFS(Raw_Data!$AJ$2:$AJ$511,">=1",Raw_Data!$AJ$2:$AJ$511,"<=5") -> 0 | H4: =COUNTIF(Raw_Data!$AJ$2:$AJ$511,1) -> 8 | I4: =COUNTIF(Raw_Data!$AJ$2:$AJ$511,2) -> 61 | J4: =COUNTIF(Raw_Data!$AJ$2:$AJ$511,3) -> 88 | K4: =COUNTIF(Raw_Data!$AJ$2:$AJ$511,4) -> 244 | L4: =COUNTIF(Raw_Data!$AJ$2:$AJ$511,5) -> 109 | M4: =AVERAGE(Raw_Data!$AJ$2:$AJ$511) -> 3.754902 | N4: =STDEV(Raw_Data!$AJ$2:$AJ$511) -> 0.97348214 | O4: 2 | P4: =Raw_Data!A2&"|"&Raw_Data!B2&"|"&Raw_Data!C2&"|"&Raw_Data!D2&"|"&Raw_Data!E2&"|"&Raw_Data!F2&"|"&Raw_Data!G2&"|"&Raw_Data!H2&"|"&Raw_Data!I2&"|"&Raw_Data!J2&"|"&Raw_Data!K2&"|"&Raw_Data!L2&"|"&Raw_Data!M2&"|"&Raw_Data!N2&"|"&Raw_Data!O2&"|"&Raw_Data!P2&"|"&Raw_Data!Q2&"|"&Raw_Data!R2&"|"&Raw_Data!S2&"|"&Raw_Data!T2&"|"&Raw_Data!U2&"|"&Raw_Data!V2&"|"&Raw_Data!W2&"|"&Raw_Data!X2&"|"&Raw_Data!Y2&"|"&Raw_Data!Z2&"|"&Raw_Data!AA2&"|"&Raw_Data!AB2&"|"&Raw_Data!AC2&"|"&Raw_Data!AD2&"|"&Raw_Data!AE2&"|"&Raw_Data!AF2&"|"&Raw_Data!AG2&"|"&Raw_Data!AH2&"|"&Raw_Data!AI2&"|"&Raw_Data!AJ2&"|"&Raw_Data!AK2&"|"&Raw_Data!AL2&"|"&Raw_Data!AM2&"|"&Raw_Data!AN2&"|"&Raw_Data!AO2 -> 0|4|2|1|2|2|4|2|3|27|4|5|4|4|5|2|4|5|4|5|5|4|4|5|3|4|4|4|4|5|5|3|3|5|5|4|5|4|4|4|4 | Q4: =COUNTIF($P$4:$P$513,P4) -> 1
A5: TB2 | B5: I think e-cars are durable | C5: =COUNT(Raw_Data!$AK$2:$AK$511) -> 510 | D5: =COUNTBLANK(Raw_Data!$AK$2:$AK$511) -> 0 | E5: =MIN(Raw_Data!$AK$2:$AK$511) -> 1 | F5: =MAX(Raw_Data!$AK$2:$AK$511) -> 5 | G5: =COUNT(Raw_Data!$AK$2:$AK$511)-COUNTIFS(Raw_Data!$AK$2:$AK$511,">=1",Raw_Data!$AK$2:$AK$511,"<=5") -> 0 | H5: =COUNTIF(Raw_Data!$AK$2:$AK$511,1) -> 23 | I5: =COUNTIF(Raw_Data!$AK$2:$AK$511,2) -> 136 | J5: =COUNTIF(Raw_Data!$AK$2:$AK$511,3) -> 174 | K5: =COUNTIF(Raw_Data!$AK$2:$AK$511,4) -> 137 | L5: =COUNTIF(Raw_Data!$AK$2:$AK$511,5) -> 40 | M5: =AVERAGE(Raw_Data!$AK$2:$AK$511) -> 3.0686275 | N5: =STDEV(Raw_Data!$AK$2:$AK$511) -> 1.0132696 | O5: 3 | P5: =Raw_Data!A3&"|"&Raw_Data!B3&"|"&Raw_Data!C3&"|"&Raw_Data!D3&"|"&Raw_Data!E3&"|"&Raw_Data!F3&"|"&Raw_Data!G3&"|"&Raw_Data!H3&"|"&Raw_Data!I3&"|"&Raw_Data!J3&"|"&Raw_Data!K3&"|"&Raw_Data!L3&"|"&Raw_Data!M3&"|"&Raw_Data!N3&"|"&Raw_Data!O3&"|"&Raw_Data!P3&"|"&Raw_Data!Q3&"|"&Raw_Data!R3&"|"&Raw_Data!S3&"|"&Raw_Data!T3&"|"&Raw_Data!U3&"|"&Raw_Data!V3&"|"&Raw_Data!W3&"|"&Raw_Data!X3&"|"&Raw_Data!Y3&"|"&Raw_Data!Z3&"|"&Raw_Data!AA3&"|"&Raw_Data!AB3&"|"&Raw_Data!AC3&"|"&Raw_Data!AD3&"|"&Raw_Data!AE3&"|"&Raw_Data!AF3&"|"&Raw_Data!AG3&"|"&Raw_Data!AH3&"|"&Raw_Data!AI3&"|"&Raw_Data!AJ3&"|"&Raw_Data!AK3&"|"&Raw_Data!AL3&"|"&Raw_Data!AM3&"|"&Raw_Data!AN3&"|"&Raw_Data!AO3 -> 0|4|1|1|2|2|3|2|1|22|2|3|4|3|5|4|4|2|5|5|5|4|3|4|5|4|3|2|1|1|4|4|3|4|3|4|1|5|3|2|3 | Q5: =COUNTIF($P$4:$P$513,P5) -> 1
A6: TB3 | B6: I think e-cars are available in different size, colours and designs | C6: =COUNT(Raw_Data!$AL$2:$AL$511) -> 510 | D6: =COUNTBLANK(Raw_Data!$AL$2:$AL$511) -> 0 | E6: =MIN(Raw_Data!$AL$2:$AL$511) -> 1 | F6: =MAX(Raw_Data!$AL$2:$AL$511) -> 5 | G6: =COUNT(Raw_Data!$AL$2:$AL$511)-COUNTIFS(Raw_Data!$AL$2:$AL$511,">=1",Raw_Data!$AL$2:$AL$511,"<=5") -> 0 | H6: =COUNTIF(Raw_Data!$AL$2:$AL$511,1) -> 4 | I6: =COUNTIF(Raw_Data!$AL$2:$AL$511,2) -> 24 | J6: =COUNTIF(Raw_Data!$AL$2:$AL$511,3) -> 86 | K6: =COUNTIF(Raw_Data!$AL$2:$AL$511,4) -> 224 | L6: =COUNTIF(Raw_Data!$AL$2:$AL$511,5) -> 172 | M6: =AVERAGE(Raw_Data!$AL$2:$AL$511) -> 4.0509804 | N6: =STDEV(Raw_Data!$AL$2:$AL$511) -> 0.87384446 | O6: 4 | P6: =Raw_Data!A4&"|"&Raw_Data!B4&"|"&Raw_Data!C4&"|"&Raw_Data!D4&"|"&Raw_Data!E4&"|"&Raw_Data!F4&"|"&Raw_Data!G4&"|"&Raw_Data!H4&"|"&Raw_Data!I4&"|"&Raw_Data!J4&"|"&Raw_Data!K4&"|"&Raw_Data!L4&"|"&Raw_Data!M4&"|"&Raw_Data!N4&"|"&Raw_Data!O4&"|"&Raw_Data!P4&"|"&Raw_Data!Q4&"|"&Raw_Data!R4&"|"&Raw_Data!S4&"|"&Raw_Data!T4&"|"&Raw_Data!U4&"|"&Raw_Data!V4&"|"&Raw_Data!W4&"|"&Raw_Data!X4&"|"&Raw_Data!Y4&"|"&Raw_Data!Z4&"|"&Raw_Data!AA4&"|"&Raw_Data!AB4&"|"&Raw_Data!AC4&"|"&Raw_Data!AD4&"|"&Raw_Data!AE4&"|"&Raw_Data!AF4&"|"&Raw_Data!AG4&"|"&Raw_Data!AH4&"|"&Raw_Data!AI4&"|"&Raw_Data!AJ4&"|"&Raw_Data!AK4&"|"&Raw_Data!AL4&"|"&Raw_Data!AM4&"|"&Raw_Data!AN4&"|"&Raw_Data!AO4 -> 1|1|1|1|2|2|3|2|3|27|3|3|3|3|4|3|2|4|4|4|3|4|5|4|4|4|4|2|2|2|3|2|4|4|4|4|3|4|4|3|3 | Q6: =COUNTIF($P$4:$P$513,P6) -> 1
A7: TB4 | B7: I think e-cars are aesthetically appealing | C7: =COUNT(Raw_Data!$AM$2:$AM$511) -> 510 | D7: =COUNTBLANK(Raw_Data!$AM$2:$AM$511) -> 0 | E7: =MIN(Raw_Data!$AM$2:$AM$511) -> 1 | F7: =MAX(Raw_Data!$AM$2:$AM$511) -> 5 | G7: =COUNT(Raw_Data!$AM$2:$AM$511)-COUNTIFS(Raw_Data!$AM$2:$AM$511,">=1",Raw_Data!$AM$2:$AM$511,"<=5") -> 0 | H7: =COUNTIF(Raw_Data!$AM$2:$AM$511,1) -> 5 | I7: =COUNTIF(Raw_Data!$AM$2:$AM$511,2) -> 53 | J7: =COUNTIF(Raw_Data!$AM$2:$AM$511,3) -> 254 | K7: =COUNTIF(Raw_Data!$AM$2:$AM$511,4) -> 160 | L7: =COUNTIF(Raw_Data!$AM$2:$AM$511,5) -> 38 | M7: =AVERAGE(Raw_Data!$AM$2:$AM$511) -> 3.3392157 | N7: =STDEV(Raw_Data!$AM$2:$AM$511) -> 0.80068204 | O7: 5 | P7: =Raw_Data!A5&"|"&Raw_Data!B5&"|"&Raw_Data!C5&"|"&Raw_Data!D5&"|"&Raw_Data!E5&"|"&Raw_Data!F5&"|"&Raw_Data!G5&"|"&Raw_Data!H5&"|"&Raw_Data!I5&"|"&Raw_Data!J5&"|"&Raw_Data!K5&"|"&Raw_Data!L5&"|"&Raw_Data!M5&"|"&Raw_Data!N5&"|"&Raw_Data!O5&"|"&Raw_Data!P5&"|"&Raw_Data!Q5&"|"&Raw_Data!R5&"|"&Raw_Data!S5&"|"&Raw_Data!T5&"|"&Raw_Data!U5&"|"&Raw_Data!V5&"|"&Raw_Data!W5&"|"&Raw_Data!X5&"|"&Raw_Data!Y5&"|"&Raw_Data!Z5&"|"&Raw_Data!AA5&"|"&Raw_Data!AB5&"|"&Raw_Data!AC5&"|"&Raw_Data!AD5&"|"&Raw_Data!AE5&"|"&Raw_Data!AF5&"|"&Raw_Data!AG5&"|"&Raw_Data!AH5&"|"&Raw_Data!AI5&"|"&Raw_Data!AJ5&"|"&Raw_Data!AK5&"|"&Raw_Data!AL5&"|"&Raw_Data!AM5&"|"&Raw_Data!AN5&"|"&Raw_Data!AO5 -> 0|4|1|1|2|2|2|3|2|24|3|4|2|2|3|2|4|2|4|4|5|4|4|4|3|3|4|4|2|2|4|3|4|4|4|4|3|4|3|2|2 | Q7: =COUNTIF($P$4:$P$513,P7) -> 1
A8: TB5 | B8: I think e-cars are technologically superior | C8: =COUNT(Raw_Data!$AN$2:$AN$511) -> 510 | D8: =COUNTBLANK(Raw_Data!$AN$2:$AN$511) -> 0 | E8: =MIN(Raw_Data!$AN$2:$AN$511) -> 1 | F8: =MAX(Raw_Data!$AN$2:$AN$511) -> 5 | G8: =COUNT(Raw_Data!$AN$2:$AN$511)-COUNTIFS(Raw_Data!$AN$2:$AN$511,">=1",Raw_Data!$AN$2:$AN$511,"<=5") -> 0 | H8: =COUNTIF(Raw_Data!$AN$2:$AN$511,1) -> 33 | I8: =COUNTIF(Raw_Data!$AN$2:$AN$511,2) -> 138 | J8: =COUNTIF(Raw_Data!$AN$2:$AN$511,3) -> 196 | K8: =COUNTIF(Raw_Data!$AN$2:$AN$511,4) -> 130 | L8: =COUNTIF(Raw_Data!$AN$2:$AN$511,5) -> 13 | M8: =AVERAGE(Raw_Data!$AN$2:$AN$511) -> 2.9058824 | N8: =STDEV(Raw_Data!$AN$2:$AN$511) -> 0.93762476 | O8: 6 | P8: =Raw_Data!A6&"|"&Raw_Data!B6&"|"&Raw_Data!C6&"|"&Raw_Data!D6&"|"&Raw_Data!E6&"|"&Raw_Data!F6&"|"&Raw_Data!G6&"|"&Raw_Data!H6&"|"&Raw_Data!I6&"|"&Raw_Data!J6&"|"&Raw_Data!K6&"|"&Raw_Data!L6&"|"&Raw_Data!M6&"|"&Raw_Data!N6&"|"&Raw_Data!O6&"|"&Raw_Data!P6&"|"&Raw_Data!Q6&"|"&Raw_Data!R6&"|"&Raw_Data!S6&"|"&Raw_Data!T6&"|"&Raw_Data!U6&"|"&Raw_Data!V6&"|"&Raw_Data!W6&"|"&Raw_Data!X6&"|"&Raw_Data!Y6&"|"&Raw_Data!Z6&"|"&Raw_Data!AA6&"|"&Raw_Data!AB6&"|"&Raw_Data!AC6&"|"&Raw_Data!AD6&"|"&Raw_Data!AE6&"|"&Raw_Data!AF6&"|"&Raw_Data!AG6&"|"&Raw_Data!AH6&"|"&Raw_Data!AI6&"|"&Raw_Data!AJ6&"|"&Raw_Data!AK6&"|"&Raw_Data!AL6&"|"&Raw_Data!AM6&"|"&Raw_Data!AN6&"|"&Raw_Data!AO6 -> 1|4|1|2|2|2|4|2|3|24|3|4|4|3|5|2|3|4|5|5|5|3|3|4|1|4|3|3|1|1|4|3|4|3|3|3|5|5|4|4|4 | Q8: =COUNTIF($P$4:$P$513,P8) -> 1
A9: TB6 | B9: I think e-cars give comfortable ride | C9: =COUNT(Raw_Data!$AO$2:$AO$511) -> 510 | D9: =COUNTBLANK(Raw_Data!$AO$2:$AO$511) -> 0 | E9: =MIN(Raw_Data!$AO$2:$AO$511) -> 1 | F9: =MAX(Raw_Data!$AO$2:$AO$511) -> 5 | G9: =COUNT(Raw_Data!$AO$2:$AO$511)-COUNTIFS(Raw_Data!$AO$2:$AO$511,">=1",Raw_Data!$AO$2:$AO$511,"<=5") -> 0 | H9: =COUNTIF(Raw_Data!$AO$2:$AO$511,1) -> 20 | I9: =COUNTIF(Raw_Data!$AO$2:$AO$511,2) -> 116 | J9: =COUNTIF(Raw_Data!$AO$2:$AO$511,3) -> 217 | K9: =COUNTIF(Raw_Data!$AO$2:$AO$511,4) -> 134 | L9: =COUNTIF(Raw_Data!$AO$2:$AO$511,5) -> 23 | M9: =AVERAGE(Raw_Data!$AO$2:$AO$511) -> 3.0470588 | N9: =STDEV(Raw_Data!$AO$2:$AO$511) -> 0.90931718 | O9: 7 | P9: =Raw_Data!A7&"|"&Raw_Data!B7&"|"&Raw_Data!C7&"|"&Raw_Data!D7&"|"&Raw_Data!E7&"|"&Raw_Data!F7&"|"&Raw_Data!G7&"|"&Raw_Data!H7&"|"&Raw_Data!I7&"|"&Raw_Data!J7&"|"&Raw_Data!K7&"|"&Raw_Data!L7&"|"&Raw_Data!M7&"|"&Raw_Data!N7&"|"&Raw_Data!O7&"|"&Raw_Data!P7&"|"&Raw_Data!Q7&"|"&Raw_Data!R7&"|"&Raw_Data!S7&"|"&Raw_Data!T7&"|"&Raw_Data!U7&"|"&Raw_Data!V7&"|"&Raw_Data!W7&"|"&Raw_Data!X7&"|"&Raw_Data!Y7&"|"&Raw_Data!Z7&"|"&Raw_Data!AA7&"|"&Raw_Data!AB7&"|"&Raw_Data!AC7&"|"&Raw_Data!AD7&"|"&Raw_Data!AE7&"|"&Raw_Data!AF7&"|"&Raw_Data!AG7&"|"&Raw_Data!AH7&"|"&Raw_Data!AI7&"|"&Raw_Data!AJ7&"|"&Raw_Data!AK7&"|"&Raw_Data!AL7&"|"&Raw_Data!AM7&"|"&Raw_Data!AN7&"|"&Raw_Data!AO7 -> 0|4|1|1|2|2|4|2|1|23|3|5|4|4|5|4|4|5|3|5|5|4|4|5|2|4|4|4|4|4|5|3|4|4|5|3|5|3|3|4|3 | Q9: =COUNTIF($P$4:$P$513,P9) -> 1
O10: 8 | P10: =Raw_Data!A8&"|"&Raw_Data!B8&"|"&Raw_Data!C8&"|"&Raw_Data!D8&"|"&Raw_Data!E8&"|"&Raw_Data!F8&"|"&Raw_Data!G8&"|"&Raw_Data!H8&"|"&Raw_Data!I8&"|"&Raw_Data!J8&"|"&Raw_Data!K8&"|"&Raw_Data!L8&"|"&Raw_Data!M8&"|"&Raw_Data!N8&"|"&Raw_Data!O8&"|"&Raw_Data!P8&"|"&Raw_Data!Q8&"|"&Raw_Data!R8&"|"&Raw_Data!S8&"|"&Raw_Data!T8&"|"&Raw_Data!U8&"|"&Raw_Data!V8&"|"&Raw_Data!W8&"|"&Raw_Data!X8&"|"&Raw_Data!Y8&"|"&Raw_Data!Z8&"|"&Raw_Data!AA8&"|"&Raw_Data!AB8&"|"&Raw_Data!AC8&"|"&Raw_Data!AD8&"|"&Raw_Data!AE8&"|"&Raw_Data!AF8&"|"&Raw_Data!AG8&"|"&Raw_Data!AH8&"|"&Raw_Data!AI8&"|"&Raw_Data!AJ8&"|"&Raw_Data!AK8&"|"&Raw_Data!AL8&"|"&Raw_Data!AM8&"|"&Raw_Data!AN8&"|"&Raw_Data!AO8 -> 1|6|1|1|2|2|3|1|1|21|3|4|4|4|3|2|3|3|4|4|4|3|4|4|2|4|4|4|2|2|4|4|4|2|3|4|2|5|3|3|3 | Q10: =COUNTIF($P$4:$P$513,P10) -> 1
A11: All 31 Likert items (CC1:TB6) | O11: 9 | P11: =Raw_Data!A9&"|"&Raw_Data!B9&"|"&Raw_Data!C9&"|"&Raw_Data!D9&"|"&Raw_Data!E9&"|"&Raw_Data!F9&"|"&Raw_Data!G9&"|"&Raw_Data!H9&"|"&Raw_Data!I9&"|"&Raw_Data!J9&"|"&Raw_Data!K9&"|"&Raw_Data!L9&"|"&Raw_Data!M9&"|"&Raw_Data!N9&"|"&Raw_Data!O9&"|"&Raw_Data!P9&"|"&Raw_Data!Q9&"|"&Raw_Data!R9&"|"&Raw_Data!S9&"|"&Raw_Data!T9&"|"&Raw_Data!U9&"|"&Raw_Data!V9&"|"&Raw_Data!W9&"|"&Raw_Data!X9&"|"&Raw_Data!Y9&"|"&Raw_Data!Z9&"|"&Raw_Data!AA9&"|"&Raw_Data!AB9&"|"&Raw_Data!AC9&"|"&Raw_Data!AD9&"|"&Raw_Data!AE9&"|"&Raw_Data!AF9&"|"&Raw_Data!AG9&"|"&Raw_Data!AH9&"|"&Raw_Data!AI9&"|"&Raw_Data!AJ9&"|"&Raw_Data!AK9&"|"&Raw_Data!AL9&"|"&Raw_Data!AM9&"|"&Raw_Data!AN9&"|"&Raw_Data!AO9 -> |1|1|1|2|2|1|2|1|23|2|2|4|3|4|4|4|2|4|5|4|3|4|4|4|4|4|4|2|3|3|3|3|3|2|3|4|4|4|2|4 | Q11: =COUNTIF($P$4:$P$513,P11) -> 1
A12: Cells | C12: =ROWS(Raw_Data!$K$2:$AO$511)*COLUMNS(Raw_Data!$K$2:$AO$511) -> 15810 | O12: 10 | P12: =Raw_Data!A10&"|"&Raw_Data!B10&"|"&Raw_Data!C10&"|"&Raw_Data!D10&"|"&Raw_Data!E10&"|"&Raw_Data!F10&"|"&Raw_Data!G10&"|"&Raw_Data!H10&"|"&Raw_Data!I10&"|"&Raw_Data!J10&"|"&Raw_Data!K10&"|"&Raw_Data!L10&"|"&Raw_Data!M10&"|"&Raw_Data!N10&"|"&Raw_Data!O10&"|"&Raw_Data!P10&"|"&Raw_Data!Q10&"|"&Raw_Data!R10&"|"&Raw_Data!S10&"|"&Raw_Data!T10&"|"&Raw_Data!U10&"|"&Raw_Data!V10&"|"&Raw_Data!W10&"|"&Raw_Data!X10&"|"&Raw_Data!Y10&"|"&Raw_Data!Z10&"|"&Raw_Data!AA10&"|"&Raw_Data!AB10&"|"&Raw_Data!AC10&"|"&Raw_Data!AD10&"|"&Raw_Data!AE10&"|"&Raw_Data!AF10&"|"&Raw_Data!AG10&"|"&Raw_Data!AH10&"|"&Raw_Data!AI10&"|"&Raw_Data!AJ10&"|"&Raw_Data!AK10&"|"&Raw_Data!AL10&"|"&Raw_Data!AM10&"|"&Raw_Data!AN10&"|"&Raw_Data!AO10 -> 1|4|2|2|2|2|3|2|1|22|3|2|3|4|4|4|3|2|4|5|5|3|5|3|4|5|4|2|2|3|3|4|4|4|4|4|5|4|4|3|3 | Q12: =COUNTIF($P$4:$P$513,P12) -> 1
A13: Blank cells | C13: =COUNTBLANK(Raw_Data!$K$2:$AO$511) -> 0 | O13: 11 | P13: =Raw_Data!A11&"|"&Raw_Data!B11&"|"&Raw_Data!C11&"|"&Raw_Data!D11&"|"&Raw_Data!E11&"|"&Raw_Data!F11&"|"&Raw_Data!G11&"|"&Raw_Data!H11&"|"&Raw_Data!I11&"|"&Raw_Data!J11&"|"&Raw_Data!K11&"|"&Raw_Data!L11&"|"&Raw_Data!M11&"|"&Raw_Data!N11&"|"&Raw_Data!O11&"|"&Raw_Data!P11&"|"&Raw_Data!Q11&"|"&Raw_Data!R11&"|"&Raw_Data!S11&"|"&Raw_Data!T11&"|"&Raw_Data!U11&"|"&Raw_Data!V11&"|"&Raw_Data!W11&"|"&Raw_Data!X11&"|"&Raw_Data!Y11&"|"&Raw_Data!Z11&"|"&Raw_Data!AA11&"|"&Raw_Data!AB11&"|"&Raw_Data!AC11&"|"&Raw_Data!AD11&"|"&Raw_Data!AE11&"|"&Raw_Data!AF11&"|"&Raw_Data!AG11&"|"&Raw_Data!AH11&"|"&Raw_Data!AI11&"|"&Raw_Data!AJ11&"|"&Raw_Data!AK11&"|"&Raw_Data!AL11&"|"&Raw_Data!AM11&"|"&Raw_Data!AN11&"|"&Raw_Data!AO11 -> 1|3|2|2|2|2|1|1|1|23|4|4|4|5|3|2|3|3|4|5|2|4|5|3|3|3|4|3|2|2|2|2|2|4|4|4|3|3|3|3|3 | Q13: =COUNTIF($P$4:$P$513,P13) -> 1
A14: Cells outside 1-5 | C14: =COUNT(Raw_Data!$K$2:$AO$511)-COUNTIFS(Raw_Data!$K$2:$AO$511,">=1",Raw_Data!$K$2:$AO$511,"<=5") -> 0 | O14: 12 | P14: =Raw_Data!A12&"|"&Raw_Data!B12&"|"&Raw_Data!C12&"|"&Raw_Data!D12&"|"&Raw_Data!E12&"|"&Raw_Data!F12&"|"&Raw_Data!G12&"|"&Raw_Data!H12&"|"&Raw_Data!I12&"|"&Raw_Data!J12&"|"&Raw_Data!K12&"|"&Raw_Data!L12&"|"&Raw_Data!M12&"|"&Raw_Data!N12&"|"&Raw_Data!O12&"|"&Raw_Data!P12&"|"&Raw_Data!Q12&"|"&Raw_Data!R12&"|"&Raw_Data!S12&"|"&Raw_Data!T12&"|"&Raw_Data!U12&"|"&Raw_Data!V12&"|"&Raw_Data!W12&"|"&Raw_Data!X12&"|"&Raw_Data!Y12&"|"&Raw_Data!Z12&"|"&Raw_Data!AA12&"|"&Raw_Data!AB12&"|"&Raw_Data!AC12&"|"&Raw_Data!AD12&"|"&Raw_Data!AE12&"|"&Raw_Data!AF12&"|"&Raw_Data!AG12&"|"&Raw_Data!AH12&"|"&Raw_Data!AI12&"|"&Raw_Data!AJ12&"|"&Raw_Data!AK12&"|"&Raw_Data!AL12&"|"&Raw_Data!AM12&"|"&Raw_Data!AN12&"|"&Raw_Data!AO12 -> 1|4|1|1|2|2|3|2|2|25|4|5|5|5|5|4|4|4|5|5|5|2|4|4|3|4|4|4|1|1|5|4|4|4|4|4|4|5|4|3|2 | Q14: =COUNTIF($P$4:$P$513,P14) -> 1
A15: Data rows | C15: =COUNTA(Raw_Data!$J$2:$J$511) -> 510 | O15: 13 | P15: =Raw_Data!A13&"|"&Raw_Data!B13&"|"&Raw_Data!C13&"|"&Raw_Data!D13&"|"&Raw_Data!E13&"|"&Raw_Data!F13&"|"&Raw_Data!G13&"|"&Raw_Data!H13&"|"&Raw_Data!I13&"|"&Raw_Data!J13&"|"&Raw_Data!K13&"|"&Raw_Data!L13&"|"&Raw_Data!M13&"|"&Raw_Data!N13&"|"&Raw_Data!O13&"|"&Raw_Data!P13&"|"&Raw_Data!Q13&"|"&Raw_Data!R13&"|"&Raw_Data!S13&"|"&Raw_Data!T13&"|"&Raw_Data!U13&"|"&Raw_Data!V13&"|"&Raw_Data!W13&"|"&Raw_Data!X13&"|"&Raw_Data!Y13&"|"&Raw_Data!Z13&"|"&Raw_Data!AA13&"|"&Raw_Data!AB13&"|"&Raw_Data!AC13&"|"&Raw_Data!AD13&"|"&Raw_Data!AE13&"|"&Raw_Data!AF13&"|"&Raw_Data!AG13&"|"&Raw_Data!AH13&"|"&Raw_Data!AI13&"|"&Raw_Data!AJ13&"|"&Raw_Data!AK13&"|"&Raw_Data!AL13&"|"&Raw_Data!AM13&"|"&Raw_Data!AN13&"|"&Raw_Data!AO13 -> 0|4|1|1|2|2|3|2|3|27|3|2|4|3|3|4|3|2|4|5|4|2|3|2|2|3|4|1|1|2|3|2|4|4|4|2|4|5|2|1|2 | Q15: =COUNTIF($P$4:$P$513,P15) -> 1
O16: 14 | P16: =Raw_Data!A14&"|"&Raw_Data!B14&"|"&Raw_Data!C14&"|"&Raw_Data!D14&"|"&Raw_Data!E14&"|"&Raw_Data!F14&"|"&Raw_Data!G14&"|"&Raw_Data!H14&"|"&Raw_Data!I14&"|"&Raw_Data!J14&"|"&Raw_Data!K14&"|"&Raw_Data!L14&"|"&Raw_Data!M14&"|"&Raw_Data!N14&"|"&Raw_Data!O14&"|"&Raw_Data!P14&"|"&Raw_Data!Q14&"|"&Raw_Data!R14&"|"&Raw_Data!S14&"|"&Raw_Data!T14&"|"&Raw_Data!U14&"|"&Raw_Data!V14&"|"&Raw_Data!W14&"|"&Raw_Data!X14&"|"&Raw_Data!Y14&"|"&Raw_Data!Z14&"|"&Raw_Data!AA14&"|"&Raw_Data!AB14&"|"&Raw_Data!AC14&"|"&Raw_Data!AD14&"|"&Raw_Data!AE14&"|"&Raw_Data!AF14&"|"&Raw_Data!AG14&"|"&Raw_Data!AH14&"|"&Raw_Data!AI14&"|"&Raw_Data!AJ14&"|"&Raw_Data!AK14&"|"&Raw_Data!AL14&"|"&Raw_Data!AM14&"|"&Raw_Data!AN14&"|"&Raw_Data!AO14 -> |1|1|2|2|2|1|2|1|23|3|4|4|4|4|4|4|5|4|5|5|4|4|4|4|5|5|4|2|2|4|3|4|3|4|3|4|4|3|4|3 | Q16: =COUNTIF($P$4:$P$513,P16) -> 1
A17: Duplicate rows (all 41 variables identical) | O17: 15 | P17: =Raw_Data!A15&"|"&Raw_Data!B15&"|"&Raw_Data!C15&"|"&Raw_Data!D15&"|"&Raw_Data!E15&"|"&Raw_Data!F15&"|"&Raw_Data!G15&"|"&Raw_Data!H15&"|"&Raw_Data!I15&"|"&Raw_Data!J15&"|"&Raw_Data!K15&"|"&Raw_Data!L15&"|"&Raw_Data!M15&"|"&Raw_Data!N15&"|"&Raw_Data!O15&"|"&Raw_Data!P15&"|"&Raw_Data!Q15&"|"&Raw_Data!R15&"|"&Raw_Data!S15&"|"&Raw_Data!T15&"|"&Raw_Data!U15&"|"&Raw_Data!V15&"|"&Raw_Data!W15&"|"&Raw_Data!X15&"|"&Raw_Data!Y15&"|"&Raw_Data!Z15&"|"&Raw_Data!AA15&"|"&Raw_Data!AB15&"|"&Raw_Data!AC15&"|"&Raw_Data!AD15&"|"&Raw_Data!AE15&"|"&Raw_Data!AF15&"|"&Raw_Data!AG15&"|"&Raw_Data!AH15&"|"&Raw_Data!AI15&"|"&Raw_Data!AJ15&"|"&Raw_Data!AK15&"|"&Raw_Data!AL15&"|"&Raw_Data!AM15&"|"&Raw_Data!AN15&"|"&Raw_Data!AO15 -> 0|3|1|1|2|2|3|3|2|24|3|4|3|4|5|3|3|4|5|5|5|3|4|4|5|4|3|4|1|3|5|5|5|3|5|5|3|5|4|4|4 | Q17: =COUNTIF($P$4:$P$513,P17) -> 1
A18: Rows that have an identical twin | C18: =COUNTIF($Q$4:$Q$513,">1") -> 2 | O18: 16 | P18: =Raw_Data!A16&"|"&Raw_Data!B16&"|"&Raw_Data!C16&"|"&Raw_Data!D16&"|"&Raw_Data!E16&"|"&Raw_Data!F16&"|"&Raw_Data!G16&"|"&Raw_Data!H16&"|"&Raw_Data!I16&"|"&Raw_Data!J16&"|"&Raw_Data!K16&"|"&Raw_Data!L16&"|"&Raw_Data!M16&"|"&Raw_Data!N16&"|"&Raw_Data!O16&"|"&Raw_Data!P16&"|"&Raw_Data!Q16&"|"&Raw_Data!R16&"|"&Raw_Data!S16&"|"&Raw_Data!T16&"|"&Raw_Data!U16&"|"&Raw_Data!V16&"|"&Raw_Data!W16&"|"&Raw_Data!X16&"|"&Raw_Data!Y16&"|"&Raw_Data!Z16&"|"&Raw_Data!AA16&"|"&Raw_Data!AB16&"|"&Raw_Data!AC16&"|"&Raw_Data!AD16&"|"&Raw_Data!AE16&"|"&Raw_Data!AF16&"|"&Raw_Data!AG16&"|"&Raw_Data!AH16&"|"&Raw_Data!AI16&"|"&Raw_Data!AJ16&"|"&Raw_Data!AK16&"|"&Raw_Data!AL16&"|"&Raw_Data!AM16&"|"&Raw_Data!AN16&"|"&Raw_Data!AO16 -> 0|2|2|1|2|2|3|2|3|23|3|4|4|3|4|3|3|3|4|4|5|3|5|4|3|4|2|2|3|3|4|3|4|4|4|4|4|4|3|3|3 | Q18: =COUNTIF($P$4:$P$513,P18) -> 1
A19: Raw_Data rows involved | C19: 142 and 139 (data rows 141 and 138); see column Q | O19: 17 | P19: =Raw_Data!A17&"|"&Raw_Data!B17&"|"&Raw_Data!C17&"|"&Raw_Data!D17&"|"&Raw_Data!E17&"|"&Raw_Data!F17&"|"&Raw_Data!G17&"|"&Raw_Data!H17&"|"&Raw_Data!I17&"|"&Raw_Data!J17&"|"&Raw_Data!K17&"|"&Raw_Data!L17&"|"&Raw_Data!M17&"|"&Raw_Data!N17&"|"&Raw_Data!O17&"|"&Raw_Data!P17&"|"&Raw_Data!Q17&"|"&Raw_Data!R17&"|"&Raw_Data!S17&"|"&Raw_Data!T17&"|"&Raw_Data!U17&"|"&Raw_Data!V17&"|"&Raw_Data!W17&"|"&Raw_Data!X17&"|"&Raw_Data!Y17&"|"&Raw_Data!Z17&"|"&Raw_Data!AA17&"|"&Raw_Data!AB17&"|"&Raw_Data!AC17&"|"&Raw_Data!AD17&"|"&Raw_Data!AE17&"|"&Raw_Data!AF17&"|"&Raw_Data!AG17&"|"&Raw_Data!AH17&"|"&Raw_Data!AI17&"|"&Raw_Data!AJ17&"|"&Raw_Data!AK17&"|"&Raw_Data!AL17&"|"&Raw_Data!AM17&"|"&Raw_Data!AN17&"|"&Raw_Data!AO17 -> |3|1|2|1|2|2|2|1|22|3|2|5|3|4|2|4|4|5|4|4|4|4|2|2|4|3|2|4|4|4|4|4|4|2|5|4|4|4|4|3 | Q19: =COUNTIF($P$4:$P$513,P19) -> 1
A20: Age outside 18-35 (count) | C20: =COUNTIF(Raw_Data!$J$2:$J$511,"<18")+COUNTIF(Raw_Data!$J$2:$J$511,">35") -> 1 | O20: 18 | P20: =Raw_Data!A18&"|"&Raw_Data!B18&"|"&Raw_Data!C18&"|"&Raw_Data!D18&"|"&Raw_Data!E18&"|"&Raw_Data!F18&"|"&Raw_Data!G18&"|"&Raw_Data!H18&"|"&Raw_Data!I18&"|"&Raw_Data!J18&"|"&Raw_Data!K18&"|"&Raw_Data!L18&"|"&Raw_Data!M18&"|"&Raw_Data!N18&"|"&Raw_Data!O18&"|"&Raw_Data!P18&"|"&Raw_Data!Q18&"|"&Raw_Data!R18&"|"&Raw_Data!S18&"|"&Raw_Data!T18&"|"&Raw_Data!U18&"|"&Raw_Data!V18&"|"&Raw_Data!W18&"|"&Raw_Data!X18&"|"&Raw_Data!Y18&"|"&Raw_Data!Z18&"|"&Raw_Data!AA18&"|"&Raw_Data!AB18&"|"&Raw_Data!AC18&"|"&Raw_Data!AD18&"|"&Raw_Data!AE18&"|"&Raw_Data!AF18&"|"&Raw_Data!AG18&"|"&Raw_Data!AH18&"|"&Raw_Data!AI18&"|"&Raw_Data!AJ18&"|"&Raw_Data!AK18&"|"&Raw_Data!AL18&"|"&Raw_Data!AM18&"|"&Raw_Data!AN18&"|"&Raw_Data!AO18 -> 0|4|2|1|2|2|2|2|3|24|3|4|2|2|4|2|2|3|3|5|4|3|4|5|4|4|2|2|2|2|4|3|3|4|4|1|2|4|4|3|3 | Q20: =COUNTIF($P$4:$P$513,P20) -> 1
A21: Note: Age and the demographic coding issues do not enter the TB analysis. | O21: 19 | P21: =Raw_Data!A19&"|"&Raw_Data!B19&"|"&Raw_Data!C19&"|"&Raw_Data!D19&"|"&Raw_Data!E19&"|"&Raw_Data!F19&"|"&Raw_Data!G19&"|"&Raw_Data!H19&"|"&Raw_Data!I19&"|"&Raw_Data!J19&"|"&Raw_Data!K19&"|"&Raw_Data!L19&"|"&Raw_Data!M19&"|"&Raw_Data!N19&"|"&Raw_Data!O19&"|"&Raw_Data!P19&"|"&Raw_Data!Q19&"|"&Raw_Data!R19&"|"&Raw_Data!S19&"|"&Raw_Data!T19&"|"&Raw_Data!U19&"|"&Raw_Data!V19&"|"&Raw_Data!W19&"|"&Raw_Data!X19&"|"&Raw_Data!Y19&"|"&Raw_Data!Z19&"|"&Raw_Data!AA19&"|"&Raw_Data!AB19&"|"&Raw_Data!AC19&"|"&Raw_Data!AD19&"|"&Raw_Data!AE19&"|"&Raw_Data!AF19&"|"&Raw_Data!AG19&"|"&Raw_Data!AH19&"|"&Raw_Data!AI19&"|"&Raw_Data!AJ19&"|"&Raw_Data!AK19&"|"&Raw_Data!AL19&"|"&Raw_Data!AM19&"|"&Raw_Data!AN19&"|"&Raw_Data!AO19 -> 0|4|1|1|2|2|3|3|3|24|4|2|4|4|4|3|3|3|3|3|4|4|4|4|3|3|5|3|1|2|3|4|4|3|2|5|2|5|3|3|4 | Q21: =COUNTIF($P$4:$P$513,P21) -> 1
O22: 20 | P22: =Raw_Data!A20&"|"&Raw_Data!B20&"|"&Raw_Data!C20&"|"&Raw_Data!D20&"|"&Raw_Data!E20&"|"&Raw_Data!F20&"|"&Raw_Data!G20&"|"&Raw_Data!H20&"|"&Raw_Data!I20&"|"&Raw_Data!J20&"|"&Raw_Data!K20&"|"&Raw_Data!L20&"|"&Raw_Data!M20&"|"&Raw_Data!N20&"|"&Raw_Data!O20&"|"&Raw_Data!P20&"|"&Raw_Data!Q20&"|"&Raw_Data!R20&"|"&Raw_Data!S20&"|"&Raw_Data!T20&"|"&Raw_Data!U20&"|"&Raw_Data!V20&"|"&Raw_Data!W20&"|"&Raw_Data!X20&"|"&Raw_Data!Y20&"|"&Raw_Data!Z20&"|"&Raw_Data!AA20&"|"&Raw_Data!AB20&"|"&Raw_Data!AC20&"|"&Raw_Data!AD20&"|"&Raw_Data!AE20&"|"&Raw_Data!AF20&"|"&Raw_Data!AG20&"|"&Raw_Data!AH20&"|"&Raw_Data!AI20&"|"&Raw_Data!AJ20&"|"&Raw_Data!AK20&"|"&Raw_Data!AL20&"|"&Raw_Data!AM20&"|"&Raw_Data!AN20&"|"&Raw_Data!AO20 -> 0|4|1|2|2|2|4|2|3|23|3|3|4|3|4|1|4|3|4|5|4|4|4|4|3|4|4|2|2|3|3|3|4|3|2|4|4|2|3|3|3 | Q22: =COUNTIF($P$4:$P$513,P22) -> 1
O23: 21 | P23: =Raw_Data!A21&"|"&Raw_Data!B21&"|"&Raw_Data!C21&"|"&Raw_Data!D21&"|"&Raw_Data!E21&"|"&Raw_Data!F21&"|"&Raw_Data!G21&"|"&Raw_Data!H21&"|"&Raw_Data!I21&"|"&Raw_Data!J21&"|"&Raw_Data!K21&"|"&Raw_Data!L21&"|"&Raw_Data!M21&"|"&Raw_Data!N21&"|"&Raw_Data!O21&"|"&Raw_Data!P21&"|"&Raw_Data!Q21&"|"&Raw_Data!R21&"|"&Raw_Data!S21&"|"&Raw_Data!T21&"|"&Raw_Data!U21&"|"&Raw_Data!V21&"|"&Raw_Data!W21&"|"&Raw_Data!X21&"|"&Raw_Data!Y21&"|"&Raw_Data!Z21&"|"&Raw_Data!AA21&"|"&Raw_Data!AB21&"|"&Raw_Data!AC21&"|"&Raw_Data!AD21&"|"&Raw_Data!AE21&"|"&Raw_Data!AF21&"|"&Raw_Data!AG21&"|"&Raw_Data!AH21&"|"&Raw_Data!AI21&"|"&Raw_Data!AJ21&"|"&Raw_Data!AK21&"|"&Raw_Data!AL21&"|"&Raw_Data!AM21&"|"&Raw_Data!AN21&"|"&Raw_Data!AO21 -> 0|3|1|1|2|2|3|3|1|23|4|4|4|4|4|3|4|2|5|5|5|3|3|4|2|4|4|1|2|2|5|3|5|4|3|5|3|5|5|1|2 | Q23: =COUNTIF($P$4:$P$513,P23) -> 1
O24: 22 | P24: =Raw_Data!A22&"|"&Raw_Data!B22&"|"&Raw_Data!C22&"|"&Raw_Data!D22&"|"&Raw_Data!E22&"|"&Raw_Data!F22&"|"&Raw_Data!G22&"|"&Raw_Data!H22&"|"&Raw_Data!I22&"|"&Raw_Data!J22&"|"&Raw_Data!K22&"|"&Raw_Data!L22&"|"&Raw_Data!M22&"|"&Raw_Data!N22&"|"&Raw_Data!O22&"|"&Raw_Data!P22&"|"&Raw_Data!Q22&"|"&Raw_Data!R22&"|"&Raw_Data!S22&"|"&Raw_Data!T22&"|"&Raw_Data!U22&"|"&Raw_Data!V22&"|"&Raw_Data!W22&"|"&Raw_Data!X22&"|"&Raw_Data!Y22&"|"&Raw_Data!Z22&"|"&Raw_Data!AA22&"|"&Raw_Data!AB22&"|"&Raw_Data!AC22&"|"&Raw_Data!AD22&"|"&Raw_Data!AE22&"|"&Raw_Data!AF22&"|"&Raw_Data!AG22&"|"&Raw_Data!AH22&"|"&Raw_Data!AI22&"|"&Raw_Data!AJ22&"|"&Raw_Data!AK22&"|"&Raw_Data!AL22&"|"&Raw_Data!AM22&"|"&Raw_Data!AN22&"|"&Raw_Data!AO22 -> 1|4|1|1|2|2|3|3|3|24|4|4|4|5|4|3|3|3|3|5|4|4|3|5|4|5|5|4|1|2|4|4|5|4|4|4|4|5|4|3|5 | Q24: =COUNTIF($P$4:$P$513,P24) -> 1
O25: 23 | P25: =Raw_Data!A23&"|"&Raw_Data!B23&"|"&Raw_Data!C23&"|"&Raw_Data!D23&"|"&Raw_Data!E23&"|"&Raw_Data!F23&"|"&Raw_Data!G23&"|"&Raw_Data!H23&"|"&Raw_Data!I23&"|"&Raw_Data!J23&"|"&Raw_Data!K23&"|"&Raw_Data!L23&"|"&Raw_Data!M23&"|"&Raw_Data!N23&"|"&Raw_Data!O23&"|"&Raw_Data!P23&"|"&Raw_Data!Q23&"|"&Raw_Data!R23&"|"&Raw_Data!S23&"|"&Raw_Data!T23&"|"&Raw_Data!U23&"|"&Raw_Data!V23&"|"&Raw_Data!W23&"|"&Raw_Data!X23&"|"&Raw_Data!Y23&"|"&Raw_Data!Z23&"|"&Raw_Data!AA23&"|"&Raw_Data!AB23&"|"&Raw_Data!AC23&"|"&Raw_Data!AD23&"|"&Raw_Data!AE23&"|"&Raw_Data!AF23&"|"&Raw_Data!AG23&"|"&Raw_Data!AH23&"|"&Raw_Data!AI23&"|"&Raw_Data!AJ23&"|"&Raw_Data!AK23&"|"&Raw_Data!AL23&"|"&Raw_Data!AM23&"|"&Raw_Data!AN23&"|"&Raw_Data!AO23 -> 1|4|2|1|2|2|4|2|3|25|2|3|2|2|2|2|3|2|4|4|4|4|4|4|3|4|2|2|2|2|3|3|3|3|3|3|3|4|3|2|3 | Q25: =COUNTIF($P$4:$P$513,P25) -> 1
O26: 24 | P26: =Raw_Data!A24&"|"&Raw_Data!B24&"|"&Raw_Data!C24&"|"&Raw_Data!D24&"|"&Raw_Data!E24&"|"&Raw_Data!F24&"|"&Raw_Data!G24&"|"&Raw_Data!H24&"|"&Raw_Data!I24&"|"&Raw_Data!J24&"|"&Raw_Data!K24&"|"&Raw_Data!L24&"|"&Raw_Data!M24&"|"&Raw_Data!N24&"|"&Raw_Data!O24&"|"&Raw_Data!P24&"|"&Raw_Data!Q24&"|"&Raw_Data!R24&"|"&Raw_Data!S24&"|"&Raw_Data!T24&"|"&Raw_Data!U24&"|"&Raw_Data!V24&"|"&Raw_Data!W24&"|"&Raw_Data!X24&"|"&Raw_Data!Y24&"|"&Raw_Data!Z24&"|"&Raw_Data!AA24&"|"&Raw_Data!AB24&"|"&Raw_Data!AC24&"|"&Raw_Data!AD24&"|"&Raw_Data!AE24&"|"&Raw_Data!AF24&"|"&Raw_Data!AG24&"|"&Raw_Data!AH24&"|"&Raw_Data!AI24&"|"&Raw_Data!AJ24&"|"&Raw_Data!AK24&"|"&Raw_Data!AL24&"|"&Raw_Data!AM24&"|"&Raw_Data!AN24&"|"&Raw_Data!AO24 -> 0|4|2|1|2|2|2|1|1|23|4|3|4|3|3|4|5|2|4|4|4|4|4|4|3|3|5|4|2|2|3|2|4|3|4|3|3|4|3|3|2 | Q26: =COUNTIF($P$4:$P$513,P26) -> 1
O27: 25 | P27: =Raw_Data!A25&"|"&Raw_Data!B25&"|"&Raw_Data!C25&"|"&Raw_Data!D25&"|"&Raw_Data!E25&"|"&Raw_Data!F25&"|"&Raw_Data!G25&"|"&Raw_Data!H25&"|"&Raw_Data!I25&"|"&Raw_Data!J25&"|"&Raw_Data!K25&"|"&Raw_Data!L25&"|"&Raw_Data!M25&"|"&Raw_Data!N25&"|"&Raw_Data!O25&"|"&Raw_Data!P25&"|"&Raw_Data!Q25&"|"&Raw_Data!R25&"|"&Raw_Data!S25&"|"&Raw_Data!T25&"|"&Raw_Data!U25&"|"&Raw_Data!V25&"|"&Raw_Data!W25&"|"&Raw_Data!X25&"|"&Raw_Data!Y25&"|"&Raw_Data!Z25&"|"&Raw_Data!AA25&"|"&Raw_Data!AB25&"|"&Raw_Data!AC25&"|"&Raw_Data!AD25&"|"&Raw_Data!AE25&"|"&Raw_Data!AF25&"|"&Raw_Data!AG25&"|"&Raw_Data!AH25&"|"&Raw_Data!AI25&"|"&Raw_Data!AJ25&"|"&Raw_Data!AK25&"|"&Raw_Data!AL25&"|"&Raw_Data!AM25&"|"&Raw_Data!AN25&"|"&Raw_Data!AO25 -> 0|4|1|2|2|2|2|1|1|26|4|2|3|3|5|4|4|2|4|5|4|4|4|3|4|3|4|2|2|2|4|4|4|3|4|4|4|5|3|3|2 | Q27: =COUNTIF($P$4:$P$513,P27) -> 1
O28: 26 | P28: =Raw_Data!A26&"|"&Raw_Data!B26&"|"&Raw_Data!C26&"|"&Raw_Data!D26&"|"&Raw_Data!E26&"|"&Raw_Data!F26&"|"&Raw_Data!G26&"|"&Raw_Data!H26&"|"&Raw_Data!I26&"|"&Raw_Data!J26&"|"&Raw_Data!K26&"|"&Raw_Data!L26&"|"&Raw_Data!M26&"|"&Raw_Data!N26&"|"&Raw_Data!O26&"|"&Raw_Data!P26&"|"&Raw_Data!Q26&"|"&Raw_Data!R26&"|"&Raw_Data!S26&"|"&Raw_Data!T26&"|"&Raw_Data!U26&"|"&Raw_Data!V26&"|"&Raw_Data!W26&"|"&Raw_Data!X26&"|"&Raw_Data!Y26&"|"&Raw_Data!Z26&"|"&Raw_Data!AA26&"|"&Raw_Data!AB26&"|"&Raw_Data!AC26&"|"&Raw_Data!AD26&"|"&Raw_Data!AE26&"|"&Raw_Data!AF26&"|"&Raw_Data!AG26&"|"&Raw_Data!AH26&"|"&Raw_Data!AI26&"|"&Raw_Data!AJ26&"|"&Raw_Data!AK26&"|"&Raw_Data!AL26&"|"&Raw_Data!AM26&"|"&Raw_Data!AN26&"|"&Raw_Data!AO26 -> 0|4|1|1|2|2|4|3|3|25|3|4|4|3|5|4|4|4|4|4|4|4|4|4|4|4|4|4|2|2|4|3|4|4|4|4|4|5|4|3|4 | Q28: =COUNTIF($P$4:$P$513,P28) -> 1
O29: 27 | P29: =Raw_Data!A27&"|"&Raw_Data!B27&"|"&Raw_Data!C27&"|"&Raw_Data!D27&"|"&Raw_Data!E27&"|"&Raw_Data!F27&"|"&Raw_Data!G27&"|"&Raw_Data!H27&"|"&Raw_Data!I27&"|"&Raw_Data!J27&"|"&Raw_Data!K27&"|"&Raw_Data!L27&"|"&Raw_Data!M27&"|"&Raw_Data!N27&"|"&Raw_Data!O27&"|"&Raw_Data!P27&"|"&Raw_Data!Q27&"|"&Raw_Data!R27&"|"&Raw_Data!S27&"|"&Raw_Data!T27&"|"&Raw_Data!U27&"|"&Raw_Data!V27&"|"&Raw_Data!W27&"|"&Raw_Data!X27&"|"&Raw_Data!Y27&"|"&Raw_Data!Z27&"|"&Raw_Data!AA27&"|"&Raw_Data!AB27&"|"&Raw_Data!AC27&"|"&Raw_Data!AD27&"|"&Raw_Data!AE27&"|"&Raw_Data!AF27&"|"&Raw_Data!AG27&"|"&Raw_Data!AH27&"|"&Raw_Data!AI27&"|"&Raw_Data!AJ27&"|"&Raw_Data!AK27&"|"&Raw_Data!AL27&"|"&Raw_Data!AM27&"|"&Raw_Data!AN27&"|"&Raw_Data!AO27 -> 0|4|1|2|2|2|1|1|3|25|3|3|4|3|4|4|3|4|4|5|5|4|4|3|3|4|4|4|2|2|4|3|4|3|4|4|4|5|5|3|3 | Q29: =COUNTIF($P$4:$P$513,P29) -> 1
O30: 28 | P30: =Raw_Data!A28&"|"&Raw_Data!B28&"|"&Raw_Data!C28&"|"&Raw_Data!D28&"|"&Raw_Data!E28&"|"&Raw_Data!F28&"|"&Raw_Data!G28&"|"&Raw_Data!H28&"|"&Raw_Data!I28&"|"&Raw_Data!J28&"|"&Raw_Data!K28&"|"&Raw_Data!L28&"|"&Raw_Data!M28&"|"&Raw_Data!N28&"|"&Raw_Data!O28&"|"&Raw_Data!P28&"|"&Raw_Data!Q28&"|"&Raw_Data!R28&"|"&Raw_Data!S28&"|"&Raw_Data!T28&"|"&Raw_Data!U28&"|"&Raw_Data!V28&"|"&Raw_Data!W28&"|"&Raw_Data!X28&"|"&Raw_Data!Y28&"|"&Raw_Data!Z28&"|"&Raw_Data!AA28&"|"&Raw_Data!AB28&"|"&Raw_Data!AC28&"|"&Raw_Data!AD28&"|"&Raw_Data!AE28&"|"&Raw_Data!AF28&"|"&Raw_Data!AG28&"|"&Raw_Data!AH28&"|"&Raw_Data!AI28&"|"&Raw_Data!AJ28&"|"&Raw_Data!AK28&"|"&Raw_Data!AL28&"|"&Raw_Data!AM28&"|"&Raw_Data!AN28&"|"&Raw_Data!AO28 -> 0|3|1|1|2|2|3|2|1|24|3|3|4|2|4|2|2|2|4|4|4|4|4|2|4|4|4|2|1|2|4|2|4|2|2|2|2|4|4|2|3 | Q30: =COUNTIF($P$4:$P$513,P30) -> 1
O31: 29 | P31: =Raw_Data!A29&"|"&Raw_Data!B29&"|"&Raw_Data!C29&"|"&Raw_Data!D29&"|"&Raw_Data!E29&"|"&Raw_Data!F29&"|"&Raw_Data!G29&"|"&Raw_Data!H29&"|"&Raw_Data!I29&"|"&Raw_Data!J29&"|"&Raw_Data!K29&"|"&Raw_Data!L29&"|"&Raw_Data!M29&"|"&Raw_Data!N29&"|"&Raw_Data!O29&"|"&Raw_Data!P29&"|"&Raw_Data!Q29&"|"&Raw_Data!R29&"|"&Raw_Data!S29&"|"&Raw_Data!T29&"|"&Raw_Data!U29&"|"&Raw_Data!V29&"|"&Raw_Data!W29&"|"&Raw_Data!X29&"|"&Raw_Data!Y29&"|"&Raw_Data!Z29&"|"&Raw_Data!AA29&"|"&Raw_Data!AB29&"|"&Raw_Data!AC29&"|"&Raw_Data!AD29&"|"&Raw_Data!AE29&"|"&Raw_Data!AF29&"|"&Raw_Data!AG29&"|"&Raw_Data!AH29&"|"&Raw_Data!AI29&"|"&Raw_Data!AJ29&"|"&Raw_Data!AK29&"|"&Raw_Data!AL29&"|"&Raw_Data!AM29&"|"&Raw_Data!AN29&"|"&Raw_Data!AO29 -> 0|3|1|1|2|2|2|2|1|22|2|3|2|3|4|4|4|3|3|5|4|4|3|2|3|4|4|2|1|2|4|3|4|4|4|4|2|5|4|3|2 | Q31: =COUNTIF($P$4:$P$513,P31) -> 1
O32: 30 | P32: =Raw_Data!A30&"|"&Raw_Data!B30&"|"&Raw_Data!C30&"|"&Raw_Data!D30&"|"&Raw_Data!E30&"|"&Raw_Data!F30&"|"&Raw_Data!G30&"|"&Raw_Data!H30&"|"&Raw_Data!I30&"|"&Raw_Data!J30&"|"&Raw_Data!K30&"|"&Raw_Data!L30&"|"&Raw_Data!M30&"|"&Raw_Data!N30&"|"&Raw_Data!O30&"|"&Raw_Data!P30&"|"&Raw_Data!Q30&"|"&Raw_Data!R30&"|"&Raw_Data!S30&"|"&Raw_Data!T30&"|"&Raw_Data!U30&"|"&Raw_Data!V30&"|"&Raw_Data!W30&"|"&Raw_Data!X30&"|"&Raw_Data!Y30&"|"&Raw_Data!Z30&"|"&Raw_Data!AA30&"|"&Raw_Data!AB30&"|"&Raw_Data!AC30&"|"&Raw_Data!AD30&"|"&Raw_Data!AE30&"|"&Raw_Data!AF30&"|"&Raw_Data!AG30&"|"&Raw_Data!AH30&"|"&Raw_Data!AI30&"|"&Raw_Data!AJ30&"|"&Raw_Data!AK30&"|"&Raw_Data!AL30&"|"&Raw_Data!AM30&"|"&Raw_Data!AN30&"|"&Raw_Data!AO30 -> 1|3|2|1|2|2|3|3|1|22|3|4|5|5|3|2|3|3|5|5|5|4|5|4|2|5|4|1|2|2|5|4|5|2|2|4|2|4|4|3|3 | Q32: =COUNTIF($P$4:$P$513,P32) -> 1
O33: 31 | P33: =Raw_Data!A31&"|"&Raw_Data!B31&"|"&Raw_Data!C31&"|"&Raw_Data!D31&"|"&Raw_Data!E31&"|"&Raw_Data!F31&"|"&Raw_Data!G31&"|"&Raw_Data!H31&"|"&Raw_Data!I31&"|"&Raw_Data!J31&"|"&Raw_Data!K31&"|"&Raw_Data!L31&"|"&Raw_Data!M31&"|"&Raw_Data!N31&"|"&Raw_Data!O31&"|"&Raw_Data!P31&"|"&Raw_Data!Q31&"|"&Raw_Data!R31&"|"&Raw_Data!S31&"|"&Raw_Data!T31&"|"&Raw_Data!U31&"|"&Raw_Data!V31&"|"&Raw_Data!W31&"|"&Raw_Data!X31&"|"&Raw_Data!Y31&"|"&Raw_Data!Z31&"|"&Raw_Data!AA31&"|"&Raw_Data!AB31&"|"&Raw_Data!AC31&"|"&Raw_Data!AD31&"|"&Raw_Data!AE31&"|"&Raw_Data!AF31&"|"&Raw_Data!AG31&"|"&Raw_Data!AH31&"|"&Raw_Data!AI31&"|"&Raw_Data!AJ31&"|"&Raw_Data!AK31&"|"&Raw_Data!AL31&"|"&Raw_Data!AM31&"|"&Raw_Data!AN31&"|"&Raw_Data!AO31 -> 0|3|1|1|2|2|1|2|3|23|4|3|4|4|3|4|4|3|5|4|4|3|4|2|3|4|4|4|3|2|3|3|3|4|3|4|3|4|3|3|3 | Q33: =COUNTIF($P$4:$P$513,P33) -> 1
... O513: 511 | P513: =Raw_Data!A511&"|"&Raw_Data!B511&"|"&Raw_Data!C511&"|"&Raw_Data!D511&"|"&Raw_Data!E511&"|"&Raw_Data!F511&"|"&Raw_Data!G511&"|"&Raw_Data!H511&"|"&Raw_Data!I511&"|"&Raw_Data!J511&"|"&Raw_Data!K511&"|"&Raw_Data!L511&"|"&Raw_Data!M511&"|"&Raw_Data!N511&"|"&Raw_Data!O511&"|"&Raw_Data!P511&"|"&Raw_Data!Q511&"|"&Raw_Data!R511&"|"&Raw_Data!S511&"|"&Raw_Data!T511&"|"&Raw_Data!U511&"|"&Raw_Data!V511&"|"&Raw_Data!W511&"|"&Raw_Data!X511&"|"&Raw_Data!Y511&"|"&Raw_Data!Z511&"|"&Raw_Data!AA511&"|"&Raw_Data!AB511&"|"&Raw_Data!AC511&"|"&Raw_Data!AD511&"|"&Raw_Data!AE511&"|"&Raw_Data!AF511&"|"&Raw_Data!AG511&"|"&Raw_Data!AH511&"|"&Raw_Data!AI511&"|"&Raw_Data!AJ511&"|"&Raw_Data!AK511&"|"&Raw_Data!AL511&"|"&Raw_Data!AM511&"|"&Raw_Data!AN511&"|"&Raw_Data!AO511 -> 0|4|1|2|2|2|1|1|3|27|4|5|5|4|4|2|2|3|5|5|4|3|4|4|4|4|2|5|3|4|5|5|5|3|5|5|2|4|4|4|3 | Q513: =COUNTIF($P$4:$P$513,P513) -> 1

Sheet TB_Primary
A1: Raw_Data row | B1: TB1 | C1: TB2 | D1: TB3 | E1: TB4 | F1: TB5 | G1: TB6 | H1: Total | I1: Rest_TB1 | J1: Rest_TB2 | K1: Rest_TB3 | L1: Rest_TB4 | M1: Rest_TB5 | N1: Rest_TB6 | O1: Odd (TB1+TB3+TB5) | P1: Even (TB2+TB4+TB6)
A2: 2 | B2: =Raw_Data!AJ2 -> 4 | C2: =Raw_Data!AK2 -> 5 | D2: =Raw_Data!AL2 -> 4 | E2: =Raw_Data!AM2 -> 4 | F2: =Raw_Data!AN2 -> 4 | G2: =Raw_Data!AO2 -> 4 | H2: =SUM(B2:G2) -> 25 | I2: =H2-B2 -> 21 | J2: =H2-C2 -> 20 | K2: =H2-D2 -> 21 | L2: =H2-E2 -> 21 | M2: =H2-F2 -> 21 | N2: =H2-G2 -> 21 | O2: =B2+D2+F2 -> 12 | P2: =C2+E2+G2 -> 13
A3: 3 | B3: =Raw_Data!AJ3 -> 4 | C3: =Raw_Data!AK3 -> 1 | D3: =Raw_Data!AL3 -> 5 | E3: =Raw_Data!AM3 -> 3 | F3: =Raw_Data!AN3 -> 2 | G3: =Raw_Data!AO3 -> 3 | H3: =SUM(B3:G3) -> 18 | I3: =H3-B3 -> 14 | J3: =H3-C3 -> 17 | K3: =H3-D3 -> 13 | L3: =H3-E3 -> 15 | M3: =H3-F3 -> 16 | N3: =H3-G3 -> 15 | O3: =B3+D3+F3 -> 11 | P3: =C3+E3+G3 -> 7
A4: 4 | B4: =Raw_Data!AJ4 -> 4 | C4: =Raw_Data!AK4 -> 3 | D4: =Raw_Data!AL4 -> 4 | E4: =Raw_Data!AM4 -> 4 | F4: =Raw_Data!AN4 -> 3 | G4: =Raw_Data!AO4 -> 3 | H4: =SUM(B4:G4) -> 21 | I4: =H4-B4 -> 17 | J4: =H4-C4 -> 18 | K4: =H4-D4 -> 17 | L4: =H4-E4 -> 17 | M4: =H4-F4 -> 18 | N4: =H4-G4 -> 18 | O4: =B4+D4+F4 -> 11 | P4: =C4+E4+G4 -> 10
A5: 5 | B5: =Raw_Data!AJ5 -> 4 | C5: =Raw_Data!AK5 -> 3 | D5: =Raw_Data!AL5 -> 4 | E5: =Raw_Data!AM5 -> 3 | F5: =Raw_Data!AN5 -> 2 | G5: =Raw_Data!AO5 -> 2 | H5: =SUM(B5:G5) -> 18 | I5: =H5-B5 -> 14 | J5: =H5-C5 -> 15 | K5: =H5-D5 -> 14 | L5: =H5-E5 -> 15 | M5: =H5-F5 -> 16 | N5: =H5-G5 -> 16 | O5: =B5+D5+F5 -> 10 | P5: =C5+E5+G5 -> 8
A6: 6 | B6: =Raw_Data!AJ6 -> 3 | C6: =Raw_Data!AK6 -> 5 | D6: =Raw_Data!AL6 -> 5 | E6: =Raw_Data!AM6 -> 4 | F6: =Raw_Data!AN6 -> 4 | G6: =Raw_Data!AO6 -> 4 | H6: =SUM(B6:G6) -> 25 | I6: =H6-B6 -> 22 | J6: =H6-C6 -> 20 | K6: =H6-D6 -> 20 | L6: =H6-E6 -> 21 | M6: =H6-F6 -> 21 | N6: =H6-G6 -> 21 | O6: =B6+D6+F6 -> 12 | P6: =C6+E6+G6 -> 13
A7: 7 | B7: =Raw_Data!AJ7 -> 3 | C7: =Raw_Data!AK7 -> 5 | D7: =Raw_Data!AL7 -> 3 | E7: =Raw_Data!AM7 -> 3 | F7: =Raw_Data!AN7 -> 4 | G7: =Raw_Data!AO7 -> 3 | H7: =SUM(B7:G7) -> 21 | I7: =H7-B7 -> 18 | J7: =H7-C7 -> 16 | K7: =H7-D7 -> 18 | L7: =H7-E7 -> 18 | M7: =H7-F7 -> 17 | N7: =H7-G7 -> 18 | O7: =B7+D7+F7 -> 10 | P7: =C7+E7+G7 -> 11
A8: 8 | B8: =Raw_Data!AJ8 -> 4 | C8: =Raw_Data!AK8 -> 2 | D8: =Raw_Data!AL8 -> 5 | E8: =Raw_Data!AM8 -> 3 | F8: =Raw_Data!AN8 -> 3 | G8: =Raw_Data!AO8 -> 3 | H8: =SUM(B8:G8) -> 20 | I8: =H8-B8 -> 16 | J8: =H8-C8 -> 18 | K8: =H8-D8 -> 15 | L8: =H8-E8 -> 17 | M8: =H8-F8 -> 17 | N8: =H8-G8 -> 17 | O8: =B8+D8+F8 -> 12 | P8: =C8+E8+G8 -> 8
A9: 9 | B9: =Raw_Data!AJ9 -> 3 | C9: =Raw_Data!AK9 -> 4 | D9: =Raw_Data!AL9 -> 4 | E9: =Raw_Data!AM9 -> 4 | F9: =Raw_Data!AN9 -> 2 | G9: =Raw_Data!AO9 -> 4 | H9: =SUM(B9:G9) -> 21 | I9: =H9-B9 -> 18 | J9: =H9-C9 -> 17 | K9: =H9-D9 -> 17 | L9: =H9-E9 -> 17 | M9: =H9-F9 -> 19 | N9: =H9-G9 -> 17 | O9: =B9+D9+F9 -> 9 | P9: =C9+E9+G9 -> 12
A10: 10 | B10: =Raw_Data!AJ10 -> 4 | C10: =Raw_Data!AK10 -> 5 | D10: =Raw_Data!AL10 -> 4 | E10: =Raw_Data!AM10 -> 4 | F10: =Raw_Data!AN10 -> 3 | G10: =Raw_Data!AO10 -> 3 | H10: =SUM(B10:G10) -> 23 | I10: =H10-B10 -> 19 | J10: =H10-C10 -> 18 | K10: =H10-D10 -> 19 | L10: =H10-E10 -> 19 | M10: =H10-F10 -> 20 | N10: =H10-G10 -> 20 | O10: =B10+D10+F10 -> 11 | P10: =C10+E10+G10 -> 12
A11: 11 | B11: =Raw_Data!AJ11 -> 4 | C11: =Raw_Data!AK11 -> 3 | D11: =Raw_Data!AL11 -> 3 | E11: =Raw_Data!AM11 -> 3 | F11: =Raw_Data!AN11 -> 3 | G11: =Raw_Data!AO11 -> 3 | H11: =SUM(B11:G11) -> 19 | I11: =H11-B11 -> 15 | J11: =H11-C11 -> 16 | K11: =H11-D11 -> 16 | L11: =H11-E11 -> 16 | M11: =H11-F11 -> 16 | N11: =H11-G11 -> 16 | O11: =B11+D11+F11 -> 10 | P11: =C11+E11+G11 -> 9
A12: 12 | B12: =Raw_Data!AJ12 -> 4 | C12: =Raw_Data!AK12 -> 4 | D12: =Raw_Data!AL12 -> 5 | E12: =Raw_Data!AM12 -> 4 | F12: =Raw_Data!AN12 -> 3 | G12: =Raw_Data!AO12 -> 2 | H12: =SUM(B12:G12) -> 22 | I12: =H12-B12 -> 18 | J12: =H12-C12 -> 18 | K12: =H12-D12 -> 17 | L12: =H12-E12 -> 18 | M12: =H12-F12 -> 19 | N12: =H12-G12 -> 20 | O12: =B12+D12+F12 -> 12 | P12: =C12+E12+G12 -> 10
A13: 13 | B13: =Raw_Data!AJ13 -> 2 | C13: =Raw_Data!AK13 -> 4 | D13: =Raw_Data!AL13 -> 5 | E13: =Raw_Data!AM13 -> 2 | F13: =Raw_Data!AN13 -> 1 | G13: =Raw_Data!AO13 -> 2 | H13: =SUM(B13:G13) -> 16 | I13: =H13-B13 -> 14 | J13: =H13-C13 -> 12 | K13: =H13-D13 -> 11 | L13: =H13-E13 -> 14 | M13: =H13-F13 -> 15 | N13: =H13-G13 -> 14 | O13: =B13+D13+F13 -> 8 | P13: =C13+E13+G13 -> 8
... A511: 511 | B511: =Raw_Data!AJ511 -> 5 | C511: =Raw_Data!AK511 -> 2 | D511: =Raw_Data!AL511 -> 4 | E511: =Raw_Data!AM511 -> 4 | F511: =Raw_Data!AN511 -> 4 | G511: =Raw_Data!AO511 -> 3 | H511: =SUM(B511:G511) -> 22 | I511: =H511-B511 -> 17 | J511: =H511-C511 -> 20 | K511: =H511-D511 -> 18 | L511: =H511-E511 -> 18 | M511: =H511-F511 -> 18 | N511: =H511-G511 -> 19 | O511: =B511+D511+F511 -> 13 | P511: =C511+E511+G511 -> 9
A513: All 510 data rows (Raw_Data rows 2-511).

Sheet TB_Sensitivity
A1: Raw_Data row | B1: TB1 | C1: TB2 | D1: TB3 | E1: TB4 | F1: TB5 | G1: TB6 | H1: Total | I1: Rest_TB1 | J1: Rest_TB2 | K1: Rest_TB3 | L1: Rest_TB4 | M1: Rest_TB5 | N1: Rest_TB6 | O1: Odd (TB1+TB3+TB5) | P1: Even (TB2+TB4+TB6)
A2: 2 | B2: =Raw_Data!AJ2 -> 4 | C2: =Raw_Data!AK2 -> 5 | D2: =Raw_Data!AL2 -> 4 | E2: =Raw_Data!AM2 -> 4 | F2: =Raw_Data!AN2 -> 4 | G2: =Raw_Data!AO2 -> 4 | H2: =SUM(B2:G2) -> 25 | I2: =H2-B2 -> 21 | J2: =H2-C2 -> 20 | K2: =H2-D2 -> 21 | L2: =H2-E2 -> 21 | M2: =H2-F2 -> 21 | N2: =H2-G2 -> 21 | O2: =B2+D2+F2 -> 12 | P2: =C2+E2+G2 -> 13
A3: 3 | B3: =Raw_Data!AJ3 -> 4 | C3: =Raw_Data!AK3 -> 1 | D3: =Raw_Data!AL3 -> 5 | E3: =Raw_Data!AM3 -> 3 | F3: =Raw_Data!AN3 -> 2 | G3: =Raw_Data!AO3 -> 3 | H3: =SUM(B3:G3) -> 18 | I3: =H3-B3 -> 14 | J3: =H3-C3 -> 17 | K3: =H3-D3 -> 13 | L3: =H3-E3 -> 15 | M3: =H3-F3 -> 16 | N3: =H3-G3 -> 15 | O3: =B3+D3+F3 -> 11 | P3: =C3+E3+G3 -> 7
