Workbook

Sheet Raw_Data
A1: ID | B1: EA_Q1_Pre | C1: EA_Q2_Pre | D1: EA_Q3_Pre | E1: ELT_Q1_Pre | F1: ELT_Q2_Pre | G1: ELT_Q3_Pre | H1: TSE_Q1_Pre | I1: TSE_Q2_Pre | J1: TSE_Q3_Pre | K1: TS_Q1_Pre | L1: TS_Q2_Pre | M1: TS_Q3_Pre | N1: EA_Q1_Post | O1: EA_Q2_Post | P1: EA_Q3_Post | Q1: ELT_Q1_Post | R1: ELT_Q2_Post | S1: ELT_Q3_Post | T1: TSE_Q1_Post | U1: TSE_Q2_Post | V1: TSE_Q3_Post | W1: TS_Q1_Post | X1: TS_Q2_Post | Y1: TS_Q3_Post | AA1: Note
A2: P01 | B2: 5 | C2: 5 | D2: 5 | E2: 5 | F2: 5 | G2: 4 | H2: 4 | I2: 5 | J2: 4 | K2: 5 | L2: 5 | M2: 5 | N2: 5 | O2: 4 | P2: 5 | Q2: 5 | R2: 5 | S2: 5 | T2: 4 | U2: 4 | V2: 4 | W2: 4 | X2: 4 | Y2: 5 | AA2: Data copied unchanged from Likert Scale Responses.xlsx (sheet Questionnaire_Data). Do not edit; all other sheets reference A1:Y18.
A3: P02 | B3: 5 | C3: 4 | D3: 5 | E3: 4 | F3: 5 | G3: 4 | H3: 3 | I3: 4 | J3: 3 | K3: 4 | L3: 5 | M3: 4 | N3: 4 | O3: 3 | P3: 4 | Q3: 4 | R3: 4 | S3: 4 | T3: 3 | U3: 3 | V3: 4 | W3: 4 | X3: 4 | Y3: 4
A4: P03 | B4: 5 | C4: 4 | D4: 4 | E4: 5 | F4: 5 | G4: 4 | H4: 5 | I4: 4 | J4: 5 | K4: 3 | L4: 4 | M4: 5 | N4: 5 | O4: 5 | P4: 5 | Q4: 5 | R4: 5 | S4: 5 | T4: 5 | U4: 5 | V4: 5 | W4: 5 | X4: 5 | Y4: 5
A5: P04 | B5: 5 | C5: 4 | D5: 5 | E5: 5 | F5: 4 | G5: 4 | H5: 4 | I5: 5 | J5: 5 | K5: 5 | L5: 5 | M5: 5 | N5: 5 | O5: 5 | P5: 5 | Q5: 5 | R5: 5 | S5: 5 | T5: 4 | U5: 5 | V5: 5 | W5: 5 | X5: 5 | Y5: 5
A6: P05 | B6: 5 | C6: 5 | D6: 5 | E6: 5 | F6: 5 | G6: 4 | H6: 4 | I6: 4 | J6: 4 | K6: 5 | L6: 5 | M6: 4 | N6: 5 | O6: 5 | P6: 5 | Q6: 5 | R6: 5 | S6: 5 | T6: 5 | U6: 5 | V6: 5 | W6: 5 | X6: 5 | Y6: 5
A7: P06 | B7: 5 | C7: 5 | D7: 5 | E7: 5 | F7: 5 | G7: 4 | H7: 4 | I7: 5 | J7: 4 | K7: 5 | L7: 4 | M7: 4 | N7: 5 | O7: 5 | P7: 5 | Q7: 4 | R7: 4 | S7: 4 | T7: 5 | U7: 5 | V7: 5 | W7: 5 | X7: 5 | Y7: 5
A8: P07 | B8: 5 | C8: 5 | D8: 5 | E8: 4 | F8: 4 | G8: 5 | H8: 4 | I8: 3 | J8: 5 | K8: 4 | L8: 5 | M8: 5 | N8: 4 | O8: 3 | P8: 5 | Q8: 5 | R8: 5 | S8: 5 | T8: 4 | U8: 4 | V8: 4 | W8: 5 | X8: 4 | Y8: 5
A9: P08 | B9: 5 | C9: 5 | D9: 5 | E9: 5 | F9: 5 | G9: 5 | H9: 4 | I9: 4 | J9: 3 | K9: 5 | L9: 5 | M9: 5 | N9: 5 | O9: 5 | P9: 5 | Q9: 5 | R9: 5 | S9: 5 | T9: 4 | U9: 4 | V9: 5 | W9: 4 | X9: 4 | Y9: 5
A10: P09 | B10: 5 | C10: 5 | D10: 5 | E10: 5 | F10: 5 | G10: 5 | H10: 5 | I10: 5 | J10: 5 | K10: 5 | L10: 5 | M10: 5 | N10: 3 | O10: 3 | P10: 5 | Q10: 5 | R10: 5 | S10: 5 | T10: 5 | U10: 5 | V10: 5 | W10: 5 | X10: 5 | Y10: 5
A11: P10 | B11: 4 | C11: 4 | D11: 5 | E11: 3 | F11: 2 | G11: 4 | H11: 4 | I11: 3 | J11: 5 | K11: 4 | L11: 4 | M11: 4 | N11: 3 | O11: 3 | P11: 5 | Q11: 5 | R11: 5 | S11: 5 | T11: 4 | U11: 4 | V11: 4 | W11: 4 | X11: 4 | Y11: 5
A12: P11 | B12: 4 | C12: 5 | D12: 5 | E12: 5 | F12: 5 | G12: 5 | H12: 4 | I12: 5 | J12: 5 | K12: 5 | L12: 5 | M12: 5 | N12: 4 | O12: 4 | P12: 5 | Q12: 5 | R12: 5 | S12: 5 | T12: 4 | U12: 5 | V12: 3 | W12: 4 | X12: 5 | Y12: 5
A13: P12 | B13: 3 | C13: 4 | D13: 5 | E13: 5 | F13: 5 | G13: 5 | H13: 4 | I13: 4 | J13: 4 | K13: 5 | L13: 5 | M13: 5 | N13: 5 | O13: 5 | P13: 5 | Q13: 5 | R13: 5 | S13: 5 | T13: 4 | U13: 5 | V13: 5 | W13: 5 | X13: 5 | Y13: 5
A14: P13 | B14: 4 | C14: 4 | D14: 5 | E14: 4 | F14: 5 | G14: 4 | H14: 4 | I14: 4 | J14: 4 | K14: 4 | L14: 5 | M14: 4 | N14: 5 | O14: 4 | P14: 5 | Q14: 5 | R14: 5 | S14: 5 | T14: 4 | U14: 5 | V14: 5 | W14: 5 | X14: 5 | Y14: 5
... A18: P17 | B18: 4 | C18: 5 | D18: 5 | E18: 5 | F18: 4 | G18: 4 | H18: 3 | I18: 3 | J18: 2 | K18: 5 | L18: 5 | M18: 5 | N18: 5 | O18: 4 | P18: 5 | Q18: 5 | R18: 5 | S18: 5 | T18: 5 | U18: 4 | V18: 3 | W18: 4 | X18: 5 | Y18: 4

Sheet Validity_Test
A1: Item validity: Pearson item-total correlation (construct total = sum of 3 items)
A3: n | B3: =COUNT(Raw_Data!B2:B18) -> 17
A4: alpha (two-tailed) | B4: 0.05 | C4: Assumption (no lecturer instruction available): alpha = 0.05, two-tailed.
A5: df = n - 2 | B5: =B3-2 -> 15
A6: t critical | B6: =TINV(B4,B5) -> 2.1314495
A7: r table (critical r) | B7: =B6/SQRT(B6^2+B5) -> 0.48214602 | C7: Decision rule: item meets criterion if corrected r >= r table (equivalent to p < alpha with r > 0).
A9: Time | B9: Construct | C9: Item | D9: Statement (English) | E9: Mean | F9: SD | G9: r item-total (uncorrected) | H9: p (uncorrected) | I9: r corrected item-total (CITC) | J9: t (CITC) | K9: p (CITC, two-tailed) | L9: r table | M9: Decision (CITC vs r table) | N9: Uncorrected r vs r table (reference only)
A10: Pre | B10: Environmental Awareness | C10: EA_Q1_Pre | D10: I am aware that marine waste such as fishing nets is a significant environmental problem in the Mediterranean. | E10: =AVERAGE(Raw_Data!$B$2:$B$18) -> 4.5882353 | F10: =STDEV(Raw_Data!$B$2:$B$18) -> 0.61834694 | G10: =CORREL(Raw_Data!$B$2:$B$18,Scores!$B$2:$B$18) -> 0.7075316 | H10: =TDIST(ABS(G10)*SQRT($B$5/(1-G10^2)),$B$5,2) -> 0.0014875645 | I10: =CORREL(Raw_Data!$B$2:$B$18,Scores!$C$2:$C$18) -> 0.12520886 | J10: =I10*SQRT($B$5/(1-I10^2)) -> 0.4887783 | K10: =TDIST(ABS(J10),$B$5,2) -> 0.63206772 | L10: =$B$7 -> 0.48214602 | M10: =IF(I10>=L10,"Meets criterion","Does not meet") -> Does not meet | N10: =IF(G10>=L10,"Meets","Does not meet") -> Meets
A11: Pre | B11: Environmental Awareness | C11: EA_Q2_Pre | D11: I feel personally concerned about the impact of marine plastic waste on ecosystems. | E11: =AVERAGE(Raw_Data!$C$2:$C$18) -> 4.5294118 | F11: =STDEV(Raw_Data!$C$2:$C$18) -> 0.51449576 | G11: =CORREL(Raw_Data!$C$2:$C$18,Scores!$B$2:$B$18) -> 0.85034715 | H11: =TDIST(ABS(G11)*SQRT($B$5/(1-G11^2)),$B$5,2) -> 1.5320115e-05 | I11: =CORREL(Raw_Data!$C$2:$C$18,Scores!$D$2:$D$18) -> 0.53799554 | J11: =I11*SQRT($B$5/(1-I11^2)) -> 2.4718589 | K11: =TDIST(ABS(J11),$B$5,2) -> 0.025903591 | L11: =$B$7 -> 0.48214602 | M11: =IF(I11>=L11,"Meets criterion","Does not meet") -> Meets criterion | N11: =IF(G11>=L11,"Meets","Does not meet") -> Meets
A12: Pre | B12: Environmental Awareness | C12: EA_Q3_Pre | D12: I believe schools should play an active role in addressing environmental challenges. | E12: =AVERAGE(Raw_Data!$D$2:$D$18) -> 4.8823529 | F12: =STDEV(Raw_Data!$D$2:$D$18) -> 0.33210558 | G12: =CORREL(Raw_Data!$D$2:$D$18,Scores!$B$2:$B$18) -> 0.37638633 | H12: =TDIST(ABS(G12)*SQRT($B$5/(1-G12^2)),$B$5,2) -> 0.13646774 | I12: =CORREL(Raw_Data!$D$2:$D$18,Scores!$E$2:$E$18) -> 0.047740992 | J12: =I12*SQRT($B$5/(1-I12^2)) -> 0.18511114 | K12: =TDIST(ABS(J12),$B$5,2) -> 0.85562157 | L12: =$B$7 -> 0.48214602 | M12: =IF(I12>=L12,"Meets criterion","Does not meet") -> Does not meet | N12: =IF(G12>=L12,"Meets","Does not meet") -> Does not meet
A13: Pre | B13: Environmental Pedagogy in Language Education | C13: ELT_Q1_Pre | D13: Environmental topics can be meaningfully integrated into English lessons in primary school. | E13: =AVERAGE(Raw_Data!$E$2:$E$18) -> 4.5294118 | F13: =STDEV(Raw_Data!$E$2:$E$18) -> 0.71743005 | G13: =CORREL(Raw_Data!$E$2:$E$18,Scores!$F$2:$F$18) -> 0.87490166 | H13: =TDIST(ABS(G13)*SQRT($B$5/(1-G13^2)),$B$5,2) -> 4.3041563e-06 | I13: =CORREL(Raw_Data!$E$2:$E$18,Scores!$G$2:$G$18) -> 0.66627432 | J13: =I13*SQRT($B$5/(1-I13^2)) -> 3.4604346 | K13: =TDIST(ABS(J13),$B$5,2) -> 0.0034961707 | L13: =$B$7 -> 0.48214602 | M13: =IF(I13>=L13,"Meets criterion","Does not meet") -> Meets criterion | N13: =IF(G13>=L13,"Meets","Does not meet") -> Meets
A14: Pre | B14: Environmental Pedagogy in Language Education | C14: ELT_Q2_Pre | D14: Creative approaches such as theatre or puppetry can help children engage with environmental issues. | E14: =AVERAGE(Raw_Data!$F$2:$F$18) -> 4.5294118 | F14: =STDEV(Raw_Data!$F$2:$F$18) -> 0.79981616 | G14: =CORREL(Raw_Data!$F$2:$F$18,Scores!$F$2:$F$18) -> 0.88110822 | H14: =TDIST(ABS(G14)*SQRT($B$5/(1-G14^2)),$B$5,2) -> 2.9941306e-06 | I14: =CORREL(Raw_Data!$F$2:$F$18,Scores!$H$2:$H$18) -> 0.63442245 | J14: =I14*SQRT($B$5/(1-I14^2)) -> 3.1787199 | K14: =TDIST(ABS(J14),$B$5,2) -> 0.00622937 | L14: =$B$7 -> 0.48214602 | M14: =IF(I14>=L14,"Meets criterion","Does not meet") -> Meets criterion | N14: =IF(G14>=L14,"Meets","Does not meet") -> Meets
A15: Pre | B15: Environmental Pedagogy in Language Education | C15: ELT_Q3_Pre | D15: In CLIL contexts, environmental topics can make language learning more meaningful for pupils. | E15: =AVERAGE(Raw_Data!$G$2:$G$18) -> 4.3529412 | F15: =STDEV(Raw_Data!$G$2:$G$18) -> 0.49259218 | G15: =CORREL(Raw_Data!$G$2:$G$18,Scores!$F$2:$F$18) -> 0.58881856 | H15: =TDIST(ABS(G15)*SQRT($B$5/(1-G15^2)),$B$5,2) -> 0.012889175 | I15: =CORREL(Raw_Data!$G$2:$G$18,Scores!$I$2:$I$18) -> 0.33275673 | J15: =I15*SQRT($B$5/(1-I15^2)) -> 1.3666425 | K15: =TDIST(ABS(J15),$B$5,2) -> 0.19187374 | L15: =$B$7 -> 0.48214602 | M15: =IF(I15>=L15,"Meets criterion","Does not meet") -> Does not meet | N15: =IF(G15>=L15,"Meets","Does not meet") -> Meets
A16: Pre | B16: Teacher Self-Efficacy | C16: TSE_Q1_Pre | D16: I feel confident designing activities that connect environmental topics with English learning. | E16: =AVERAGE(Raw_Data!$H$2:$H$18) -> 3.9411765 | F16: =STDEV(Raw_Data!$H$2:$H$18) -> 0.55571893 | G16: =CORREL(Raw_Data!$H$2:$H$18,Scores!$J$2:$J$18) -> 0.85386105 | H16: =TDIST(ABS(G16)*SQRT($B$5/(1-G16^2)),$B$5,2) -> 1.2957565e-05 | I16: =CORREL(Raw_Data!$H$2:$H$18,Scores!$K$2:$K$18) -> 0.71493885 | J16: =I16*SQRT($B$5/(1-I16^2)) -> 3.9602372 | K16: =TDIST(ABS(J16),$B$5,2) -> 0.0012570339 | L16: =$B$7 -> 0.48214602 | M16: =IF(I16>=L16,"Meets criterion","Does not meet") -> Meets criterion | N16: =IF(G16>=L16,"Meets","Does not meet") -> Meets
A17: Pre | B17: Teacher Self-Efficacy | C17: TSE_Q2_Pre | D17: I feel capable of using creative materials to teach environmental issues in the classroom. | E17: =AVERAGE(Raw_Data!$I$2:$I$18) -> 4.0588235 | F17: =STDEV(Raw_Data!$I$2:$I$18) -> 0.747545 | G17: =CORREL(Raw_Data!$I$2:$I$18,Scores!$J$2:$J$18) -> 0.72014626 | H17: =TDIST(ABS(G17)*SQRT($B$5/(1-G17^2)),$B$5,2) -> 0.0011132838 | I17: =CORREL(Raw_Data!$I$2:$I$18,Scores!$L$2:$L$18) -> 0.38279552 | J17: =I17*SQRT($B$5/(1-I17^2)) -> 1.6047927 | K17: =TDIST(ABS(J17),$B$5,2) -> 0.12938257 | L17: =$B$7 -> 0.48214602 | M17: =IF(I17>=L17,"Meets criterion","Does not meet") -> Does not meet | N17: =IF(G17>=L17,"Meets","Does not meet") -> Meets
A18: Pre | B18: Teacher Self-Efficacy | C18: TSE_Q3_Pre | D18: I feel prepared to discuss environmental problems with primary school pupils. | E18: =AVERAGE(Raw_Data!$J$2:$J$18) -> 4.1176471 | F18: =STDEV(Raw_Data!$J$2:$J$18) -> 0.85749293 | G18: =CORREL(Raw_Data!$J$2:$J$18,Scores!$J$2:$J$18) -> 0.83377 | H18: =TDIST(ABS(G18)*SQRT($B$5/(1-G18^2)),$B$5,2) -> 3.2018075e-05 | I18: =CORREL(Raw_Data!$J$2:$J$18,Scores!$M$2:$M$18) -> 0.52153619 | J18: =I18*SQRT($B$5/(1-I18^2)) -> 2.3673605 | K18: =TDIST(ABS(J18),$B$5,2) -> 0.031786081 | L18: =$B$7 -> 0.48214602 | M18: =IF(I18>=L18,"Meets criterion","Does not meet") -> Meets criterion | N18: =IF(G18>=L18,"Meets","Does not meet") -> Meets
A19: Pre | B19: Transformation and Sustainability | C19: TS_Q1_Pre | D19: Reusing discarded materials can be a meaningful way to teach environmental responsibility. | E19: =AVERAGE(Raw_Data!$K$2:$K$18) -> 4.5882353 | F19: =STDEV(Raw_Data!$K$2:$K$18) -> 0.61834694 | G19: =CORREL(Raw_Data!$K$2:$K$18,Scores!$N$2:$N$18) -> 0.81364564 | H19: =TDIST(ABS(G19)*SQRT($B$5/(1-G19^2)),$B$5,2) -> 7.0899362e-05 | I19: =CORREL(Raw_Data!$K$2:$K$18,Scores!$O$2:$O$18) -> 0.4090156 | J19: =I19*SQRT($B$5/(1-I19^2)) -> 1.7359595 | K19: =TDIST(ABS(J19),$B$5,2) -> 0.10305973 | L19: =$B$7 -> 0.48214602 | M19: =IF(I19>=L19,"Meets criterion","Does not meet") -> Does not meet | N19: =IF(G19>=L19,"Meets","Does not meet") -> Meets
A20: Pre | B20: Transformation and Sustainability | C20: TS_Q2_Pre | D20: Artistic practices can help transform environmental waste into educational resources. | E20: =AVERAGE(Raw_Data!$L$2:$L$18) -> 4.8235294 | F20: =STDEV(Raw_Data!$L$2:$L$18) -> 0.39295262 | G20: =CORREL(Raw_Data!$L$2:$L$18,Scores!$N$2:$N$18) -> 0.7113033 | H20: =TDIST(ABS(G20)*SQRT($B$5/(1-G20^2)),$B$5,2) -> 0.0013661913 | I20: =CORREL(Raw_Data!$L$2:$L$18,Scores!$P$2:$P$18) -> 0.4556967 | J20: =I20*SQRT($B$5/(1-I20^2)) -> 1.9827391 | K20: =TDIST(ABS(J20),$B$5,2) -> 0.066018911 | L20: =$B$7 -> 0.48214602 | M20: =IF(I20>=L20,"Meets criterion","Does not meet") -> Does not meet | N20: =IF(G20>=L20,"Meets","Does not meet") -> Meets
A21: Pre | B21: Transformation and Sustainability | C21: TS_Q3_Pre | D21: Education can empower children to take action on environmental problems. | E21: =AVERAGE(Raw_Data!$M$2:$M$18) -> 4.5882353 | F21: =STDEV(Raw_Data!$M$2:$M$18) -> 0.50729966 | G21: =CORREL(Raw_Data!$M$2:$M$18,Scores!$N$2:$N$18) -> 0.6611678 | H21: =TDIST(ABS(G21)*SQRT($B$5/(1-G21^2)),$B$5,2) -> 0.0038522393 | I21: =CORREL(Raw_Data!$M$2:$M$18,Scores!$Q$2:$Q$18) -> 0.26648167 | J21: =I21*SQRT($B$5/(1-I21^2)) -> 1.0707992 | K21: =TDIST(ABS(J21),$B$5,2) -> 0.30118759 | L21: =$B$7 -> 0.48214602 | M21: =IF(I21>=L21,"Meets criterion","Does not meet") -> Does not meet | N21: =IF(G21>=L21,"Meets","Does not meet") -> Meets
A22: Post | B22: Environmental Awareness | C22: EA_Q1_Post | D22: After the project, I am more aware of the environmental impact of waste such as fishing nets in the Mediterranean.* | E22: =AVERAGE(Raw_Data!$N$2:$N$18) -> 4.5294118 | F22: =STDEV(Raw_Data!$N$2:$N$18) -> 0.71743005 | G22: =CORREL(Raw_Data!$N$2:$N$18,Scores!$S$2:$S$18) -> 0.90854082 | H22: =TDIST(ABS(G22)*SQRT($B$5/(1-G22^2)),$B$5,2) -> 4.5448594e-07 | I22: =CORREL(Raw_Data!$N$2:$N$18,Scores!$T$2:$T$18) -> 0.75828754 | J22: =I22*SQRT($B$5/(1-I22^2)) -> 4.5048993 | K22: =TDIST(ABS(J22),$B$5,2) -> 0.00041918507 | L22: =$B$7 -> 0.48214602 | M22: =IF(I22>=L22,"Meets criterion","Does not meet") -> Meets criterion | N22: =IF(G22>=L22,"Meets","Does not meet") -> Meets
A23: Post | B23: Environmental Awareness | C23: EA_Q2_Post | D23: The experience increased my concern about problems related to marine pollution.* | E23: =AVERAGE(Raw_Data!$O$2:$O$18) -> 4.1764706 | F23: =STDEV(Raw_Data!$O$2:$O$18) -> 0.882843 | G23: =CORREL(Raw_Data!$O$2:$O$18,Scores!$S$2:$S$18) -> 0.96888255 | H23: =TDIST(ABS(G23)*SQRT($B$5/(1-G23^2)),$B$5,2) -> 1.6707655e-10 | I23: =CORREL(Raw_Data!$O$2:$O$18,Scores!$U$2:$U$18) -> 0.8756883 | J23: =I23*SQRT($B$5/(1-I23^2)) -> 7.0235851 | K23: =TDIST(ABS(J23),$B$5,2) -> 4.1150303e-06 | L23: =$B$7 -> 0.48214602 | M23: =IF(I23>=L23,"Meets criterion","Does not meet") -> Meets criterion | N23: =IF(G23>=L23,"Meets","Does not meet") -> Meets
A24: Post | B24: Environmental Awareness | C24: EA_Q3_Post | D24: The project helped me reflect on the importance of addressing environmental problems at school.* | E24: =AVERAGE(Raw_Data!$P$2:$P$18) -> 4.8823529 | F24: =STDEV(Raw_Data!$P$2:$P$18) -> 0.33210558 | G24: =CORREL(Raw_Data!$P$2:$P$18,Scores!$S$2:$S$18) -> 0.57380458 | H24: =TDIST(ABS(G24)*SQRT($B$5/(1-G24^2)),$B$5,2) -> 0.016019018 | I24: =CORREL(Raw_Data!$P$2:$P$18,Scores!$V$2:$V$18) -> 0.41923451 | J24: =I24*SQRT($B$5/(1-I24^2)) -> 1.7884433 | K24: =TDIST(ABS(J24),$B$5,2) -> 0.093916531 | L24: =$B$7 -> 0.48214602 | M24: =IF(I24>=L24,"Meets criterion","Does not meet") -> Does not meet | N24: =IF(G24>=L24,"Meets","Does not meet") -> Meets
A25: Post | B25: Environmental Pedagogy in Language Education | C25: ELT_Q1_Post | D25: After the project, I consider that environmental topics can be effectively integrated into English classes.* | E25: =AVERAGE(Raw_Data!$Q$2:$Q$18) -> 4.8235294 | F25: =STDEV(Raw_Data!$Q$2:$Q$18) -> 0.39295262 | G25: =CORREL(Raw_Data!$Q$2:$Q$18,Scores!$W$2:$W$18) -> 0.95525871 | H25: =TDIST(ABS(G25)*SQRT($B$5/(1-G25^2)),$B$5,2) -> 2.4460565e-09 | I25: =CORREL(Raw_Data!$Q$2:$Q$18,Scores!$X$2:$X$18) -> 0.89309521 | J25: =I25*SQRT($B$5/(1-I25^2)) -> 7.6888001 | K25: =TDIST(ABS(J25),$B$5,2) -> 1.3987945e-06 | L25: =$B$7 -> 0.48214602 | M25: =IF(I25>=L25,"Meets criterion","Does not meet") -> Meets criterion | N25: =IF(G25>=L25,"Meets","Does not meet") -> Meets
A26: Post | B26: Environmental Pedagogy in Language Education | C26: ELT_Q2_Post | D26: The experience helped me understand the educational potential of theatre, puppets and other creative resources for environmental issues.* | E26: =AVERAGE(Raw_Data!$R$2:$R$18) -> 4.7647059 | F26: =STDEV(Raw_Data!$R$2:$R$18) -> 0.43723732 | G26: =CORREL(Raw_Data!$R$2:$R$18,Scores!$W$2:$W$18) -> 0.92151698 | H26: =TDIST(ABS(G26)*SQRT($B$5/(1-G26^2)),$B$5,2) -> 1.4992371e-07 | I26: =CORREL(Raw_Data!$R$2:$R$18,Scores!$Y$2:$Y$18) -> 0.7967218 | J26: =I26*SQRT($B$5/(1-I26^2)) -> 5.1058318 | K26: =TDIST(ABS(J26),$B$5,2) -> 0.00012909433 | L26: =$B$7 -> 0.48214602 | M26: =IF(I26>=L26,"Meets criterion","Does not meet") -> Meets criterion | N26: =IF(G26>=L26,"Meets","Does not meet") -> Meets
A27: Post | B27: Environmental Pedagogy in Language Education | C27: ELT_Q3_Post | D27: English learning can be more meaningful when connected to real problems such as sustainability or marine pollution.* | E27: =AVERAGE(Raw_Data!$S$2:$S$18) -> 4.8823529 | F27: =STDEV(Raw_Data!$S$2:$S$18) -> 0.33210558 | G27: =CORREL(Raw_Data!$S$2:$S$18,Scores!$W$2:$W$18) -> 0.87103942 | H27: =TDIST(ABS(G27)*SQRT($B$5/(1-G27^2)),$B$5,2) -> 5.3438999e-06 | I27: =CORREL(Raw_Data!$S$2:$S$18,Scores!$Z$2:$Z$18) -> 0.75174216 | J27: =I27*SQRT($B$5/(1-I27^2)) -> 4.4149721 | K27: =TDIST(ABS(J27),$B$5,2) -> 0.00050164438 | L27: =$B$7 -> 0.48214602 | M27: =IF(I27>=L27,"Meets criterion","Does not meet") -> Meets criterion | N27: =IF(G27>=L27,"Meets","Does not meet") -> Meets
A28: Post | B28: Teacher Self-Efficacy | C28: TSE_Q1_Post | D28: After this experience, I feel more able to design activities that connect sustainability and English teaching.* | E28: =AVERAGE(Raw_Data!$T$2:$T$18) -> 4.2352941 | F28: =STDEV(Raw_Data!$T$2:$T$18) -> 0.56229571 | G28: =CORREL(Raw_Data!$T$2:$T$18,Scores!$AA$2:$AA$18) -> 0.72913818 | H28: =TDIST(ABS(G28)*SQRT($B$5/(1-G28^2)),$B$5,2) -> 0.00089704754 | I28: =CORREL(Raw_Data!$T$2:$T$18,Scores!$AB$2:$AB$18) -> 0.44708977 | J28: =I28*SQRT($B$5/(1-I28^2)) -> 1.9358215 | K28: =TDIST(ABS(J28),$B$5,2) -> 0.071967877 | L28: =$B$7 -> 0.48214602 | M28: =IF(I28>=L28,"Meets criterion","Does not meet") -> Does not meet | N28: =IF(G28>=L28,"Meets","Does not meet") -> Meets
A29: Post | B29: Teacher Self-Efficacy | C29: TSE_Q2_Post | D29: I feel better prepared to use creative and reused materials in the classroom.* | E29: =AVERAGE(Raw_Data!$U$2:$U$18) -> 4.5294118 | F29: =STDEV(Raw_Data!$U$2:$U$18) -> 0.62426427 | G29: =CORREL(Raw_Data!$U$2:$U$18,Scores!$AA$2:$AA$18) -> 0.82297598 | H29: =TDIST(ABS(G29)*SQRT($B$5/(1-G29^2)),$B$5,2) -> 4.9644885e-05 | I29: =CORREL(Raw_Data!$U$2:$U$18,Scores!$AC$2:$AC$18) -> 0.56917199 | J29: =I29*SQRT($B$5/(1-I29^2)) -> 2.6810315 | K29: =TDIST(ABS(J29),$B$5,2) -> 0.017096449 | L29: =$B$7 -> 0.48214602 | M29: =IF(I29>=L29,"Meets criterion","Does not meet") -> Meets criterion | N29: =IF(G29>=L29,"Meets","Does not meet") -> Meets
A30: Post | B30: Teacher Self-Efficacy | C30: TSE_Q3_Post | D30: The experience increased my confidence to talk about environmental problems with primary pupils.* | E30: =AVERAGE(Raw_Data!$V$2:$V$18) -> 4.3529412 | F30: =STDEV(Raw_Data!$V$2:$V$18) -> 0.70188821 | G30: =CORREL(Raw_Data!$V$2:$V$18,Scores!$AA$2:$AA$18) -> 0.75359488 | H30: =TDIST(ABS(G30)*SQRT($B$5/(1-G30^2)),$B$5,2) -> 0.00047704341 | I30: =CORREL(Raw_Data!$V$2:$V$18,Scores!$AD$2:$AD$18) -> 0.38046075 | J30: =I30*SQRT($B$5/(1-I30^2)) -> 1.5933422 | K30: =TDIST(ABS(J30),$B$5,2) -> 0.13193329 | L30: =$B$7 -> 0.48214602 | M30: =IF(I30>=L30,"Meets criterion","Does not meet") -> Does not meet | N30: =IF(G30>=L30,"Meets","Does not meet") -> Meets
A31: Post | B31: Transformation and Sustainability | C31: TS_Q1_Post | D31: Working with reused materials helped me better understand the educational value of reuse.* | E31: =AVERAGE(Raw_Data!$W$2:$W$18) -> 4.6470588 | F31: =STDEV(Raw_Data!$W$2:$W$18) -> 0.49259218 | G31: =CORREL(Raw_Data!$W$2:$W$18,Scores!$AE$2:$AE$18) -> 0.85716709 | H31: =TDIST(ABS(G31)*SQRT($B$5/(1-G31^2)),$B$5,2) -> 1.102461e-05 | I31: =CORREL(Raw_Data!$W$2:$W$18,Scores!$AF$2:$AF$18) -> 0.57387372 | J31: =I31*SQRT($B$5/(1-I31^2)) -> 2.7139876 | K31: =TDIST(ABS(J31),$B$5,2) -> 0.016003353 | L31: =$B$7 -> 0.48214602 | M31: =IF(I31>=L31,"Meets criterion","Does not meet") -> Meets criterion | N31: =IF(G31>=L31,"Meets","Does not meet") -> Meets
A32: Post | B32: Transformation and Sustainability | C32: TS_Q2_Post | D32: The project made me reflect on how waste can be transformed into educational and artistic resources.* | E32: =AVERAGE(Raw_Data!$X$2:$X$18) -> 4.5882353 | F32: =STDEV(Raw_Data!$X$2:$X$18) -> 0.50729966 | G32: =CORREL(Raw_Data!$X$2:$X$18,Scores!$AE$2:$AE$18) -> 0.72280105 | H32: =TDIST(ABS(G32)*SQRT($B$5/(1-G32^2)),$B$5,2) -> 0.001045394 | I32: =CORREL(Raw_Data!$X$2:$X$18,Scores!$AG$2:$AG$18) -> 0.29294424 | J32: =I32*SQRT($B$5/(1-I32^2)) -> 1.186626 | K32: =TDIST(ABS(J32),$B$5,2) -> 0.25382986 | L32: =$B$7 -> 0.48214602 | M32: =IF(I32>=L32,"Meets criterion","Does not meet") -> Does not meet | N32: =IF(G32>=L32,"Meets","Does not meet") -> Meets
A33: Post | B33: Transformation and Sustainability | C33: TS_Q3_Post | D33: Creative experiences like this can help children become more involved in environmental problems.* | E33: =AVERAGE(Raw_Data!$Y$2:$Y$18) -> 4.8823529 | F33: =STDEV(Raw_Data!$Y$2:$Y$18) -> 0.33210558 | G33: =CORREL(Raw_Data!$Y$2:$Y$18,Scores!$AE$2:$AE$18) -> 0.61338714 | H33: =TDIST(ABS(G33)*SQRT($B$5/(1-G33^2)),$B$5,2) -> 0.0088283583 | I33: =CORREL(Raw_Data!$Y$2:$Y$18,Scores!$AH$2:$AH$18) -> 0.33288978 | J33: =I33*SQRT($B$5/(1-I33^2)) -> 1.367257 | K33: =TDIST(ABS(J33),$B$5,2) -> 0.19168522 | L33: =$B$7 -> 0.48214602 | M33: =IF(I33>=L33,"Meets criterion","Does not meet") -> Does not meet | N33: =IF(G33>=L33,"Meets","Does not meet") -> Meets
A35: * Post-test statements are the author's own English translation of the Spanish-only post-test questionnaire.
A36: Uncorrected r includes the item in its own total (1/3 of the total with 3 items), so it is inflated; it is shown only for comparison.
A37: Summary
A38: Pre: items meeting criterion (CITC) | D38: =COUNTIFS(A10:A33,"Pre",M10:M33,"Meets criterion")&" of "&COUNTIF(A10:A33,"Pre") -> 5 of 12
A39: Post: items meeting criterion (CITC) | D39: =COUNTIFS(A10:A33,"Post",M10:M33,"Meets criterion")&" of "&COUNTIF(A10:A33,"Post") -> 7 of 12
A40: Pre: uncorrected r >= r table | D40: =COUNTIFS(A10:A33,"Pre",N10:N33,"Meets")&" of "&COUNTIF(A10:A33,"Pre") -> 11 of 12
A41: Post: uncorrected r >= r table | D41: =COUNTIFS(A10:A33,"Post",N10:N33,"Meets")&" of "&COUNTIF(A10:A33,"Post") -> 12 of 12

Sheet Reliability_Test
A1: Reliability: Cronbach's alpha per construct (sample variances, n-1)
A3: CI level | B3: 0.95 | C3: Feldt (1965) confidence interval for alpha.
A4: n | B4: =COUNT(Raw_Data!B2:B18) -> 17
A6: Time | B6: Construct | C6: k | D6: Var item 1 | E6: Var item 2 | F6: Var item 3 | G6: Sum of item variances | H6: Variance of total | I6: Cronbach alpha | J6: 95% CI lower (Feldt) | K6: 95% CI upper (Feldt) | L6: r(Q1,Q2) | M6: r(Q1,Q3) | N6: r(Q2,Q3) | O6: Mean inter-item r | P6: Alpha if Q1 deleted | Q6: Alpha if Q2 deleted | R6: Alpha if Q3 deleted | S6: Decision (>= 0.70 acceptable; 0.60-0.69 marginal; < 0.60 inadequate)
A7: Pre | B7: Environmental Awareness | C7: 3 | D7: =VAR(Raw_Data!$B$2:$B$18) -> 0.38235294 | E7: =VAR(Raw_Data!$C$2:$C$18) -> 0.26470588 | F7: =VAR(Raw_Data!$D$2:$D$18) -> 0.11029412 | G7: =SUM(D7:F7) -> 0.75735294 | H7: =VAR(Scores!$B$2:$B$18) -> 1 | I7: =(C7/(C7-1))*(1-G7/H7) -> 0.36397059 | J7: =1-(1-I7)*FINV((1-$B$3)/2,$B$4-1,($B$4-1)*(C7-1)) -> -0.42980249 | K7: =1-(1-I7)*FINV(1-(1-$B$3)/2,$B$4-1,($B$4-1)*(C7-1)) -> 0.75088751 | L7: =CORREL(Raw_Data!$B$2:$B$18,Raw_Data!$C$2:$C$18) -> 0.33513137 | M7: =CORREL(Raw_Data!$B$2:$B$18,Raw_Data!$D$2:$D$18) -> -0.25064021 | N7: =CORREL(Raw_Data!$C$2:$C$18,Raw_Data!$D$2:$D$18) -> 0.38729833 | O7: =AVERAGE(L7:N7) -> 0.15726317 | P7: =2*(1-(E7+F7)/VAR(Scores!$C$2:$C$18)) -> 0.52173913 | Q7: =2*(1-(D7+F7)/VAR(Scores!$D$2:$D$18)) -> -0.52830189 | R7: =2*(1-(D7+E7)/VAR(Scores!$E$2:$E$18)) -> 0.4957265 | S7: =IF(I7>=0.7,"Acceptable",IF(I7>=0.6,"Marginal","Inadequate")) -> Inadequate
A8: Pre | B8: Environmental Pedagogy in Language Education | C8: 3 | D8: =VAR(Raw_Data!$E$2:$E$18) -> 0.51470588 | E8: =VAR(Raw_Data!$F$2:$F$18) -> 0.63970588 | F8: =VAR(Raw_Data!$G$2:$G$18) -> 0.24264706 | G8: =SUM(D8:F8) -> 1.3970588 | H8: =VAR(Scores!$F$2:$F$18) -> 2.6323529 | I8: =(C8/(C8-1))*(1-G8/H8) -> 0.70391061 | J8: =1-(1-I8)*FINV((1-$B$3)/2,$B$4-1,($B$4-1)*(C8-1)) -> 0.33438716 | K8: =1-(1-I8)*FINV(1-(1-$B$3)/2,$B$4-1,($B$4-1)*(C8-1)) -> 0.88403121 | L8: =CORREL(Raw_Data!$E$2:$E$18,Raw_Data!$F$2:$F$18) -> 0.67915237 | M8: =CORREL(Raw_Data!$E$2:$E$18,Raw_Data!$G$2:$G$18) -> 0.32249702 | N8: =CORREL(Raw_Data!$F$2:$F$18,Raw_Data!$G$2:$G$18) -> 0.2892778 | O8: =AVERAGE(L8:N8) -> 0.43030906 | P8: =2*(1-(E8+F8)/VAR(Scores!$G$2:$G$18)) -> 0.41059603 | Q8: =2*(1-(D8+F8)/VAR(Scores!$H$2:$H$18)) -> 0.46268657 | R8: =2*(1-(D8+E8)/VAR(Scores!$I$2:$I$18)) -> 0.80608365 | S8: =IF(I8>=0.7,"Acceptable",IF(I8>=0.6,"Marginal","Inadequate")) -> Acceptable
A9: Pre | B9: Teacher Self-Efficacy | C9: 3 | D9: =VAR(Raw_Data!$H$2:$H$18) -> 0.30882353 | E9: =VAR(Raw_Data!$I$2:$I$18) -> 0.55882353 | F9: =VAR(Raw_Data!$J$2:$J$18) -> 0.73529412 | G9: =SUM(D9:F9) -> 1.6029412 | H9: =VAR(Scores!$J$2:$J$18) -> 2.9852941 | I9: =(C9/(C9-1))*(1-G9/H9) -> 0.69458128 | J9: =1-(1-I9)*FINV((1-$B$3)/2,$B$4-1,($B$4-1)*(C9-1)) -> 0.3134147 | K9: =1-(1-I9)*FINV(1-(1-$B$3)/2,$B$4-1,($B$4-1)*(C9-1)) -> 0.8803772 | L9: =CORREL(Raw_Data!$H$2:$H$18,Raw_Data!$I$2:$I$18) -> 0.46019501 | M9: =CORREL(Raw_Data!$H$2:$H$18,Raw_Data!$J$2:$J$18) -> 0.67121957 | N9: =CORREL(Raw_Data!$I$2:$I$18,Raw_Data!$J$2:$J$18) -> 0.28103427 | O9: =AVERAGE(L9:N9) -> 0.47081629 | P9: =2*(1-(E9+F9)/VAR(Scores!$K$2:$K$18)) -> 0.43555556 | Q9: =2*(1-(D9+F9)/VAR(Scores!$L$2:$L$18)) -> 0.75982533 | R9: =2*(1-(D9+E9)/VAR(Scores!$M$2:$M$18)) -> 0.61176471 | S9: =IF(I9>=0.7,"Acceptable",IF(I9>=0.6,"Marginal","Inadequate")) -> Marginal
A10: Pre | B10: Transformation and Sustainability | C10: 3 | D10: =VAR(Raw_Data!$K$2:$K$18) -> 0.38235294 | E10: =VAR(Raw_Data!$L$2:$L$18) -> 0.15441176 | F10: =VAR(Raw_Data!$M$2:$M$18) -> 0.25735294 | G10: =SUM(D10:F10) -> 0.79411765 | H10: =VAR(Scores!$N$2:$N$18) -> 1.25 | I10: =(C10/(C10-1))*(1-G10/H10) -> 0.54705882 | J10: =1-(1-I10)*FINV((1-$B$3)/2,$B$4-1,($B$4-1)*(C10-1)) -> -0.018217727 | K10: =1-(1-I10)*FINV(1-(1-$B$3)/2,$B$4-1,($B$4-1)*(C10-1)) -> 0.82259735 | L10: =CORREL(Raw_Data!$K$2:$K$18,Raw_Data!$L$2:$L$18) -> 0.45392065 | M10: =CORREL(Raw_Data!$K$2:$K$18,Raw_Data!$M$2:$M$18) -> 0.22268343 | N10: =CORREL(Raw_Data!$L$2:$L$18,Raw_Data!$M$2:$M$18) -> 0.23975611 | O10: =AVERAGE(L10:N10) -> 0.3054534 | P10: =2*(1-(E10+F10)/VAR(Scores!$O$2:$O$18)) -> 0.37681159 | Q10: =2*(1-(D10+F10)/VAR(Scores!$P$2:$P$18)) -> 0.35849057 | R10: =2*(1-(D10+E10)/VAR(Scores!$Q$2:$Q$18)) -> 0.58252427 | S10: =IF(I10>=0.7,"Acceptable",IF(I10>=0.6,"Marginal","Inadequate")) -> Inadequate
A11: Post | B11: Environmental Awareness | C11: 3 | D11: =VAR(Raw_Data!$N$2:$N$18) -> 0.51470588 | E11: =VAR(Raw_Data!$O$2:$O$18) -> 0.77941176 | F11: =VAR(Raw_Data!$P$2:$P$18) -> 0.11029412 | G11: =SUM(D11:F11) -> 1.4044118 | H11: =VAR(Scores!$S$2:$S$18) -> 2.8823529 | I11: =(C11/(C11-1))*(1-G11/H11) -> 0.76913265 | J11: =1-(1-I11)*FINV((1-$B$3)/2,$B$4-1,($B$4-1)*(C11-1)) -> 0.48100717 | K11: =1-(1-I11)*FINV(1-(1-$B$3)/2,$B$4-1,($B$4-1)*(C11-1)) -> 0.9095766 | L11: =CORREL(Raw_Data!$N$2:$N$18,Raw_Data!$O$2:$O$18) -> 0.83004969 | M11: =CORREL(Raw_Data!$N$2:$N$18,Raw_Data!$P$2:$P$18) -> 0.27774603 | N11: =CORREL(Raw_Data!$O$2:$O$18,Raw_Data!$P$2:$P$18) -> 0.50156986 | O11: =AVERAGE(L11:N11) -> 0.53645519 | P11: =2*(1-(E11+F11)/VAR(Scores!$T$2:$T$18)) -> 0.49689441 | Q11: =2*(1-(D11+F11)/VAR(Scores!$U$2:$U$18)) -> 0.34951456 | R11: =2*(1-(D11+E11)/VAR(Scores!$V$2:$V$18)) -> 0.89655172 | S11: =IF(I11>=0.7,"Acceptable",IF(I11>=0.6,"Marginal","Inadequate")) -> Acceptable
A12: Post | B12: Environmental Pedagogy in Language Education | C12: 3 | D12: =VAR(Raw_Data!$Q$2:$Q$18) -> 0.15441176 | E12: =VAR(Raw_Data!$R$2:$R$18) -> 0.19117647 | F12: =VAR(Raw_Data!$S$2:$S$18) -> 0.11029412 | G12: =SUM(D12:F12) -> 0.45588235 | H12: =VAR(Scores!$W$2:$W$18) -> 1.1397059 | I12: =(C12/(C12-1))*(1-G12/H12) -> 0.9 | J12: =1-(1-I12)*FINV((1-$B$3)/2,$B$4-1,($B$4-1)*(C12-1)) -> 0.77519868 | K12: =1-(1-I12)*FINV(1-(1-$B$3)/2,$B$4-1,($B$4-1)*(C12-1)) -> 0.96083318 | L12: =CORREL(Raw_Data!$Q$2:$Q$18,Raw_Data!$R$2:$R$18) -> 0.83452296 | M12: =CORREL(Raw_Data!$Q$2:$Q$18,Raw_Data!$S$2:$S$18) -> 0.78881064 | N12: =CORREL(Raw_Data!$R$2:$R$18,Raw_Data!$S$2:$S$18) -> 0.65828059 | O12: =AVERAGE(L12:N12) -> 0.76053806 | P12: =2*(1-(E12+F12)/VAR(Scores!$X$2:$X$18)) -> 0.7761194 | Q12: =2*(1-(D12+F12)/VAR(Scores!$Y$2:$Y$18)) -> 0.875 | R12: =2*(1-(D12+E12)/VAR(Scores!$Z$2:$Z$18)) -> 0.90697674 | S12: =IF(I12>=0.7,"Acceptable",IF(I12>=0.6,"Marginal","Inadequate")) -> Acceptable
A13: Post | B13: Teacher Self-Efficacy | C13: 3 | D13: =VAR(Raw_Data!$T$2:$T$18) -> 0.31617647 | E13: =VAR(Raw_Data!$U$2:$U$18) -> 0.38970588 | F13: =VAR(Raw_Data!$V$2:$V$18) -> 0.49264706 | G13: =SUM(D13:F13) -> 1.1985294 | H13: =VAR(Scores!$AA$2:$AA$18) -> 2.1102941 | I13: =(C13/(C13-1))*(1-G13/H13) -> 0.64808362 | J13: =1-(1-I13)*FINV((1-$B$3)/2,$B$4-1,($B$4-1)*(C13-1)) -> 0.20888735 | K13: =1-(1-I13)*FINV(1-(1-$B$3)/2,$B$4-1,($B$4-1)*(C13-1)) -> 0.86216555 | L13: =CORREL(Raw_Data!$T$2:$T$18,Raw_Data!$U$2:$U$18) -> 0.5132086 | M13: =CORREL(Raw_Data!$T$2:$T$18,Raw_Data!$V$2:$V$18) -> 0.25151399 | N13: =CORREL(Raw_Data!$U$2:$U$18,Raw_Data!$V$2:$V$18) -> 0.40275033 | O13: =AVERAGE(L13:N13) -> 0.38915764 | P13: =2*(1-(E13+F13)/VAR(Scores!$AB$2:$AB$18)) -> 0.57142857 | Q13: =2*(1-(D13+F13)/VAR(Scores!$AC$2:$AC$18)) -> 0.39416058 | R13: =2*(1-(D13+E13)/VAR(Scores!$AD$2:$AD$18)) -> 0.67586207 | S13: =IF(I13>=0.7,"Acceptable",IF(I13>=0.6,"Marginal","Inadequate")) -> Marginal
A14: Post | B14: Transformation and Sustainability | C14: 3 | D14: =VAR(Raw_Data!$W$2:$W$18) -> 0.24264706 | E14: =VAR(Raw_Data!$X$2:$X$18) -> 0.25735294 | F14: =VAR(Raw_Data!$Y$2:$Y$18) -> 0.11029412 | G14: =SUM(D14:F14) -> 0.61029412 | H14: =VAR(Scores!$AE$2:$AE$18) -> 0.98529412 | I14: =(C14/(C14-1))*(1-G14/H14) -> 0.57089552 | J14: =1-(1-I14)*FINV((1-$B$3)/2,$B$4-1,($B$4-1)*(C14-1)) -> 0.035367486 | K14: =1-(1-I14)*FINV(1-(1-$B$3)/2,$B$4-1,($B$4-1)*(C14-1)) -> 0.83193343 | L14: =CORREL(Raw_Data!$W$2:$W$18,Raw_Data!$X$2:$X$18) -> 0.38251843 | M14: =CORREL(Raw_Data!$W$2:$W$18,Raw_Data!$Y$2:$Y$18) -> 0.49441323 | N14: =CORREL(Raw_Data!$X$2:$X$18,Raw_Data!$Y$2:$Y$18) -> 0.065465367 | O14: =AVERAGE(L14:N14) -> 0.31413234 | P14: =2*(1-(E14+F14)/VAR(Scores!$AF$2:$AF$18)) -> 0.11320755 | Q14: =2*(1-(D14+F14)/VAR(Scores!$AG$2:$AG$18)) -> 0.62857143 | R14: =2*(1-(D14+E14)/VAR(Scores!$AH$2:$AH$18)) -> 0.55319149 | S14: =IF(I14>=0.7,"Acceptable",IF(I14>=0.6,"Marginal","Inadequate")) -> Inadequate
A16: Supplementary: all 12 items as one scale (not the main analysis; the 12 items span 4 different constructs)
A17: Time | B17: Scale | C17: k | D17: Sum of 12 item variances | E17: Variance of 12-item total | F17: Cronbach alpha
A18: Pre | B18: All 12 items | C18: 12 | D18: =VAR(Raw_Data!$B$2:$B$18)+VAR(Raw_Data!$C$2:$C$18)+VAR(Raw_Data!$D$2:$D$18)+VAR(Raw_Data!$E$2:$E$18)+VAR(Raw_Data!$F$2:$F$18)+VAR(Raw_Data!$G$2:$G$18)+VAR(Raw_Data!$H$2:$H$18)+VAR(Raw_Data!$I$2:$I$18)+VAR(Raw_Data!$J$2:$J$18)+VAR(Raw_Data!$K$2:$K$18)+VAR(Raw_Data!$L$2:$L$18)+VAR(Raw_Data!$M$2:$M$18) -> 4.5514706 | E18: =VAR(Scores!$R$2:$R$18) -> 15.014706 | F18: =(C18/(C18-1))*(1-D18/E18) -> 0.76021726
A19: Post | B19: All 12 items | C19: 12 | D19: =VAR(Raw_Data!$N$2:$N$18)+VAR(Raw_Data!$O$2:$O$18)+VAR(Raw_Data!$P$2:$P$18)+VAR(Raw_Data!$Q$2:$Q$18)+VAR(Raw_Data!$R$2:$R$18)+VAR(Raw_Data!$S$2:$S$18)+VAR(Raw_Data!$T$2:$T$18)+VAR(Raw_Data!$U$2:$U$18)+VAR(Raw_Data!$V$2:$V$18)+VAR(Raw_Data!$W$2:$W$18)+VAR(Raw_Data!$X$2:$X$18)+VAR(Raw_Data!$Y$2:$Y$18) -> 3.6691176 | E19: =VAR(Scores!$AI$2:$AI$18) -> 14.345588 | F19: =(C19/(C19-1))*(1-D19/E19) -> 0.81189134
A21: Formula: alpha = k/(k-1) * (1 - sum of item variances / variance of total score).
A22: Alpha if item deleted (k = 3 -> 2 items left) = 2 * (1 - (var a + var b) / var(a + b)); the 'Rest' column in Scores holds a + b.
A23: Feldt CI: lower = 1-(1-alpha)*F(0.975; n-1, (n-1)(k-1)), upper = 1-(1-alpha)*F(0.025; n-1, (n-1)(k-1)).
A24: A negative alpha-if-deleted means the two remaining items are negatively correlated.

Sheet Interpretation
A1: Interpretation summary (numbers link to Validity_Test and Reliability_Test)
A3: Time | B3: Construct | C3: Cronbach alpha | D3: 95% CI lower | E3: 95% CI upper | F3: Alpha decision | G3: Items meeting CITC >= r table | H3: Interpretation
A4: =Reliability_Test!A7 -> Pre | B4: =Reliability_Test!B7 -> Environmental Awareness | C4: =Reliability_Test!I7 -> 0.36397059 | D4: =Reliability_Test!J7 -> -0.42980249 | E4: =Reliability_Test!K7 -> 0.75088751 | F4: =Reliability_Test!S7 -> Inadequate | G4: =COUNTIFS(Validity_Test!$A$10:$A$33,A4,Validity_Test!$B$10:$B$33,B4,Validity_Test!$M$10:$M$33,"Meets criterion")&" of 3" -> 1 of 3 | H4: Inadequate. Q1 and Q3 fail CITC; Q1 and Q3 correlate negatively (see Reliability_Test). Q3 has a ceiling (15 of 17 answered 5). Items do not behave as one scale at pre-test.
A5: =Reliability_Test!A8 -> Pre | B5: =Reliability_Test!B8 -> Environmental Pedagogy in Language Education | C5: =Reliability_Test!I8 -> 0.70391061 | D5: =Reliability_Test!J8 -> 0.33438716 | E5: =Reliability_Test!K8 -> 0.88403121 | F5: =Reliability_Test!S8 -> Acceptable | G5: =COUNTIFS(Validity_Test!$A$10:$A$33,A5,Validity_Test!$B$10:$B$33,B5,Validity_Test!$M$10:$M$33,"Meets criterion")&" of 3" -> 2 of 3 | H5: Meets 0.70 only narrowly and the CI reaches down to about 0.33. Q3 (CLIL item) fails CITC; deleting it raises alpha (see 'Alpha if Q3 deleted'). Treat as tentative.
A6: =Reliability_Test!A9 -> Pre | B6: =Reliability_Test!B9 -> Teacher Self-Efficacy | C6: =Reliability_Test!I9 -> 0.69458128 | D6: =Reliability_Test!J9 -> 0.3134147 | E6: =Reliability_Test!K9 -> 0.8803772 | F6: =Reliability_Test!S9 -> Marginal | G6: =COUNTIFS(Validity_Test!$A$10:$A$33,A6,Validity_Test!$B$10:$B$33,B6,Validity_Test!$M$10:$M$33,"Meets criterion")&" of 3" -> 2 of 3 | H6: Just below 0.70 (marginal). Q2 fails CITC; deleting it raises alpha. Usable only for exploratory purposes.
A7: =Reliability_Test!A10 -> Pre | B7: =Reliability_Test!B10 -> Transformation and Sustainability | C7: =Reliability_Test!I10 -> 0.54705882 | D7: =Reliability_Test!J10 -> -0.018217727 | E7: =Reliability_Test!K10 -> 0.82259735 | F7: =Reliability_Test!S10 -> Inadequate | G7: =COUNTIFS(Validity_Test!$A$10:$A$33,A7,Validity_Test!$B$10:$B$33,B7,Validity_Test!$M$10:$M$33,"Meets criterion")&" of 3" -> 0 of 3 | H7: Inadequate. None of the 3 items meets CITC. Q2 has a strong ceiling (14 of 17 answered 5).
A8: =Reliability_Test!A11 -> Post | B8: =Reliability_Test!B11 -> Environmental Awareness | C8: =Reliability_Test!I11 -> 0.76913265 | D8: =Reliability_Test!J11 -> 0.48100717 | E8: =Reliability_Test!K11 -> 0.9095766 | F8: =Reliability_Test!S11 -> Acceptable | G8: =COUNTIFS(Validity_Test!$A$10:$A$33,A8,Validity_Test!$B$10:$B$33,B8,Validity_Test!$M$10:$M$33,"Meets criterion")&" of 3" -> 2 of 3 | H8: Acceptable. Q3 fails CITC and has a ceiling (15 of 17 answered 5); deleting Q3 raises alpha. Q1 and Q2 carry the scale.
A9: =Reliability_Test!A12 -> Post | B9: =Reliability_Test!B12 -> Environmental Pedagogy in Language Education | C9: =Reliability_Test!I12 -> 0.9 | D9: =Reliability_Test!J12 -> 0.77519868 | E9: =Reliability_Test!K12 -> 0.96083318 | F9: =Reliability_Test!S12 -> Acceptable | G9: =COUNTIFS(Validity_Test!$A$10:$A$33,A9,Validity_Test!$B$10:$B$33,B9,Validity_Test!$M$10:$M$33,"Meets criterion")&" of 3" -> 3 of 3 | H9: Good. All 3 items meet CITC; the only construct whose CI lower bound is above 0.70. Caution: Q3 has 15 of 17 answering 5, so its correlation rests on 2 respondents.
A10: =Reliability_Test!A13 -> Post | B10: =Reliability_Test!B13 -> Teacher Self-Efficacy | C10: =Reliability_Test!I13 -> 0.64808362 | D10: =Reliability_Test!J13 -> 0.20888735 | E10: =Reliability_Test!K13 -> 0.86216555 | F10: =Reliability_Test!S13 -> Marginal | G10: =COUNTIFS(Validity_Test!$A$10:$A$33,A10,Validity_Test!$B$10:$B$33,B10,Validity_Test!$M$10:$M$33,"Meets criterion")&" of 3" -> 1 of 3 | H10: Marginal. Q1 and Q3 fail CITC. Usable only for exploratory purposes.
A11: =Reliability_Test!A14 -> Post | B11: =Reliability_Test!B14 -> Transformation and Sustainability | C11: =Reliability_Test!I14 -> 0.57089552 | D11: =Reliability_Test!J14 -> 0.035367486 | E11: =Reliability_Test!K14 -> 0.83193343 | F11: =Reliability_Test!S14 -> Inadequate | G11: =COUNTIFS(Validity_Test!$A$10:$A$33,A11,Validity_Test!$B$10:$B$33,B11,Validity_Test!$M$10:$M$33,"Meets criterion")&" of 3" -> 1 of 3 | H11: Inadequate. Only Q1 meets CITC; Q1 and Q3 are almost uncorrelated.
A13: Overall
A14: Pre-test: items meeting CITC criterion | D14: =Validity_Test!D38 -> 5 of 12
A15: Post-test: items meeting CITC criterion | D15: =Validity_Test!D39 -> 7 of 12
A16: Constructs with alpha >= 0.70 (pre) | D16: =COUNTIFS(A4:A11,"Pre",C4:C11,">=0.7")&" of 4" -> 1 of 4
A17: Constructs with alpha >= 0.70 (post) | D17: =COUNTIFS(A4:A11,"Post",C4:C11,">=0.7")&" of 4" -> 2 of 4
A18: Assumptions
A19: No official lecturer instruction was provided. Validity = corrected item-total Pearson r (item vs sum of the other 2 items of the same construct), compared with r table at alpha 0.05 two-tailed, df = 15.
A20: Reliability = Cronbach's alpha per construct; >= 0.70 acceptable, 0.60-0.69 marginal, < 0.60 inadequate. Pre-test and post-test analysed separately because item wording differs between the two questionnaires.
A21: Limitations
A22: n = 17: r table is high (0.482) and every correlation has a wide CI; one respondent can change a decision. Alpha CIs (Feldt) are wide, e.g. several include values below 0.60.
A23: Ceiling effect: 6 of 24 items have >= 80% of respondents at 5 (see Data_Check), which restricts variance and lowers correlations.
A24: Only 3 items per construct: alpha is depressed by short scales; alpha if item deleted leaves a 2-item scale.
A25: Item-total correlation is internal-consistency evidence only; construct validity (factor analysis) is not testable with n = 17. Likert data are ordinal; Pearson r treats them as interval.

Sheet Data_Check
A1: Data screening per item (all values computed from Raw_Data)
A3: Item | B3: N valid | C3: Missing | D3: Min | E3: Max | F3: Out of range (not 1-5) | G3: Mean | H3: SD | I3: n = 5 | J3: % = 5
A4: EA_Q1_Pre | B4: =COUNT(Raw_Data!$B$2:$B$18) -> 17 | C4: =COUNTBLANK(Raw_Data!$B$2:$B$18) -> 0 | D4: =MIN(Raw_Data!$B$2:$B$18) -> 3 | E4: =MAX(Raw_Data!$B$2:$B$18) -> 5 | F4: =COUNT(Raw_Data!$B$2:$B$18)-COUNTIFS(Raw_Data!$B$2:$B$18,">=1",Raw_Data!$B$2:$B$18,"<=5") -> 0 | G4: =AVERAGE(Raw_Data!$B$2:$B$18) -> 4.5882353 | H4: =STDEV(Raw_Data!$B$2:$B$18) -> 0.61834694 | I4: =COUNTIF(Raw_Data!$B$2:$B$18,5) -> 11 | J4: =I4/B4 -> 0.64705882
A5: EA_Q2_Pre | B5: =COUNT(Raw_Data!$C$2:$C$18) -> 17 | C5: =COUNTBLANK(Raw_Data!$C$2:$C$18) -> 0 | D5: =MIN(Raw_Data!$C$2:$C$18) -> 4 | E5: =MAX(Raw_Data!$C$2:$C$18) -> 5 | F5: =COUNT(Raw_Data!$C$2:$C$18)-COUNTIFS(Raw_Data!$C$2:$C$18,">=1",Raw_Data!$C$2:$C$18,"<=5") -> 0 | G5: =AVERAGE(Raw_Data!$C$2:$C$18) -> 4.5294118 | H5: =STDEV(Raw_Data!$C$2:$C$18) -> 0.51449576 | I5: =COUNTIF(Raw_Data!$C$2:$C$18,5) -> 9 | J5: =I5/B5 -> 0.52941176
A6: EA_Q3_Pre | B6: =COUNT(Raw_Data!$D$2:$D$18) -> 17 | C6: =COUNTBLANK(Raw_Data!$D$2:$D$18) -> 0 | D6: =MIN(Raw_Data!$D$2:$D$18) -> 4 | E6: =MAX(Raw_Data!$D$2:$D$18) -> 5 | F6: =COUNT(Raw_Data!$D$2:$D$18)-COUNTIFS(Raw_Data!$D$2:$D$18,">=1",Raw_Data!$D$2:$D$18,"<=5") -> 0 | G6: =AVERAGE(Raw_Data!$D$2:$D$18) -> 4.8823529 | H6: =STDEV(Raw_Data!$D$2:$D$18) -> 0.33210558 | I6: =COUNTIF(Raw_Data!$D$2:$D$18,5) -> 15 | J6: =I6/B6 -> 0.88235294
A7: ELT_Q1_Pre | B7: =COUNT(Raw_Data!$E$2:$E$18) -> 17 | C7: =COUNTBLANK(Raw_Data!$E$2:$E$18) -> 0 | D7: =MIN(Raw_Data!$E$2:$E$18) -> 3 | E7: =MAX(Raw_Data!$E$2:$E$18) -> 5 | F7: =COUNT(Raw_Data!$E$2:$E$18)-COUNTIFS(Raw_Data!$E$2:$E$18,">=1",Raw_Data!$E$2:$E$18,"<=5") -> 0 | G7: =AVERAGE(Raw_Data!$E$2:$E$18) -> 4.5294118 | H7: =STDEV(Raw_Data!$E$2:$E$18) -> 0.71743005 | I7: =COUNTIF(Raw_Data!$E$2:$E$18,5) -> 11 | J7: =I7/B7 -> 0.64705882
A8: ELT_Q2_Pre | B8: =COUNT(Raw_Data!$F$2:$F$18) -> 17 | C8: =COUNTBLANK(Raw_Data!$F$2:$F$18) -> 0 | D8: =MIN(Raw_Data!$F$2:$F$18) -> 2 | E8: =MAX(Raw_Data!$F$2:$F$18) -> 5 | F8: =COUNT(Raw_Data!$F$2:$F$18)-COUNTIFS(Raw_Data!$F$2:$F$18,">=1",Raw_Data!$F$2:$F$18,"<=5") -> 0 | G8: =AVERAGE(Raw_Data!$F$2:$F$18) -> 4.5294118 | H8: =STDEV(Raw_Data!$F$2:$F$18) -> 0.79981616 | I8: =COUNTIF(Raw_Data!$F$2:$F$18,5) -> 11 | J8: =I8/B8 -> 0.64705882
A9: ELT_Q3_Pre | B9: =COUNT(Raw_Data!$G$2:$G$18) -> 17 | C9: =COUNTBLANK(Raw_Data!$G$2:$G$18) -> 0 | D9: =MIN(Raw_Data!$G$2:$G$18) -> 4 | E9: =MAX(Raw_Data!$G$2:$G$18) -> 5 | F9: =COUNT(Raw_Data!$G$2:$G$18)-COUNTIFS(Raw_Data!$G$2:$G$18,">=1",Raw_Data!$G$2:$G$18,"<=5") -> 0 | G9: =AVERAGE(Raw_Data!$G$2:$G$18) -> 4.3529412 | H9: =STDEV(Raw_Data!$G$2:$G$18) -> 0.49259218 | I9: =COUNTIF(Raw_Data!$G$2:$G$18,5) -> 6 | J9: =I9/B9 -> 0.35294118
A10: TSE_Q1_Pre | B10: =COUNT(Raw_Data!$H$2:$H$18) -> 17 | C10: =COUNTBLANK(Raw_Data!$H$2:$H$18) -> 0 | D10: =MIN(Raw_Data!$H$2:$H$18) -> 3 | E10: =MAX(Raw_Data!$H$2:$H$18) -> 5 | F10: =COUNT(Raw_Data!$H$2:$H$18)-COUNTIFS(Raw_Data!$H$2:$H$18,">=1",Raw_Data!$H$2:$H$18,"<=5") -> 0 | G10: =AVERAGE(Raw_Data!$H$2:$H$18) -> 3.9411765 | H10: =STDEV(Raw_Data!$H$2:$H$18) -> 0.55571893 | I10: =COUNTIF(Raw_Data!$H$2:$H$18,5) -> 2 | J10: =I10/B10 -> 0.11764706
A11: TSE_Q2_Pre | B11: =COUNT(Raw_Data!$I$2:$I$18) -> 17 | C11: =COUNTBLANK(Raw_Data!$I$2:$I$18) -> 0 | D11: =MIN(Raw_Data!$I$2:$I$18) -> 3 | E11: =MAX(Raw_Data!$I$2:$I$18) -> 5 | F11: =COUNT(Raw_Data!$I$2:$I$18)-COUNTIFS(Raw_Data!$I$2:$I$18,">=1",Raw_Data!$I$2:$I$18,"<=5") -> 0 | G11: =AVERAGE(Raw_Data!$I$2:$I$18) -> 4.0588235 | H11: =STDEV(Raw_Data!$I$2:$I$18) -> 0.747545 | I11: =COUNTIF(Raw_Data!$I$2:$I$18,5) -> 5 | J11: =I11/B11 -> 0.29411765
A12: TSE_Q3_Pre | B12: =COUNT(Raw_Data!$J$2:$J$18) -> 17 | C12: =COUNTBLANK(Raw_Data!$J$2:$J$18) -> 0 | D12: =MIN(Raw_Data!$J$2:$J$18) -> 2 | E12: =MAX(Raw_Data!$J$2:$J$18) -> 5 | F12: =COUNT(Raw_Data!$J$2:$J$18)-COUNTIFS(Raw_Data!$J$2:$J$18,">=1",Raw_Data!$J$2:$J$18,"<=5") -> 0 | G12: =AVERAGE(Raw_Data!$J$2:$J$18) -> 4.1176471 | H12: =STDEV(Raw_Data!$J$2:$J$18) -> 0.85749293 | I12: =COUNTIF(Raw_Data!$J$2:$J$18,5) -> 6 | J12: =I12/B12 -> 0.35294118
A13: TS_Q1_Pre | B13: =COUNT(Raw_Data!$K$2:$K$18) -> 17 | C13: =COUNTBLANK(Raw_Data!$K$2:$K$18) -> 0 | D13: =MIN(Raw_Data!$K$2:$K$18) -> 3 | E13: =MAX(Raw_Data!$K$2:$K$18) -> 5 | F13: =COUNT(Raw_Data!$K$2:$K$18)-COUNTIFS(Raw_Data!$K$2:$K$18,">=1",Raw_Data!$K$2:$K$18,"<=5") -> 0 | G13: =AVERAGE(Raw_Data!$K$2:$K$18) -> 4.5882353 | H13: =STDEV(Raw_Data!$K$2:$K$18) -> 0.61834694 | I13: =COUNTIF(Raw_Data!$K$2:$K$18,5) -> 11 | J13: =I13/B13 -> 0.64705882
A14: TS_Q2_Pre | B14: =COUNT(Raw_Data!$L$2:$L$18) -> 17 | C14: =COUNTBLANK(Raw_Data!$L$2:$L$18) -> 0 | D14: =MIN(Raw_Data!$L$2:$L$18) -> 4 | E14: =MAX(Raw_Data!$L$2:$L$18) -> 5 | F14: =COUNT(Raw_Data!$L$2:$L$18)-COUNTIFS(Raw_Data!$L$2:$L$18,">=1",Raw_Data!$L$2:$L$18,"<=5") -> 0 | G14: =AVERAGE(Raw_Data!$L$2:$L$18) -> 4.8235294 | H14: =STDEV(Raw_Data!$L$2:$L$18) -> 0.39295262 | I14: =COUNTIF(Raw_Data!$L$2:$L$18,5) -> 14 | J14: =I14/B14 -> 0.82352941
A15: TS_Q3_Pre | B15: =COUNT(Raw_Data!$M$2:$M$18) -> 17 | C15: =COUNTBLANK(Raw_Data!$M$2:$M$18) -> 0 | D15: =MIN(Raw_Data!$M$2:$M$18) -> 4 | E15: =MAX(Raw_Data!$M$2:$M$18) -> 5 | F15: =COUNT(Raw_Data!$M$2:$M$18)-COUNTIFS(Raw_Data!$M$2:$M$18,">=1",Raw_Data!$M$2:$M$18,"<=5") -> 0 | G15: =AVERAGE(Raw_Data!$M$2:$M$18) -> 4.5882353 | H15: =STDEV(Raw_Data!$M$2:$M$18) -> 0.50729966 | I15: =COUNTIF(Raw_Data!$M$2:$M$18,5) -> 10 | J15: =I15/B15 -> 0.58823529
A16: EA_Q1_Post | B16: =COUNT(Raw_Data!$N$2:$N$18) -> 17 | C16: =COUNTBLANK(Raw_Data!$N$2:$N$18) -> 0 | D16: =MIN(Raw_Data!$N$2:$N$18) -> 3 | E16: =MAX(Raw_Data!$N$2:$N$18) -> 5 | F16: =COUNT(Raw_Data!$N$2:$N$18)-COUNTIFS(Raw_Data!$N$2:$N$18,">=1",Raw_Data!$N$2:$N$18,"<=5") -> 0 | G16: =AVERAGE(Raw_Data!$N$2:$N$18) -> 4.5294118 | H16: =STDEV(Raw_Data!$N$2:$N$18) -> 0.71743005 | I16: =COUNTIF(Raw_Data!$N$2:$N$18,5) -> 11 | J16: =I16/B16 -> 0.64705882
A17: EA_Q2_Post | B17: =COUNT(Raw_Data!$O$2:$O$18) -> 17 | C17: =COUNTBLANK(Raw_Data!$O$2:$O$18) -> 0 | D17: =MIN(Raw_Data!$O$2:$O$18) -> 3 | E17: =MAX(Raw_Data!$O$2:$O$18) -> 5 | F17: =COUNT(Raw_Data!$O$2:$O$18)-COUNTIFS(Raw_Data!$O$2:$O$18,">=1",Raw_Data!$O$2:$O$18,"<=5") -> 0 | G17: =AVERAGE(Raw_Data!$O$2:$O$18) -> 4.1764706 | H17: =STDEV(Raw_Data!$O$2:$O$18) -> 0.882843 | I17: =COUNTIF(Raw_Data!$O$2:$O$18,5) -> 8 | J17: =I17/B17 -> 0.47058824
A18: EA_Q3_Post | B18: =COUNT(Raw_Data!$P$2:$P$18) -> 17 | C18: =COUNTBLANK(Raw_Data!$P$2:$P$18) -> 0 | D18: =MIN(Raw_Data!$P$2:$P$18) -> 4 | E18: =MAX(Raw_Data!$P$2:$P$18) -> 5 | F18: =COUNT(Raw_Data!$P$2:$P$18)-COUNTIFS(Raw_Data!$P$2:$P$18,">=1",Raw_Data!$P$2:$P$18,"<=5") -> 0 | G18: =AVERAGE(Raw_Data!$P$2:$P$18) -> 4.8823529 | H18: =STDEV(Raw_Data!$P$2:$P$18) -> 0.33210558 | I18: =COUNTIF(Raw_Data!$P$2:$P$18,5) -> 15 | J18: =I18/B18 -> 0.88235294
A19: ELT_Q1_Post | B19: =COUNT(Raw_Data!$Q$2:$Q$18) -> 17 | C19: =COUNTBLANK(Raw_Data!$Q$2:$Q$18) -> 0 | D19: =MIN(Raw_Data!$Q$2:$Q$18) -> 4 | E19: =MAX(Raw_Data!$Q$2:$Q$18) -> 5 | F19: =COUNT(Raw_Data!$Q$2:$Q$18)-COUNTIFS(Raw_Data!$Q$2:$Q$18,">=1",Raw_Data!$Q$2:$Q$18,"<=5") -> 0 | G19: =AVERAGE(Raw_Data!$Q$2:$Q$18) -> 4.8235294 | H19: =STDEV(Raw_Data!$Q$2:$Q$18) -> 0.39295262 | I19: =COUNTIF(Raw_Data!$Q$2:$Q$18,5) -> 14 | J19: =I19/B19 -> 0.82352941
A20: ELT_Q2_Post | B20: =COUNT(Raw_Data!$R$2:$R$18) -> 17 | C20: =COUNTBLANK(Raw_Data!$R$2:$R$18) -> 0 | D20: =MIN(Raw_Data!$R$2:$R$18) -> 4 | E20: =MAX(Raw_Data!$R$2:$R$18) -> 5 | F20: =COUNT(Raw_Data!$R$2:$R$18)-COUNTIFS(Raw_Data!$R$2:$R$18,">=1",Raw_Data!$R$2:$R$18,"<=5") -> 0 | G20: =AVERAGE(Raw_Data!$R$2:$R$18) -> 4.7647059 | H20: =STDEV(Raw_Data!$R$2:$R$18) -> 0.43723732 | I20: =COUNTIF(Raw_Data!$R$2:$R$18,5) -> 13 | J20: =I20/B20 -> 0.76470588
A21: ELT_Q3_Post | B21: =COUNT(Raw_Data!$S$2:$S$18) -> 17 | C21: =COUNTBLANK(Raw_Data!$S$2:$S$18) -> 0 | D21: =MIN(Raw_Data!$S$2:$S$18) -> 4 | E21: =MAX(Raw_Data!$S$2:$S$18) -> 5 | F21: =COUNT(Raw_Data!$S$2:$S$18)-COUNTIFS(Raw_Data!$S$2:$S$18,">=1",Raw_Data!$S$2:$S$18,"<=5") -> 0 | G21: =AVERAGE(Raw_Data!$S$2:$S$18) -> 4.8823529 | H21: =STDEV(Raw_Data!$S$2:$S$18) -> 0.33210558 | I21: =COUNTIF(Raw_Data!$S$2:$S$18,5) -> 15 | J21: =I21/B21 -> 0.88235294
A22: TSE_Q1_Post | B22: =COUNT(Raw_Data!$T$2:$T$18) -> 17 | C22: =COUNTBLANK(Raw_Data!$T$2:$T$18) -> 0 | D22: =MIN(Raw_Data!$T$2:$T$18) -> 3 | E22: =MAX(Raw_Data!$T$2:$T$18) -> 5 | F22: =COUNT(Raw_Data!$T$2:$T$18)-COUNTIFS(Raw_Data!$T$2:$T$18,">=1",Raw_Data!$T$2:$T$18,"<=5") -> 0 | G22: =AVERAGE(Raw_Data!$T$2:$T$18) -> 4.2352941 | H22: =STDEV(Raw_Data!$T$2:$T$18) -> 0.56229571 | I22: =COUNTIF(Raw_Data!$T$2:$T$18,5) -> 5 | J22: =I22/B22 -> 0.29411765
A23: TSE_Q2_Post | B23: =COUNT(Raw_Data!$U$2:$U$18) -> 17 | C23: =COUNTBLANK(Raw_Data!$U$2:$U$18) -> 0 | D23: =MIN(Raw_Data!$U$2:$U$18) -> 3 | E23: =MAX(Raw_Data!$U$2:$U$18) -> 5 | F23: =COUNT(Raw_Data!$U$2:$U$18)-COUNTIFS(Raw_Data!$U$2:$U$18,">=1",Raw_Data!$U$2:$U$18,"<=5") -> 0 | G23: =AVERAGE(Raw_Data!$U$2:$U$18) -> 4.5294118 | H23: =STDEV(Raw_Data!$U$2:$U$18) -> 0.62426427 | I23: =COUNTIF(Raw_Data!$U$2:$U$18,5) -> 10 | J23: =I23/B23 -> 0.58823529
A24: TSE_Q3_Post | B24: =COUNT(Raw_Data!$V$2:$V$18) -> 17 | C24: =COUNTBLANK(Raw_Data!$V$2:$V$18) -> 0 | D24: =MIN(Raw_Data!$V$2:$V$18) -> 3 | E24: =MAX(Raw_Data!$V$2:$V$18) -> 5 | F24: =COUNT(Raw_Data!$V$2:$V$18)-COUNTIFS(Raw_Data!$V$2:$V$18,">=1",Raw_Data!$V$2:$V$18,"<=5") -> 0 | G24: =AVERAGE(Raw_Data!$V$2:$V$18) -> 4.3529412 | H24: =STDEV(Raw_Data!$V$2:$V$18) -> 0.70188821 | I24: =COUNTIF(Raw_Data!$V$2:$V$18,5) -> 8 | J24: =I24/B24 -> 0.47058824
A25: TS_Q1_Post | B25: =COUNT(Raw_Data!$W$2:$W$18) -> 17 | C25: =COUNTBLANK(Raw_Data!$W$2:$W$18) -> 0 | D25: =MIN(Raw_Data!$W$2:$W$18) -> 4 | E25: =MAX(Raw_Data!$W$2:$W$18) -> 5 | F25: =COUNT(Raw_Data!$W$2:$W$18)-COUNTIFS(Raw_Data!$W$2:$W$18,">=1",Raw_Data!$W$2:$W$18,"<=5") -> 0 | G25: =AVERAGE(Raw_Data!$W$2:$W$18) -> 4.6470588 | H25: =STDEV(Raw_Data!$W$2:$W$18) -> 0.49259218 | I25: =COUNTIF(Raw_Data!$W$2:$W$18,5) -> 11 | J25: =I25/B25 -> 0.64705882
A26: TS_Q2_Post | B26: =COUNT(Raw_Data!$X$2:$X$18) -> 17 | C26: =COUNTBLANK(Raw_Data!$X$2:$X$18) -> 0 | D26: =MIN(Raw_Data!$X$2:$X$18) -> 4 | E26: =MAX(Raw_Data!$X$2:$X$18) -> 5 | F26: =COUNT(Raw_Data!$X$2:$X$18)-COUNTIFS(Raw_Data!$X$2:$X$18,">=1",Raw_Data!$X$2:$X$18,"<=5") -> 0 | G26: =AVERAGE(Raw_Data!$X$2:$X$18) -> 4.5882353 | H26: =STDEV(Raw_Data!$X$2:$X$18) -> 0.50729966 | I26: =COUNTIF(Raw_Data!$X$2:$X$18,5) -> 10 | J26: =I26/B26 -> 0.58823529
A27: TS_Q3_Post | B27: =COUNT(Raw_Data!$Y$2:$Y$18) -> 17 | C27: =COUNTBLANK(Raw_Data!$Y$2:$Y$18) -> 0 | D27: =MIN(Raw_Data!$Y$2:$Y$18) -> 4 | E27: =MAX(Raw_Data!$Y$2:$Y$18) -> 5 | F27: =COUNT(Raw_Data!$Y$2:$Y$18)-COUNTIFS(Raw_Data!$Y$2:$Y$18,">=1",Raw_Data!$Y$2:$Y$18,"<=5") -> 0 | G27: =AVERAGE(Raw_Data!$Y$2:$Y$18) -> 4.8823529 | H27: =STDEV(Raw_Data!$Y$2:$Y$18) -> 0.33210558 | I27: =COUNTIF(Raw_Data!$Y$2:$Y$18,5) -> 15 | J27: =I27/B27 -> 0.88235294
A29: Respondents (IDs) | B29: =COUNTA(Raw_Data!A2:A18) -> 17
A30: Duplicate IDs | B30: =SUMPRODUCT((COUNTIF(Raw_Data!A2:A18,Raw_Data!A2:A18)>1)*1) -> 0
A31: Total missing cells | B31: =SUM(C4:C27) -> 0
A32: Total out-of-range cells | B32: =SUM(F4:F27) -> 0
A33: Items with >= 80% answering 5 (ceiling) | B33: =COUNTIF(J4:J27,">=0.8") -> 6

Sheet Scores
A1: ID | B1: EA_Total_Pre | C1: EA_Q1_Pre_Rest | D1: EA_Q2_Pre_Rest | E1: EA_Q3_Pre_Rest | F1: ELT_Total_Pre | G1: ELT_Q1_Pre_Rest | H1: ELT_Q2_Pre_Rest | I1: ELT_Q3_Pre_Rest | J1: TSE_Total_Pre | K1: TSE_Q1_Pre_Rest | L1: TSE_Q2_Pre_Rest | M1: TSE_Q3_Pre_Rest | N1: TS_Total_Pre | O1: TS_Q1_Pre_Rest | P1: TS_Q2_Pre_Rest | Q1: TS_Q3_Pre_Rest | R1: All12_Total_Pre | S1: EA_Total_Post | T1: EA_Q1_Post_Rest | U1: EA_Q2_Post_Rest | V1: EA_Q3_Post_Rest | W1: ELT_Total_Post | X1: ELT_Q1_Post_Rest | Y1: ELT_Q2_Post_Rest | Z1: ELT_Q3_Post_Rest | AA1: TSE_Total_Post | AB1: TSE_Q1_Post_Rest | AC1: TSE_Q2_Post_Rest | AD1: TSE_Q3_Post_Rest | AE1: TS_Total_Post | AF1: TS_Q1_Post_Rest | AG1: TS_Q2_Post_Rest | AH1: TS_Q3_Post_Rest | AI1: All12_Total_Post
A2: =Raw_Data!A2 -> P01 | B2: =Raw_Data!B2+Raw_Data!C2+Raw_Data!D2 -> 15 | C2: =Raw_Data!C2+Raw_Data!D2 -> 10 | D2: =Raw_Data!B2+Raw_Data!D2 -> 10 | E2: =Raw_Data!B2+Raw_Data!C2 -> 10 | F2: =Raw_Data!E2+Raw_Data!F2+Raw_Data!G2 -> 14 | G2: =Raw_Data!F2+Raw_Data!G2 -> 9 | H2: =Raw_Data!E2+Raw_Data!G2 -> 9 | I2: =Raw_Data!E2+Raw_Data!F2 -> 10 | J2: =Raw_Data!H2+Raw_Data!I2+Raw_Data!J2 -> 13 | K2: =Raw_Data!I2+Raw_Data!J2 -> 9 | L2: =Raw_Data!H2+Raw_Data!J2 -> 8 | M2: =Raw_Data!H2+Raw_Data!I2 -> 9 | N2: =Raw_Data!K2+Raw_Data!L2+Raw_Data!M2 -> 15 | O2: =Raw_Data!L2+Raw_Data!M2 -> 10 | P2: =Raw_Data!K2+Raw_Data!M2 -> 10 | Q2: =Raw_Data!K2+Raw_Data!L2 -> 10 | R2: =SUM(Raw_Data!B2:M2) -> 57 | S2: =Raw_Data!N2+Raw_Data!O2+Raw_Data!P2 -> 14 | T2: =Raw_Data!O2+Raw_Data!P2 -> 9 | U2: =Raw_Data!N2+Raw_Data!P2 -> 10 | V2: =Raw_Data!N2+Raw_Data!O2 -> 9 | W2: =Raw_Data!Q2+Raw_Data!R2+Raw_Data!S2 -> 15 | X2: =Raw_Data!R2+Raw_Data!S2 -> 10 | Y2: =Raw_Data!Q2+Raw_Data!S2 -> 10 | Z2: =Raw_Data!Q2+Raw_Data!R2 -> 10 | AA2: =Raw_Data!T2+Raw_Data!U2+Raw_Data!V2 -> 12 | AB2: =Raw_Data!U2+Raw_Data!V2 -> 8 | AC2: =Raw_Data!T2+Raw_Data!V2 -> 8 | AD2: =Raw_Data!T2+Raw_Data!U2 -> 8 | AE2: =Raw_Data!W2+Raw_Data!X2+Raw_Data!Y2 -> 13 | AF2: =Raw_Data!X2+Raw_Data!Y2 -> 9 | AG2: =Raw_Data!W2+Raw_Data!Y2 -> 9 | AH2: =Raw_Data!W2+Raw_Data!X2 -> 8 | AI2: =SUM(Raw_Data!N2:Y2) -> 54
A3: =Raw_Data!A3 -> P02 | B3: =Raw_Data!B3+Raw_Data!C3+Raw_Data!D3 -> 14 | C3: =Raw_Data!C3+Raw_Data!D3 -> 9 | D3: =Raw_Data!B3+Raw_Data!D3 -> 10 | E3: =Raw_Data!B3+Raw_Data!C3 -> 9 | F3: =Raw_Data!E3+Raw_Data!F3+Raw_Data!G3 -> 13 | G3: =Raw_Data!F3+Raw_Data!G3 -> 9 | H3: =Raw_Data!E3+Raw_Data!G3 -> 8 | I3: =Raw_Data!E3+Raw_Data!F3 -> 9 | J3: =Raw_Data!H3+Raw_Data!I3+Raw_Data!J3 -> 10 | K3: =Raw_Data!I3+Raw_Data!J3 -> 7 | L3: =Raw_Data!H3+Raw_Data!J3 -> 6 | M3: =Raw_Data!H3+Raw_Data!I3 -> 7 | N3: =Raw_Data!K3+Raw_Data!L3+Raw_Data!M3 -> 13 | O3: =Raw_Data!L3+Raw_Data!M3 -> 9 | P3: =Raw_Data!K3+Raw_Data!M3 -> 8 | Q3: =Raw_Data!K3+Raw_Data!L3 -> 9 | R3: =SUM(Raw_Data!B3:M3) -> 50 | S3: =Raw_Data!N3+Raw_Data!O3+Raw_Data!P3 -> 11 | T3: =Raw_Data!O3+Raw_Data!P3 -> 7 | U3: =Raw_Data!N3+Raw_Data!P3 -> 8 | V3: =Raw_Data!N3+Raw_Data!O3 -> 7 | W3: =Raw_Data!Q3+Raw_Data!R3+Raw_Data!S3 -> 12 | X3: =Raw_Data!R3+Raw_Data!S3 -> 8 | Y3: =Raw_Data!Q3+Raw_Data!S3 -> 8 | Z3: =Raw_Data!Q3+Raw_Data!R3 -> 8 | AA3: =Raw_Data!T3+Raw_Data!U3+Raw_Data!V3 -> 10 | AB3: =Raw_Data!U3+Raw_Data!V3 -> 7 | AC3: =Raw_Data!T3+Raw_Data!V3 -> 7 | AD3: =Raw_Data!T3+Raw_Data!U3 -> 6 | AE3: =Raw_Data!W3+Raw_Data!X3+Raw_Data!Y3 -> 12 | AF3: =Raw_Data!X3+Raw_Data!Y3 -> 8 | AG3: =Raw_Data!W3+Raw_Data!Y3 -> 8 | AH3: =Raw_Data!W3+Raw_Data!X3 -> 8 | AI3: =SUM(Raw_Data!N3:Y3) -> 45
A4: =Raw_Data!A4 -> P03 | B4: =Raw_Data!B4+Raw_Data!C4+Raw_Data!D4 -> 13 | C4: =Raw_Data!C4+Raw_Data!D4 -> 8 | D4: =Raw_Data!B4+Raw_Data!D4 -> 9 | E4: =Raw_Data!B4+Raw_Data!C4 -> 9 | F4: =Raw_Data!E4+Raw_Data!F4+Raw_Data!G4 -> 14 | G4: =Raw_Data!F4+Raw_Data!G4 -> 9 | H4: =Raw_Data!E4+Raw_Data!G4 -> 9 | I4: =Raw_Data!E4+Raw_Data!F4 -> 10 | J4: =Raw_Data!H4+Raw_Data!I4+Raw_Data!J4 -> 14 | K4: =Raw_Data!I4+Raw_Data!J4 -> 9 | L4: =Raw_Data!H4+Raw_Data!J4 -> 10 | M4: =Raw_Data!H4+Raw_Data!I4 -> 9 | N4: =Raw_Data!K4+Raw_Data!L4+Raw_Data!M4 -> 12 | O4: =Raw_Data!L4+Raw_Data!M4 -> 9 | P4: =Raw_Data!K4+Raw_Data!M4 -> 8 | Q4: =Raw_Data!K4+Raw_Data!L4 -> 7 | R4: =SUM(Raw_Data!B4:M4) -> 53 | S4: =Raw_Data!N4+Raw_Data!O4+Raw_Data!P4 -> 15 | T4: =Raw_Data!O4+Raw_Data!P4 -> 10 | U4: =Raw_Data!N4+Raw_Data!P4 -> 10 | V4: =Raw_Data!N4+Raw_Data!O4 -> 10 | W4: =Raw_Data!Q4+Raw_Data!R4+Raw_Data!S4 -> 15 | X4: =Raw_Data!R4+Raw_Data!S4 -> 10 | Y4: =Raw_Data!Q4+Raw_Data!S4 -> 10 | Z4: =Raw_Data!Q4+Raw_Data!R4 -> 10 | AA4: =Raw_Data!T4+Raw_Data!U4+Raw_Data!V4 -> 15 | AB4: =Raw_Data!U4+Raw_Data!V4 -> 10 | AC4: =Raw_Data!T4+Raw_Data!V4 -> 10 | AD4: =Raw_Data!T4+Raw_Data!U4 -> 10 | AE4: =Raw_Data!W4+Raw_Data!X4+Raw_Data!Y4 -> 15 | AF4: =Raw_Data!X4+Raw_Data!Y4 -> 10 | AG4: =Raw_Data!W4+Raw_Data!Y4 -> 10 | AH4: =Raw_Data!W4+Raw_Data!X4 -> 10 | AI4: =SUM(Raw_Data!N4:Y4) -> 60
A5: =Raw_Data!A5 -> P04 | B5: =Raw_Data!B5+Raw_Data!C5+Raw_Data!D5 -> 14 | C5: =Raw_Data!C5+Raw_Data!D5 -> 9 | D5: =Raw_Data!B5+Raw_Data!D5 -> 10 | E5: =Raw_Data!B5+Raw_Data!C5 -> 9 | F5: =Raw_Data!E5+Raw_Data!F5+Raw_Data!G5 -> 13 | G5: =Raw_Data!F5+Raw_Data!G5 -> 8 | H5: =Raw_Data!E5+Raw_Data!G5 -> 9 | I5: =Raw_Data!E5+Raw_Data!F5 -> 9 | J5: =Raw_Data!H5+Raw_Data!I5+Raw_Data!J5 -> 14 | K5: =Raw_Data!I5+Raw_Data!J5 -> 10 | L5: =Raw_Data!H5+Raw_Data!J5 -> 9 | M5: =Raw_Data!H5+Raw_Data!I5 -> 9 | N5: =Raw_Data!K5+Raw_Data!L5+Raw_Data!M5 -> 15 | O5: =Raw_Data!L5+Raw_Data!M5 -> 10 | P5: =Raw_Data!K5+Raw_Data!M5 -> 10 | Q5: =Raw_Data!K5+Raw_Data!L5 -> 10 | R5: =SUM(Raw_Data!B5:M5) -> 56 | S5: =Raw_Data!N5+Raw_Data!O5+Raw_Data!P5 -> 15 | T5: =Raw_Data!O5+Raw_Data!P5 -> 10 | U5: =Raw_Data!N5+Raw_Data!P5 -> 10 | V5: =Raw_Data!N5+Raw_Data!O5 -> 10 | W5: =Raw_Data!Q5+Raw_Data!R5+Raw_Data!S5 -> 15 | X5: =Raw_Data!R5+Raw_Data!S5 -> 10 | Y5: =Raw_Data!Q5+Raw_Data!S5 -> 10 | Z5: =Raw_Data!Q5+Raw_Data!R5 -> 10 | AA5: =Raw_Data!T5+Raw_Data!U5+Raw_Data!V5 -> 14 | AB5: =Raw_Data!U5+Raw_Data!V5 -> 10 | AC5: =Raw_Data!T5+Raw_Data!V5 -> 9 | AD5: =Raw_Data!T5+Raw_Data!U5 -> 9 | AE5: =Raw_Data!W5+Raw_Data!X5+Raw_Data!Y5 -> 15 | AF5: =Raw_Data!X5+Raw_Data!Y5 -> 10 | AG5: =Raw_Data!W5+Raw_Data!Y5 -> 10 | AH5: =Raw_Data!W5+Raw_Data!X5 -> 10 | AI5: =SUM(Raw_Data!N5:Y5) -> 59
A6: =Raw_Data!A6 -> P05 | B6: =Raw_Data!B6+Raw_Data!C6+Raw_Data!D6 -> 15 | C6: =Raw_Data!C6+Raw_Data!D6 -> 10 | D6: =Raw_Data!B6+Raw_Data!D6 -> 10 | E6: =Raw_Data!B6+Raw_Data!C6 -> 10 | F6: =Raw_Data!E6+Raw_Data!F6+Raw_Data!G6 -> 14 | G6: =Raw_Data!F6+Raw_Data!G6 -> 9 | H6: =Raw_Data!E6+Raw_Data!G6 -> 9 | I6: =Raw_Data!E6+Raw_Data!F6 -> 10 | J6: =Raw_Data!H6+Raw_Data!I6+Raw_Data!J6 -> 12 | K6: =Raw_Data!I6+Raw_Data!J6 -> 8 | L6: =Raw_Data!H6+Raw_Data!J6 -> 8 | M6: =Raw_Data!H6+Raw_Data!I6 -> 8 | N6: =Raw_Data!K6+Raw_Data!L6+Raw_Data!M6 -> 14 | O6: =Raw_Data!L6+Raw_Data!M6 -> 9 | P6: =Raw_Data!K6+Raw_Data!M6 -> 9 | Q6: =Raw_Data!K6+Raw_Data!L6 -> 10 | R6: =SUM(Raw_Data!B6:M6) -> 55 | S6: =Raw_Data!N6+Raw_Data!O6+Raw_Data!P6 -> 15 | T6: =Raw_Data!O6+Raw_Data!P6 -> 10 | U6: =Raw_Data!N6+Raw_Data!P6 -> 10 | V6: =Raw_Data!N6+Raw_Data!O6 -> 10 | W6: =Raw_Data!Q6+Raw_Data!R6+Raw_Data!S6 -> 15 | X6: =Raw_Data!R6+Raw_Data!S6 -> 10 | Y6: =Raw_Data!Q6+Raw_Data!S6 -> 10 | Z6: =Raw_Data!Q6+Raw_Data!R6 -> 10 | AA6: =Raw_Data!T6+Raw_Data!U6+Raw_Data!V6 -> 15 | AB6: =Raw_Data!U6+Raw_Data!V6 -> 10 | AC6: =Raw_Data!T6+Raw_Data!V6 -> 10 | AD6: =Raw_Data!T6+Raw_Data!U6 -> 10 | AE6: =Raw_Data!W6+Raw_Data!X6+Raw_Data!Y6 -> 15 | AF6: =Raw_Data!X6+Raw_Data!Y6 -> 10 | AG6: =Raw_Data!W6+Raw_Data!Y6 -> 10 | AH6: =Raw_Data!W6+Raw_Data!X6 -> 10 | AI6: =SUM(Raw_Data!N6:Y6) -> 60
A7: =Raw_Data!A7 -> P06 | B7: =Raw_Data!B7+Raw_Data!C7+Raw_Data!D7 -> 15 | C7: =Raw_Data!C7+Raw_Data!D7 -> 10 | D7: =Raw_Data!B7+Raw_Data!D7 -> 10 | E7: =Raw_Data!B7+Raw_Data!C7 -> 10 | F7: =Raw_Data!E7+Raw_Data!F7+Raw_Data!G7 -> 14 | G7: =Raw_Data!F7+Raw_Data!G7 -> 9 | H7: =Raw_Data!E7+Raw_Data!G7 -> 9 | I7: =Raw_Data!E7+Raw_Data!F7 -> 10 | J7: =Raw_Data!H7+Raw_Data!I7+Raw_Data!J7 -> 13 | K7: =Raw_Data!I7+Raw_Data!J7 -> 9 | L7: =Raw_Data!H7+Raw_Data!J7 -> 8 | M7: =Raw_Data!H7+Raw_Data!I7 -> 9 | N7: =Raw_Data!K7+Raw_Data!L7+Raw_Data!M7 -> 13 | O7: =Raw_Data!L7+Raw_Data!M7 -> 8 | P7: =Raw_Data!K7+Raw_Data!M7 -> 9 | Q7: =Raw_Data!K7+Raw_Data!L7 -> 9 | R7: =SUM(Raw_Data!B7:M7) -> 55 | S7: =Raw_Data!N7+Raw_Data!O7+Raw_Data!P7 -> 15 | T7: =Raw_Data!O7+Raw_Data!P7 -> 10 | U7: =Raw_Data!N7+Raw_Data!P7 -> 10 | V7: =Raw_Data!N7+Raw_Data!O7 -> 10 | W7: =Raw_Data!Q7+Raw_Data!R7+Raw_Data!S7 -> 12 | X7: =Raw_Data!R7+Raw_Data!S7 -> 8 | Y7: =Raw_Data!Q7+Raw_Data!S7 -> 8 | Z7: =Raw_Data!Q7+Raw_Data!R7 -> 8 | AA7: =Raw_Data!T7+Raw_Data!U7+Raw_Data!V7 -> 15 | AB7: =Raw_Data!U7+Raw_Data!V7 -> 10 | AC7: =Raw_Data!T7+Raw_Data!V7 -> 10 | AD7: =Raw_Data!T7+Raw_Data!U7 -> 10 | AE7: =Raw_Data!W7+Raw_Data!X7+Raw_Data!Y7 -> 15 | AF7: =Raw_Data!X7+Raw_Data!Y7 -> 10 | AG7: =Raw_Data!W7+Raw_Data!Y7 -> 10 | AH7: =Raw_Data!W7+Raw_Data!X7 -> 10 | AI7: =SUM(Raw_Data!N7:Y7) -> 57
